Workbook
Name estimate: '[1]01 收入底稿'!$B$4
Name YM: '[2]01 收入底稿(計價收入)'!$I$6:$T$6

Sheet 調整說明
A1: 調整說明
A3: 1. | B3: 依KL意見(詳圖一)
B4: 1) 增加2023年底Underbill,(即2023年底調整C/TO_Adj. $400m),2023年底與2023.8.31差異請詳"Over Under Bill 1"工作表
B5: 2) B0 2264工作表_考量物調,專案先行投入及權重因素,調整業主計價百分比,比例詳line 2, 以利underbill or overbill 金額表達較合理之趨勢
A6: 2. | B6: B1 ZSD060扣保工作表_包括CF重分配金額
A7: 3. | B7: 調整2028年底Underbill
B14: 圖一

Sheet BS2_WIP
A1: CEC 2026 Budget- Balance Sheets | C1: 3 | D1: 4 | E1: 5 | F1: 6 | G1: 7 | H1: 8 | I1: 9 | J1: 10 | K1: 11 | L1: 12 | M1: 13 | N1: 14 | O1: 15 | P1: 16 | Q1: 17 | R1: 18 | S1: 19 | T1: 20 | U1: 21 | V1: 22 | W1: 23 | X1: 24 | Z1: CEC 2020 Budget- Balance Sheets (for HQ Consolidation)
A2: Business Office : Taiwan Office | Z2: Business Office : Taiwan Office
A3: Currency : NTD | H3: =+H128-'A0 BS 1240在建'!#REF! -> #N/A | Z3: Currency : NTD
A4: BY Monthly _ for A0 BS 1240 | E4: =+E139-E79 -> -27724110 | H4: =+H139-H79 -> #N/A | I4: =+I139-I79 -> #N/A | J4: =+J139-J79 -> #N/A | K4: =+K139-K79 -> #N/A | L4: =+L139-L79 -> #N/A | M4: =+M139-M79 -> #N/A | N4: =+N139-N79 -> #N/A | O4: =+O139-O79 -> #N/A | ... X4: =+X139-X79 -> #N/A
A5: BS_WIP
A6: 2025.10.18 | D6: Actaul | E6: FCST | F6: 46022 | G6: 46387
A7: 月份 | D7: 45900 | E7: 9/1-12/31 | F7: Forecast | G7: Budget | H7: Year 2026 | I7: 46053 | J7: 46081 | K7: 46112 | L7: 46142 | M7: 46173 | N7: 46203 | O7: 46234 | P7: 46265 | Q7: 46295 | R7: 46326 | S7: 46356 | T7: 46387 | U7: Year 2027 | V7: Year 2028 | W7: Year 2029 | X7: Year 2030
A9: 流動資產: | Z9: Current Assets:
A10: 1100 現金及約當現金 | B10: 銀行存款 | E10: =SUMIF('A0 BS 1240在建'!$A$226:$A$245,$A10,'A0 BS 1240在建'!G$226:G$245) -> 0 | F10: =SUM(D10:E10) -> 0 | G10: =+F10+H10 -> 0 | I10: =SUMIF('A0 BS 1240在建'!$A$226:$A$245,$A10,'A0 BS 1240在建'!O$226:O$245) -> 0 | Z10: 1100 Cash and cash equivalents
A11: 1139 避險之金融資產-流動 | E11: =SUM(E12:E13) -> 0 | F11: =SUM(F12:F13) -> 0 | G11: =SUM(G12:G13) -> 0 | H11: =SUM(H12:H13) -> 0 | I11: =SUM(I12:I13) -> 0 | J11: =SUM(J12:J13) -> 0 | K11: =SUM(K12:K13) -> 0 | L11: =SUM(L12:L13) -> 0 | ... X11: =SUM(X12:X13) -> 0 | Z11: 1130 Current financial assets for hedging
A12: 1103外幣存款-避險 | B12: 銀行存款 | E12: =SUMIF('A0 BS 1240在建'!$A$226:$A$245, $A12,'A0 BS 1240在建'!G$226:G$245) -> 0 | F12: =SUM(D12:E12) -> 0 | G12: =+F12+H12 -> 0 | H12: =SUM(I12:T12) -> 0 | I12: =SUMIF('A0 BS 1240在建'!$A$226:$A$245,$A12,'A0 BS 1240在建'!O$226:O$245) -> 0 | J12: =SUMIF('A0 BS 1240在建'!$A$226:$A$245,$A12,'A0 BS 1240在建'!S$226:S$245) -> 0 | K12: =SUMIF('A0 BS 1240在建'!$A$226:$A$245,$A12,'A0 BS 1240在建'!W$226:W$245) -> 0 | L12: =SUMIF('A0 BS 1240在建'!$A$226:$A$245,$A12,'A0 BS 1240在建'!AA$226:AA$245) -> 0 | M12: =SUMIF('A0 BS 1240在建'!$A$226:$A$245,$A12,'A0 BS 1240在建'!AE$226:AE$245) -> 0 | N12: =SUMIF('A0 BS 1240在建'!$A$226:$A$245,$A12,'A0 BS 1240在建'!AI$226:AI$245) -> 0 | O12: =SUMIF('A0 BS 1240在建'!$A$226:$A$245,$A12,'A0 BS 1240在建'!AM$226:AM$245) -> 0 | P12: =SUMIF('A0 BS 1240在建'!$A$226:$A$245,$A12,'A0 BS 1240在建'!AQ$226:AQ$245) -> 0 | Q12: =SUMIF('A0 BS 1240在建'!$A$226:$A$245,$A12,'A0 BS 1240在建'!AU$226:AU$245) -> 0 | R12: =SUMIF('A0 BS 1240在建'!$A$226:$A$245,$A12,'A0 BS 1240在建'!AY$226:AY$245) -> 0 | S12: =SUMIF('A0 BS 1240在建'!$A$226:$A$245,$A12,'A0 BS 1240在建'!BC$226:BC$245) -> 0 | T12: =SUMIF('A0 BS 1240在建'!$A$226:$A$245,$A12,'A0 BS 1240在建'!BG$226:BG$245) -> 0 | U12: =SUMIF('A0 BS 1240在建'!$A$226:$A$245,$A12,'A0 BS 1240在建'!BS$226:BS$245) -> 0 | V12: =SUMIF('A0 BS 1240在建'!$A$226:$A$245,$A12,'A0 BS 1240在建'!CA$226:CA$245) -> 0 | W12: =SUMIF('A0 BS 1240在建'!$A$226:$A$245,$A12,'A0 BS 1240在建'!CB$226:CB$245) -> 0 | X12: =SUMIF('A0 BS 1240在建'!$A$226:$A$245,$A12,'A0 BS 1240在建'!CC$226:CC$245) -> 0
A13: 1139避險之金融資產-流動. | B13: 其他流動資產 | E13: =SUMIF('A0 BS 1240在建'!$A$226:$A$245, $A13,'A0 BS 1240在建'!G$226:G$245) -> 0 | F13: =SUM(D13:E13) -> 0 | G13: =+F13+H13 -> 0 | H13: =SUM(I13:T13) -> 0 | I13: =SUMIF('A0 BS 1240在建'!$A$226:$A$245,$A13,'A0 BS 1240在建'!O$226:O$245) -> 0 | J13: =SUMIF('A0 BS 1240在建'!$A$226:$A$245,$A13,'A0 BS 1240在建'!S$226:S$245) -> 0 | K13: =SUMIF('A0 BS 1240在建'!$A$226:$A$245,$A13,'A0 BS 1240在建'!W$226:W$245) -> 0 | L13: =SUMIF('A0 BS 1240在建'!$A$226:$A$245,$A13,'A0 BS 1240在建'!AA$226:AA$245) -> 0 | M13: =SUMIF('A0 BS 1240在建'!$A$226:$A$245,$A13,'A0 BS 1240在建'!AE$226:AE$245) -> 0 | N13: =SUMIF('A0 BS 1240在建'!$A$226:$A$245,$A13,'A0 BS 1240在建'!AI$226:AI$245) -> 0 | O13: =SUMIF('A0 BS 1240在建'!$A$226:$A$245,$A13,'A0 BS 1240在建'!AM$226:AM$245) -> 0 | P13: =SUMIF('A0 BS 1240在建'!$A$226:$A$245,$A13,'A0 BS 1240在建'!AQ$226:AQ$245) -> 0 | Q13: =SUMIF('A0 BS 1240在建'!$A$226:$A$245,$A13,'A0 BS 1240在建'!AU$226:AU$245) -> 0 | R13: =SUMIF('A0 BS 1240在建'!$A$226:$A$245,$A13,'A0 BS 1240在建'!AY$226:AY$245) -> 0 | S13: =SUMIF('A0 BS 1240在建'!$A$226:$A$245,$A13,'A0 BS 1240在建'!BC$226:BC$245) -> 0 | T13: =SUMIF('A0 BS 1240在建'!$A$226:$A$245,$A13,'A0 BS 1240在建'!BG$226:BG$245) -> 0 | U13: =SUMIF('A0 BS 1240在建'!$A$226:$A$245,$A13,'A0 BS 1240在建'!BS$226:BS$245) -> 0 | V13: =SUMIF('A0 BS 1240在建'!$A$226:$A$245,$A13,'A0 BS 1240在建'!CA$226:CA$245) -> 0 | W13: =SUMIF('A0 BS 1240在建'!$A$226:$A$245,$A13,'A0 BS 1240在建'!CB$226:CB$245) -> 0 | X13: =SUMIF('A0 BS 1240在建'!$A$226:$A$245,$A13,'A0 BS 1240在建'!CC$226:CC$245) -> 0
A14: 1190 應收建造合約款 | D14: =+#REF! -> #REF! | E14: =VLOOKUP($A14,'Over Under Bill 2'!$1:$1048576,4,0) -> 0 | F14: =+D14+E14 -> #REF! | G14: =+F14+H14 -> #REF! | H14: =SUM(I14:T14) -> 0 | I14: =VLOOKUP($A14,'Over Under Bill 2'!$1:$1048576,5,0) -> 0 | J14: =VLOOKUP($A14,'Over Under Bill 2'!$1:$1048576,6,0) -> 0 | K14: =VLOOKUP($A14,'Over Under Bill 2'!$1:$1048576,7,0) -> 0 | L14: =VLOOKUP($A14,'Over Under Bill 2'!$1:$1048576,8,0) -> 0 | M14: =VLOOKUP($A14,'Over Under Bill 2'!$1:$1048576,9,0) -> 0 | N14: =VLOOKUP($A14,'Over Under Bill 2'!$1:$1048576,10,0) -> 0 | O14: =VLOOKUP($A14,'Over Under Bill 2'!$1:$1048576,11,0) -> 0 | P14: =VLOOKUP($A14,'Over Under Bill 2'!$1:$1048576,12,0) -> 0 | Q14: =VLOOKUP($A14,'Over Under Bill 2'!$1:$1048576,13,0) -> 0 | R14: =VLOOKUP($A14,'Over Under Bill 2'!$1:$1048576,14,0) -> 0 | S14: =VLOOKUP($A14,'Over Under Bill 2'!$1:$1048576,15,0) -> 0 | T14: =VLOOKUP($A14,'Over Under Bill 2'!$1:$1048576,16,0) -> 0 | U14: =VLOOKUP($A14,'Over Under Bill 2'!$1:$1048576,17,0) -> 0 | V14: =VLOOKUP($A14,'Over Under Bill 2'!$1:$1048576,18,0) -> 0 | W14: =VLOOKUP($A14,'Over Under Bill 2'!$1:$1048576,19,0) -> 0 | X14: =VLOOKUP($A14,'Over Under Bill 2'!$1:$1048576,20,0) -> 0 | Z14: 1190 Construction contracts receivable
A15: 1240 X 在建工程_成本 | F15: =SUM(D15:E15) -> 0 | G15: =+F15+H15 -> 0 | H15: =SUM(I15:T15) -> 0 | Z15: 1240 X WIP -Cost Incurred
A16: 1247X 在建損益 | F16: =SUM(D16:E16) -> 0 | G16: =+F16+H16 -> 0 | H16: =SUM(I16:T16) -> 0 | Z16: 1247X WIP - P&L (by POC)
A17: 2264X 工程合約-其他預收工程款 | F17: =SUM(D17:E17) -> 0 | G17: =+F17+H17 -> 0 | H17: =SUM(I17:T17) -> 0 | Z17: 2264X Construction contracts - Progress billing
A18: 2264X 工程合約-業主預付款 | F18: =SUM(D18:E18) -> 0 | G18: =+F18+H18 -> 0 | H18: =SUM(I18:T18) -> 0 | Z18: 2264X Construction contracts -Client's Advance Payment
A19: 1141 合約資產-應收工程保留款 | B19: 應收款項 | E19: =SUMIF('A0 BS 1240在建'!$A$226:$A$245, $A19,'A0 BS 1240在建'!G$226:G$245) -> 0 | F19: =SUM(D19:E19) -> 0 | G19: =+F19+H19 -> 0 | H19: =SUM(I19:T19) -> 0 | I19: =SUMIF('A0 BS 1240在建'!$A$226:$A$245,$A19,'A0 BS 1240在建'!O$226:O$245) -> 0 | J19: =SUMIF('A0 BS 1240在建'!$A$226:$A$245,$A19,'A0 BS 1240在建'!S$226:S$245) -> 0 | K19: =SUMIF('A0 BS 1240在建'!$A$226:$A$245,$A19,'A0 BS 1240在建'!W$226:W$245) -> 0 | L19: =SUMIF('A0 BS 1240在建'!$A$226:$A$245,$A19,'A0 BS 1240在建'!AA$226:AA$245) -> 0 | M19: =SUMIF('A0 BS 1240在建'!$A$226:$A$245,$A19,'A0 BS 1240在建'!AE$226:AE$245) -> 0 | N19: =SUMIF('A0 BS 1240在建'!$A$226:$A$245,$A19,'A0 BS 1240在建'!AI$226:AI$245) -> 0 | O19: =SUMIF('A0 BS 1240在建'!$A$226:$A$245,$A19,'A0 BS 1240在建'!AM$226:AM$245) -> 0 | P19: =SUMIF('A0 BS 1240在建'!$A$226:$A$245,$A19,'A0 BS 1240在建'!AQ$226:AQ$245) -> 0 | Q19: =SUMIF('A0 BS 1240在建'!$A$226:$A$245,$A19,'A0 BS 1240在建'!AU$226:AU$245) -> 0 | R19: =SUMIF('A0 BS 1240在建'!$A$226:$A$245,$A19,'A0 BS 1240在建'!AY$226:AY$245) -> 0 | S19: =SUMIF('A0 BS 1240在建'!$A$226:$A$245,$A19,'A0 BS 1240在建'!BC$226:BC$245) -> 0 | T19: =SUMIF('A0 BS 1240在建'!$A$226:$A$245,$A19,'A0 BS 1240在建'!BG$226:BG$245) -> 0 | U19: =SUMIF('A0 BS 1240在建'!$A$226:$A$245,$A19,'A0 BS 1240在建'!BS$226:BS$245) -> 0 | V19: =SUMIF('A0 BS 1240在建'!$A$226:$A$245,$A19,'A0 BS 1240在建'!CA$226:CA$245) -> 0 | W19: =SUMIF('A0 BS 1240在建'!$A$226:$A$245,$A19,'A0 BS 1240在建'!CI$226:CI$245) -> 0 | X19: =SUMIF('A0 BS 1240在建'!$A$226:$A$245,$A19,'A0 BS 1240在建'!CQ$226:CQ$245) -> #REF! | Z19: 1141 Contract assets - Retention receivable
A20: 1142 合約資產-應收完工估列款 | B20: 應收款項 | E20: =SUMIF('A0 BS 1240在建'!$A$226:$A$245, $A20,'A0 BS 1240在建'!G$226:G$245) -> 0 | F20: =SUM(D20:E20) -> 0 | G20: =+F20+H20 -> 0 | H20: =SUM(I20:T20) -> 0 | I20: =SUMIF('A0 BS 1240在建'!$A$226:$A$245,$A20,'A0 BS 1240在建'!O$226:O$245) -> 0 | J20: =SUMIF('A0 BS 1240在建'!$A$226:$A$245,$A20,'A0 BS 1240在建'!S$226:S$245) -> 0 | K20: =SUMIF('A0 BS 1240在建'!$A$226:$A$245,$A20,'A0 BS 1240在建'!W$226:W$245) -> 0 | L20: =SUMIF('A0 BS 1240在建'!$A$226:$A$245,$A20,'A0 BS 1240在建'!AA$226:AA$245) -> 0 | M20: =SUMIF('A0 BS 1240在建'!$A$226:$A$245,$A20,'A0 BS 1240在建'!AE$226:AE$245) -> 0 | N20: =SUMIF('A0 BS 1240在建'!$A$226:$A$245,$A20,'A0 BS 1240在建'!AI$226:AI$245) -> 0 | O20: =SUMIF('A0 BS 1240在建'!$A$226:$A$245,$A20,'A0 BS 1240在建'!AM$226:AM$245) -> 0 | P20: =SUMIF('A0 BS 1240在建'!$A$226:$A$245,$A20,'A0 BS 1240在建'!AQ$226:AQ$245) -> 0 | Q20: =SUMIF('A0 BS 1240在建'!$A$226:$A$245,$A20,'A0 BS 1240在建'!AU$226:AU$245) -> 0 | R20: =SUMIF('A0 BS 1240在建'!$A$226:$A$245,$A20,'A0 BS 1240在建'!AY$226:AY$245) -> 0 | S20: =SUMIF('A0 BS 1240在建'!$A$226:$A$245,$A20,'A0 BS 1240在建'!BC$226:BC$245) -> 0 | T20: =SUMIF('A0 BS 1240在建'!$A$226:$A$245,$A20,'A0 BS 1240在建'!BG$226:BG$245) -> 0 | U20: =SUMIF('A0 BS 1240在建'!$A$226:$A$245,$A20,'A0 BS 1240在建'!BS$226:BS$245) -> 0 | V20: =SUMIF('A0 BS 1240在建'!$A$226:$A$245,$A20,'A0 BS 1240在建'!CA$226:CA$245) -> 0 | W20: =SUMIF('A0 BS 1240在建'!$A$226:$A$245,$A20,'A0 BS 1240在建'!CI$226:CI$245) -> 0 | X20: =SUMIF('A0 BS 1240在建'!$A$226:$A$245,$A20,'A0 BS 1240在建'!CQ$226:CQ$245) -> 0 | Z20: 1142 Contract assets - Accrual receivable
A21: 1150 應收票據淨額 | B21: 應收款項 | E21: =SUMIF('A0 BS 1240在建'!$A$226:$A$245, $A21,'A0 BS 1240在建'!G$226:G$245) -> 0 | F21: =SUM(D21:E21) -> 0 | G21: =+F21+H21 -> 0 | H21: =SUM(I21:T21) -> 0 | I21: =SUMIF('A0 BS 1240在建'!$A$226:$A$245,$A21,'A0 BS 1240在建'!O$226:O$245) -> 0 | J21: =SUMIF('A0 BS 1240在建'!$A$226:$A$245,$A21,'A0 BS 1240在建'!S$226:S$245) -> 0 | K21: =SUMIF('A0 BS 1240在建'!$A$226:$A$245,$A21,'A0 BS 1240在建'!W$226:W$245) -> 0 | L21: =SUMIF('A0 BS 1240在建'!$A$226:$A$245,$A21,'A0 BS 1240在建'!AA$226:AA$245) -> 0 | M21: =SUMIF('A0 BS 1240在建'!$A$226:$A$245,$A21,'A0 BS 1240在建'!AE$226:AE$245) -> 0 | N21: =SUMIF('A0 BS 1240在建'!$A$226:$A$245,$A21,'A0 BS 1240在建'!AI$226:AI$245) -> 0 | O21: =SUMIF('A0 BS 1240在建'!$A$226:$A$245,$A21,'A0 BS 1240在建'!AM$226:AM$245) -> 0 | P21: =SUMIF('A0 BS 1240在建'!$A$226:$A$245,$A21,'A0 BS 1240在建'!AQ$226:AQ$245) -> 0 | Q21: =SUMIF('A0 BS 1240在建'!$A$226:$A$245,$A21,'A0 BS 1240在建'!AU$226:AU$245) -> 0 | R21: =SUMIF('A0 BS 1240在建'!$A$226:$A$245,$A21,'A0 BS 1240在建'!AY$226:AY$245) -> 0 | S21: =SUMIF('A0 BS 1240在建'!$A$226:$A$245,$A21,'A0 BS 1240在建'!BC$226:BC$245) -> 0 | T21: =SUMIF('A0 BS 1240在建'!$A$226:$A$245,$A21,'A0 BS 1240在建'!BG$226:BG$245) -> 0 | U21: =SUMIF('A0 BS 1240在建'!$A$226:$A$245,$A21,'A0 BS 1240在建'!BS$226:BS$245) -> 0 | V21: =SUMIF('A0 BS 1240在建'!$A$226:$A$245,$A21,'A0 BS 1240在建'!CA$226:CA$245) -> 0 | W21: =SUMIF('A0 BS 1240在建'!$A$226:$A$245,$A21,'A0 BS 1240在建'!CI$226:CI$245) -> 0 | X21: =SUMIF('A0 BS 1240在建'!$A$226:$A$245,$A21,'A0 BS 1240在建'!CQ$226:CQ$245) -> 0 | Z21: 1150 Notes receivable, net
A22: 1170 應收帳款淨額 | B22: 應收款項 | E22: =SUMIF('A0 BS 1240在建'!$A$226:$A$245, $A22,'A0 BS 1240在建'!G$226:G$245) -> 21367000 | F22: =SUM(D22:E22) -> 21367000 | G22: =+F22+H22 -> #N/A | H22: =SUM(I22:T22) -> #N/A | I22: =SUMIF('A0 BS 1240在建'!$A$226:$A$245,$A22,'A0 BS 1240在建'!O$226:O$245) -> #N/A | J22: =SUMIF('A0 BS 1240在建'!$A$226:$A$245,$A22,'A0 BS 1240在建'!S$226:S$245) -> #N/A | K22: =SUMIF('A0 BS 1240在建'!$A$226:$A$245,$A22,'A0 BS 1240在建'!W$226:W$245) -> #N/A | L22: =SUMIF('A0 BS 1240在建'!$A$226:$A$245,$A22,'A0 BS 1240在建'!AA$226:AA$245) -> #N/A | M22: =SUMIF('A0 BS 1240在建'!$A$226:$A$245,$A22,'A0 BS 1240在建'!AE$226:AE$245) -> #N/A | N22: =SUMIF('A0 BS 1240在建'!$A$226:$A$245,$A22,'A0 BS 1240在建'!AI$226:AI$245) -> #N/A | O22: =SUMIF('A0 BS 1240在建'!$A$226:$A$245,$A22,'A0 BS 1240在建'!AM$226:AM$245) -> #N/A | P22: =SUMIF('A0 BS 1240在建'!$A$226:$A$245,$A22,'A0 BS 1240在建'!AQ$226:AQ$245) -> #N/A | Q22: =SUMIF('A0 BS 1240在建'!$A$226:$A$245,$A22,'A0 BS 1240在建'!AU$226:AU$245) -> #N/A | R22: =SUMIF('A0 BS 1240在建'!$A$226:$A$245,$A22,'A0 BS 1240在建'!AY$226:AY$245) -> #N/A | S22: =SUMIF('A0 BS 1240在建'!$A$226:$A$245,$A22,'A0 BS 1240在建'!BC$226:BC$245) -> #N/A | T22: =SUMIF('A0 BS 1240在建'!$A$226:$A$245,$A22,'A0 BS 1240在建'!BG$226:BG$245) -> #N/A | U22: =SUMIF('A0 BS 1240在建'!$A$226:$A$245,$A22,'A0 BS 1240在建'!BS$226:BS$245) -> #N/A | V22: =SUMIF('A0 BS 1240在建'!$A$226:$A$245,$A22,'A0 BS 1240在建'!CA$226:CA$245) -> #N/A | W22: =SUMIF('A0 BS 1240在建'!$A$226:$A$245,$A22,'A0 BS 1240在建'!CI$226:CI$245) -> #N/A | X22: =SUMIF('A0 BS 1240在建'!$A$226:$A$245,$A22,'A0 BS 1240在建'!CQ$226:CQ$245) -> #N/A | Z22: 1170 Accounts receivable, net
A23: 1180 應收帳款-關係人淨額 | E23: =SUMIF('A0 BS 1240在建'!$A$226:$A$245, $A23,'A0 BS 1240在建'!G$226:G$245) -> 0 | F23: =SUM(D23:E23) -> 0 | G23: =+F23+H23 -> 0 | H23: =SUM(I23:T23) -> 0 | I23: =SUMIF('A0 BS 1240在建'!$A$226:$A$245,$A23,'A0 BS 1240在建'!O$226:O$245) -> 0 | J23: =SUMIF('A0 BS 1240在建'!$A$226:$A$245,$A23,'A0 BS 1240在建'!S$226:S$245) -> 0 | K23: =SUMIF('A0 BS 1240在建'!$A$226:$A$245,$A23,'A0 BS 1240在建'!W$226:W$245) -> 0 | L23: =SUMIF('A0 BS 1240在建'!$A$226:$A$245,$A23,'A0 BS 1240在建'!AA$226:AA$245) -> 0 | M23: =SUMIF('A0 BS 1240在建'!$A$226:$A$245,$A23,'A0 BS 1240在建'!AE$226:AE$245) -> 0 | N23: =SUMIF('A0 BS 1240在建'!$A$226:$A$245,$A23,'A0 BS 1240在建'!AI$226:AI$245) -> 0 | O23: =SUMIF('A0 BS 1240在建'!$A$226:$A$245,$A23,'A0 BS 1240在建'!AM$226:AM$245) -> 0 | P23: =SUMIF('A0 BS 1240在建'!$A$226:$A$245,$A23,'A0 BS 1240在建'!AQ$226:AQ$245) -> 0 | Q23: =SUMIF('A0 BS 1240在建'!$A$226:$A$245,$A23,'A0 BS 1240在建'!AU$226:AU$245) -> 0 | R23: =SUMIF('A0 BS 1240在建'!$A$226:$A$245,$A23,'A0 BS 1240在建'!AY$226:AY$245) -> 0 | S23: =SUMIF('A0 BS 1240在建'!$A$226:$A$245,$A23,'A0 BS 1240在建'!BC$226:BC$245) -> 0 | T23: =SUMIF('A0 BS 1240在建'!$A$226:$A$245,$A23,'A0 BS 1240在建'!BG$226:BG$245) -> 0 | U23: =SUMIF('A0 BS 1240在建'!$A$226:$A$245,$A23,'A0 BS 1240在建'!BS$226:BS$245) -> 0 | V23: =SUMIF('A0 BS 1240在建'!$A$226:$A$245,$A23,'A0 BS 1240在建'!CA$226:CA$245) -> 0 | W23: =SUMIF('A0 BS 1240在建'!$A$226:$A$245,$A23,'A0 BS 1240在建'!CI$226:CI$245) -> 0 | X23: =SUMIF('A0 BS 1240在建'!$A$226:$A$245,$A23,'A0 BS 1240在建'!CQ$226:CQ$245) -> 0 | Z23: 1180 Accounts receivable-related parties, net
A24: 1200 其他應收款 | B24: 其他流動資產 | E24: =SUMIF('A0 BS 1240在建'!$A$226:$A$245, $A24,'A0 BS 1240在建'!G$226:G$245) -> 0 | F24: =SUM(D24:E24) -> 0 | G24: =+F24+H24 -> 0 | H24: =SUM(I24:T24) -> 0 | I24: =SUMIF('A0 BS 1240在建'!$A$226:$A$245,$A24,'A0 BS 1240在建'!O$226:O$245) -> 0 | J24: =SUMIF('A0 BS 1240在建'!$A$226:$A$245,$A24,'A0 BS 1240在建'!S$226:S$245) -> 0 | K24: =SUMIF('A0 BS 1240在建'!$A$226:$A$245,$A24,'A0 BS 1240在建'!W$226:W$245) -> 0 | L24: =SUMIF('A0 BS 1240在建'!$A$226:$A$245,$A24,'A0 BS 1240在建'!AA$226:AA$245) -> 0 | M24: =SUMIF('A0 BS 1240在建'!$A$226:$A$245,$A24,'A0 BS 1240在建'!AE$226:AE$245) -> 0 | N24: =SUMIF('A0 BS 1240在建'!$A$226:$A$245,$A24,'A0 BS 1240在建'!AI$226:AI$245) -> 0 | O24: =SUMIF('A0 BS 1240在建'!$A$226:$A$245,$A24,'A0 BS 1240在建'!AM$226:AM$245) -> 0 | P24: =SUMIF('A0 BS 1240在建'!$A$226:$A$245,$A24,'A0 BS 1240在建'!AQ$226:AQ$245) -> 0 | Q24: =SUMIF('A0 BS 1240在建'!$A$226:$A$245,$A24,'A0 BS 1240在建'!AU$226:AU$245) -> 0 | R24: =SUMIF('A0 BS 1240在建'!$A$226:$A$245,$A24,'A0 BS 1240在建'!AY$226:AY$245) -> 0 | S24: =SUMIF('A0 BS 1240在建'!$A$226:$A$245,$A24,'A0 BS 1240在建'!BC$226:BC$245) -> 0 | T24: =SUMIF('A0 BS 1240在建'!$A$226:$A$245,$A24,'A0 BS 1240在建'!BG$226:BG$245) -> 0 | U24: =SUMIF('A0 BS 1240在建'!$A$226:$A$245,$A24,'A0 BS 1240在建'!BS$226:BS$245) -> 0 | V24: =SUMIF('A0 BS 1240在建'!$A$226:$A$245,$A24,'A0 BS 1240在建'!CA$226:CA$245) -> 0 | W24: =SUMIF('A0 BS 1240在建'!$A$226:$A$245,$A24,'A0 BS 1240在建'!CI$226:CI$245) -> 0 | X24: =SUMIF('A0 BS 1240在建'!$A$226:$A$245,$A24,'A0 BS 1240在建'!CQ$226:CQ$245) -> 0 | Z24: 1200 Other receivable
A25: 1220 當期所得稅資產 | B25: 其他流動資產 | E25: =SUMIF('A0 BS 1240在建'!$A$226:$A$245, $A25,'A0 BS 1240在建'!G$226:G$245) -> 0 | F25: =SUM(D25:E25) -> 0 | G25: =+F25+H25 -> 0 | H25: =SUM(I25:T25) -> 0 | I25: =SUMIF('A0 BS 1240在建'!$A$226:$A$245,$A25,'A0 BS 1240在建'!O$226:O$245) -> 0 | J25: =SUMIF('A0 BS 1240在建'!$A$226:$A$245,$A25,'A0 BS 1240在建'!S$226:S$245) -> 0 | K25: =SUMIF('A0 BS 1240在建'!$A$226:$A$245,$A25,'A0 BS 1240在建'!W$226:W$245) -> 0 | L25: =SUMIF('A0 BS 1240在建'!$A$226:$A$245,$A25,'A0 BS 1240在建'!AA$226:AA$245) -> 0 | M25: =SUMIF('A0 BS 1240在建'!$A$226:$A$245,$A25,'A0 BS 1240在建'!AE$226:AE$245) -> 0 | N25: =SUMIF('A0 BS 1240在建'!$A$226:$A$245,$A25,'A0 BS 1240在建'!AI$226:AI$245) -> 0 | O25: =SUMIF('A0 BS 1240在建'!$A$226:$A$245,$A25,'A0 BS 1240在建'!AM$226:AM$245) -> 0 | P25: =SUMIF('A0 BS 1240在建'!$A$226:$A$245,$A25,'A0 BS 1240在建'!AQ$226:AQ$245) -> 0 | Q25: =SUMIF('A0 BS 1240在建'!$A$226:$A$245,$A25,'A0 BS 1240在建'!AU$226:AU$245) -> 0 | R25: =SUMIF('A0 BS 1240在建'!$A$226:$A$245,$A25,'A0 BS 1240在建'!AY$226:AY$245) -> 0 | S25: =SUMIF('A0 BS 1240在建'!$A$226:$A$245,$A25,'A0 BS 1240在建'!BC$226:BC$245) -> 0 | T25: =SUMIF('A0 BS 1240在建'!$A$226:$A$245,$A25,'A0 BS 1240在建'!BG$226:BG$245) -> 0 | U25: =SUMIF('A0 BS 1240在建'!$A$226:$A$245,$A25,'A0 BS 1240在建'!BS$226:BS$245) -> 0 | V25: =SUMIF('A0 BS 1240在建'!$A$226:$A$245,$A25,'A0 BS 1240在建'!CA$226:CA$245) -> 0 | W25: =SUMIF('A0 BS 1240在建'!$A$226:$A$245,$A25,'A0 BS 1240在建'!CI$226:CI$245) -> 0 | X25: =SUMIF('A0 BS 1240在建'!$A$226:$A$245,$A25,'A0 BS 1240在建'!CQ$226:CQ$245) -> 0 | Z25: 1220 Current tax assets
A26: 130X 存貨 | E26: =SUMIF('A0 BS 1240在建'!$A$226:$A$245, $A26,'A0 BS 1240在建'!G$226:G$245) -> 0 | F26: =SUM(D26:E26) -> 0 | G26: =+F26+H26 -> 0 | H26: =SUM(I26:T26) -> 0 | I26: =SUMIF('A0 BS 1240在建'!$A$226:$A$245,$A26,'A0 BS 1240在建'!O$226:O$245) -> 0 | J26: =SUMIF('A0 BS 1240在建'!$A$226:$A$245,$A26,'A0 BS 1240在建'!S$226:S$245) -> 0 | K26: =SUMIF('A0 BS 1240在建'!$A$226:$A$245,$A26,'A0 BS 1240在建'!W$226:W$245) -> 0 | L26: =SUMIF('A0 BS 1240在建'!$A$226:$A$245,$A26,'A0 BS 1240在建'!AA$226:AA$245) -> 0 | M26: =SUMIF('A0 BS 1240在建'!$A$226:$A$245,$A26,'A0 BS 1240在建'!AE$226:AE$245) -> 0 | N26: =SUMIF('A0 BS 1240在建'!$A$226:$A$245,$A26,'A0 BS 1240在建'!AI$226:AI$245) -> 0 | O26: =SUMIF('A0 BS 1240在建'!$A$226:$A$245,$A26,'A0 BS 1240在建'!AM$226:AM$245) -> 0 | P26: =SUMIF('A0 BS 1240在建'!$A$226:$A$245,$A26,'A0 BS 1240在建'!AQ$226:AQ$245) -> 0 | Q26: =SUMIF('A0 BS 1240在建'!$A$226:$A$245,$A26,'A0 BS 1240在建'!AU$226:AU$245) -> 0 | R26: =SUMIF('A0 BS 1240在建'!$A$226:$A$245,$A26,'A0 BS 1240在建'!AY$226:AY$245) -> 0 | S26: =SUMIF('A0 BS 1240在建'!$A$226:$A$245,$A26,'A0 BS 1240在建'!BC$226:BC$245) -> 0 | T26: =SUMIF('A0 BS 1240在建'!$A$226:$A$245,$A26,'A0 BS 1240在建'!BG$226:BG$245) -> 0 | U26: =SUMIF('A0 BS 1240在建'!$A$226:$A$245,$A26,'A0 BS 1240在建'!BS$226:BS$245) -> 0 | V26: =SUMIF('A0 BS 1240在建'!$A$226:$A$245,$A26,'A0 BS 1240在建'!CA$226:CA$245) -> 0 | W26: =SUMIF('A0 BS 1240在建'!$A$226:$A$245,$A26,'A0 BS 1240在建'!CI$226:CI$245) -> 0 | X26: =SUMIF('A0 BS 1240在建'!$A$226:$A$245,$A26,'A0 BS 1240在建'!CQ$226:CQ$245) -> 0 | Z26: 130X Inventories
A27: 1410 預付款項 | B27: 其他流動資產 | E27: =SUMIF('A0 BS 1240在建'!$A$226:$A$245, $A27,'A0 BS 1240在建'!G$226:G$245) -> 0 | F27: =SUM(D27:E27) -> 0 | G27: =+F27+H27 -> 0 | H27: =SUM(I27:T27) -> 0 | I27: =SUMIF('A0 BS 1240在建'!$A$226:$A$245,$A27,'A0 BS 1240在建'!O$226:O$245) -> 0 | J27: =SUMIF('A0 BS 1240在建'!$A$226:$A$245,$A27,'A0 BS 1240在建'!S$226:S$245) -> 0 | K27: =SUMIF('A0 BS 1240在建'!$A$226:$A$245,$A27,'A0 BS 1240在建'!W$226:W$245) -> 0 | L27: =SUMIF('A0 BS 1240在建'!$A$226:$A$245,$A27,'A0 BS 1240在建'!AA$226:AA$245) -> 0 | M27: =SUMIF('A0 BS 1240在建'!$A$226:$A$245,$A27,'A0 BS 1240在建'!AE$226:AE$245) -> 0 | N27: =SUMIF('A0 BS 1240在建'!$A$226:$A$245,$A27,'A0 BS 1240在建'!AI$226:AI$245) -> 0 | O27: =SUMIF('A0 BS 1240在建'!$A$226:$A$245,$A27,'A0 BS 1240在建'!AM$226:AM$245) -> 0 | P27: =SUMIF('A0 BS 1240在建'!$A$226:$A$245,$A27,'A0 BS 1240在建'!AQ$226:AQ$245) -> 0 | Q27: =SUMIF('A0 BS 1240在建'!$A$226:$A$245,$A27,'A0 BS 1240在建'!AU$226:AU$245) -> 0 | R27: =SUMIF('A0 BS 1240在建'!$A$226:$A$245,$A27,'A0 BS 1240在建'!AY$226:AY$245) -> 0 | S27: =SUMIF('A0 BS 1240在建'!$A$226:$A$245,$A27,'A0 BS 1240在建'!BC$226:BC$245) -> 0 | T27: =SUMIF('A0 BS 1240在建'!$A$226:$A$245,$A27,'A0 BS 1240在建'!BG$226:BG$245) -> 0 | U27: =SUMIF('A0 BS 1240在建'!$A$226:$A$245,$A27,'A0 BS 1240在建'!BS$226:BS$245) -> 0 | V27: =SUMIF('A0 BS 1240在建'!$A$226:$A$245,$A27,'A0 BS 1240在建'!CA$226:CA$245) -> 0 | W27: =SUMIF('A0 BS 1240在建'!$A$226:$A$245,$A27,'A0 BS 1240在建'!CI$226:CI$245) -> 0 | X27: =SUMIF('A0 BS 1240在建'!$A$226:$A$245,$A27,'A0 BS 1240在建'!CQ$226:CQ$245) -> 0 | Z27: 1410 Prepayments
A28: 1470 其他流動資產 | E28: =SUM(E29:E31) -> 0 | F28: =SUM(F29:F31) -> 0 | G28: =+F28+H28 -> 0 | H28: =SUM(I28:T28) -> 0 | I28: =SUM(I29:I31) -> 0 | J28: =SUM(J29:J31) -> 0 | K28: =SUM(K29:K31) -> 0 | L28: =SUM(L29:L31) -> 0 | M28: =SUM(M29:M31) -> 0 | N28: =SUM(N29:N31) -> 0 | O28: =SUM(O29:O31) -> 0 | P28: =SUM(P29:P31) -> 0 | ... V28: =SUM(V29:V31) -> 0 | W28: =SUMIF('A0 BS 1240在建'!$A$226:$A$245,$A28,'A0 BS 1240在建'!CI$226:CI$245) -> 0 | X28: =SUMIF('A0 BS 1240在建'!$A$226:$A$245,$A28,'A0 BS 1240在建'!CQ$226:CQ$245) -> 0 | Z28: 1470 Other current assets
A29: 質押定期存款 | B29: 銀行存款 | E29: =SUMIF('A0 BS 1240在建'!$A$226:$A$245, $A29,'A0 BS 1240在建'!G$226:G$245) -> 0 | F29: =SUM(D29:E29) -> 0 | G29: =+F29+H29 -> 0 | H29: =SUM(I29:T29) -> 0
A30: 銀行存款-備償 | B30: 銀行存款 | E30: =SUMIF('A0 BS 1240在建'!$A$226:$A$245, $A30,'A0 BS 1240在建'!G$226:G$245) -> 0 | F30: =SUM(D30:E30) -> 0 | G30: =+F30+H30 -> 0 | H30: =SUM(I30:T30) -> 0
A31: 其他流動資產 | B31: 其他流動資產 | E31: =SUMIF('A0 BS 1240在建'!$A$226:$A$245, $A31,'A0 BS 1240在建'!G$226:G$245) -> 0 | F31: =SUM(D31:E31) -> 0 | G31: =+F31+H31 -> 0 | H31: =SUM(I31:T31) -> 0
A32: 1471 公司內部往來: | E32: =SUM(E33:E40) -> 0 | F32: =SUM(F33:F40) -> 0 | G32: =SUM(G33:G40) -> 0 | H32: =SUM(H33:H40) -> 0 | I32: =SUM(I33:I40) -> 0 | J32: =SUM(J33:J40) -> 0 | K32: =SUM(K33:K40) -> 0 | L32: =SUM(L33:L40) -> 0 | ... X32: =SUM(X33:X40) -> 0 | Z32: 1471 Intercompany current account :
A33: 台灣事業處 | F33: =SUM(D33:E33) -> 0 | G33: =+F33+H33 -> 0 | H33: =SUM(I33:T33) -> 0 | Z33: Taiwan/HQ
A34: 台灣事業處-資金往來 | F34: =SUM(D34:E34) -> 0 | G34: =+F34+H34 -> 0 | H34: =SUM(I34:T34) -> 0 | Z34: Taiwan/HQ -Funding
A35: 香港分公司 | F35: =SUM(D35:E35) -> 0 | G35: =+F35+H35 -> 0 | H35: =SUM(I35:T35) -> 0 | Z35: HK branch /HQ
A36: 香港子公司 | F36: =SUM(D36:E36) -> 0 | G36: =+F36+H36 -> 0 | H36: =SUM(I36:T36) -> 0 | Z36: HK subsidiary/HQ
A37: 澳門分公司 | F37: =SUM(D37:E37) -> 0 | G37: =+F37+H37 -> 0 | H37: =SUM(I37:T37) -> 0 | Z37: Macau branch /HQ
A38: 印度專案辦公室 | F38: =SUM(D38:E38) -> 0 | G38: =+F38+H38 -> 0 | H38: =SUM(I38:T38) -> 0 | Z38: ICEC/HQ
A39: 印度子公司 | F39: =SUM(D39:E39) -> 0 | G39: =+F39+H39 -> 0 | H39: =SUM(I39:T39) -> 0 | Z39: CICI/HQ
A40: 馬來西亞子公司 | F40: =SUM(D40:E40) -> 0 | G40: =+F40+H40 -> 0 | H40: =SUM(I40:T40) -> 0 | Z40: CIMY/HQ
A41: 流動資產小計 | D41: =SUM(D10:D14,D19:D32)-SUM(D12:D13)-SUM(D29:D31) -> #REF! | E41: =SUM(E10:E14,E19:E32)-SUM(E12:E13)-SUM(E29:E31) -> 21367000 | F41: =SUM(F10:F14,F19:F32)-SUM(F12:F13)-SUM(F29:F31) -> #REF! | G41: =+F41+H41 -> #REF! | H41: =SUM(I41:T41) -> #N/A | I41: =SUM(I10:I14,I19:I32)-SUM(I12:I13)-SUM(I29:I31) -> #N/A | J41: =SUM(J10:J14,J19:J32)-SUM(J12:J13)-SUM(J29:J31) -> #N/A | K41: =SUM(K10:K14,K19:K32)-SUM(K12:K13)-SUM(K29:K31) -> #N/A | L41: =SUM(L10:L14,L19:L32)-SUM(L12:L13)-SUM(L29:L31) -> #N/A | M41: =SUM(M10:M14,M19:M32)-SUM(M12:M13)-SUM(M29:M31) -> #N/A | N41: =SUM(N10:N14,N19:N32)-SUM(N12:N13)-SUM(N29:N31) -> #N/A | O41: =SUM(O10:O14,O19:O32)-SUM(O12:O13)-SUM(O29:O31) -> #N/A | P41: =SUM(P10:P14,P19:P32)-SUM(P12:P13)-SUM(P29:P31) -> #N/A | ... X41: =SUM(X10:X14,X19:X32)-SUM(X12:X13)-SUM(X29:X31) -> #REF! | Z41: Subtotal Current assets
...

Sheet Over Under Bill 1 COPY 到CO欄位
A1: 2026年 | B1: Budget | C1: 3 | D1: 4 | E1: 5 | F1: 6 | G1: 7 | H1: 8 | I1: 9 | J1: 10 | K1: 11 | L1: 12 | M1: 13 | N1: 14 | O1: 15 | P1: 16 | Q1: 17 | R1: 18 | S1: 19 | T1: 20 | U1: 21 | V1: 22 | W1: 23 | X1: 24 | Y1: 25 | Z1: 26 | AA1: 27 | AB1: 28 | AC1: 29 | AD1: 30 | AE1: 31 | AF1: 32 | AG1: 33 | AH1: 34 | AI1: 35 | AJ1: 36 | AK1: 37 | AL1: 38 | AM1: 39 | AN1: 40 | AO1: 41 | AP1: 42 | AQ1: 43 | AR1: 44 | AS1: 45 | AT1: 46 | AU1: 47 | AV1: 48 | AW1: 49 | AX1: 50 | AY1: 51 | AZ1: 52 | BA1: 53 | BB1: 54 | BC1: 55 | BD1: 56 | BE1: 57 | BF1: 58 | BG1: 59 | BH1: 60 | BI1: 61 | BJ1: 62 | BK1: 63 | BL1: 64 | BM1: 65 | BN1: 66 | BO1: 67 | BP1: 68 | BQ1: 69 | BR1: 70 | BS1: 71 | BT1: 72 | BU1: 73 | BV1: 74 | BW1: 75 | BX1: 76 | BY1: 77 | BZ1: 78 | CA1: 79 | CB1: 80 | CC1: 81 | CD1: 82 | CE1: 83 | CF1: 84 | CG1: 85 | CH1: 86 | CI1: 87 | CJ1: 88 | CK1: 89 | CL1: 90 | CM1: 91 | CN1: 92 | CP1: 公式詳註解,其他年度以此類推 | CY1: Year 2026 (內部使用)
A2: WIP - IPC | B2: 公式不同 | E2: 累計至2025/8 | J2: 累計2025/12 | O2: 累計2026/1 | T2: 累計2026/2 | Y2: 累計2026/3 | AD2: 累計2026/4 | AI2: 累計2026/5 | AN2: 累計2026/6 | AS2: 累計2026/7 | AX2: 累計2026/8 | BC2: 累計2026/9 | BH2: 累計2026/10 | BM2: 累計2026/11 | BR2: 累計2026/12 | BW2: 累計2027/12 | CB2: 累計2028/12 | CG2: 累計2029/12 | CL2: 累計2030/12 | CQ2: 2024/9 - 2024/12 | CV2: Year 2025 | CY2: 應收建造變動數(正數增加,負數減少) | DD2: 應付建造變動數(正數增加,負數減少)
C3: 1240+1247 | D3: 2264+22641 | E3: 應收(付)建造 | F3: 22642業主預付款 | G3: 合約資產 | H3: 1240+1247 | I3: 2264+22641 | J3: 應收(付)建造 | K3: 22642業主預付款 | L3: 合約資產 | M3: 1240+1247 | N3: 2264+22641 | O3: 應收(付)建造 | P3: 22642業主預付款 | Q3: 合約資產 | R3: 1240+1247 | S3: 2264+22641 | T3: 應收(付)建造 | U3: 22642業主預付款 | V3: 合約資產 | W3: 1240+1247 | X3: 2264+22641 | Y3: 應收(付)建造 | Z3: 22642業主預付款 | AA3: 合約資產 | AB3: 1240+1247 | AC3: 2264+22641 | AD3: 應收(付)建造 | AE3: 22642業主預付款 | AF3: 合約資產 | AG3: 1240+1247 | AH3: 2264+22641 | AI3: 應收(付)建造 | AJ3: 22642業主預付款 | AK3: 合約資產 | AL3: 1240+1247 | AM3: 2264+22641 | AN3: 應收(付)建造 | AO3: 22642業主預付款 | AP3: 合約資產 | AQ3: 1240+1247 | AR3: 2264+22641 | AS3: 應收(付)建造 | AT3: 22642業主預付款 | AU3: 合約資產 | AV3: 1240+1247 | AW3: 2264+22641 | AX3: 應收(付)建造 | AY3: 22642業主預付款 | AZ3: 合約資產 | BA3: 1240+1247 | BB3: 2264+22641 | BC3: 應收(付)建造 | BD3: 22642業主預付款 | BE3: 合約資產 | BF3: 1240+1247 | BG3: 2264+22641 | BH3: 應收(付)建造 | BI3: 22642業主預付款 | BJ3: 合約資產 | BK3: 1240+1247 | BL3: 2264+22641 | BM3: 應收(付)建造 | BN3: 22642業主預付款 | BO3: 合約資產 | BP3: 1240+1247 | BQ3: 2264+22641 | BR3: 應收(付)建造 | BS3: 22642業主預付款 | BT3: 合約資產 | BU3: 1240+1247 | BV3: 2264+22641 | BW3: 應收(付)建造 | BX3: 22642業主預付款 | BY3: 合約資產 | BZ3: 1240+1247 | CA3: 2264+22641 | CB3: 應收(付)建造 | CC3: 22642業主預付款 | CD3: 合約資產 | CE3: 1240+1247 | CF3: 2264+22641 | CG3: 應收(付)建造 | CH3: 22642業主預付款 | CI3: 合約資產 | CJ3: 1240+1247 | CK3: 2264+22641 | CL3: 應收(付)建造 | CM3: 22642業主預付款 | CN3: 合約資產 | CP3: 應收(付)建造 | CQ3: 應收建造 | CR3: 應付建造 | CU3: 應收(付)建造 | CV3: 應收建造 | CW3: 應付建造 | CY3: 情況一 | CZ3: 情況二 | DA3: 情況三 | DB3: 情況四 | DC3: Total | DD3: 情況一 | DE3: 情況二 | DF3: 情況三 | DG3: 情況四 | DH3: Total
A4: 工程代碼 | B4: 工 程 名 稱 | C4: Revenue | D4: IPC from Client | E4: Under(Over) Bill | F4: Adv. Payment | G4: (合約負債) | H4: Revenue | I4: IPC from Client | J4: Under(Over) Bill | K4: Adv. Payment | L4: (合約負債) | M4: Revenue | N4: IPC from Client | O4: Under(Over) Bill | P4: Adv. Payment | Q4: (合約負債) | R4: Revenue | S4: IPC from Client | T4: Under(Over) Bill | U4: Adv. Payment | V4: (合約負債) | W4: Revenue | X4: IPC from Client | Y4: Under(Over) Bill | Z4: Adv. Payment | AA4: (合約負債) | AB4: Revenue | AC4: IPC from Client | AD4: Under(Over) Bill | AE4: Adv. Payment | AF4: (合約負債) | AG4: Revenue | AH4: IPC from Client | AI4: Under(Over) Bill | AJ4: Adv. Payment | AK4: (合約負債) | AL4: Revenue | AM4: IPC from Client | AN4: Under(Over) Bill | AO4: Adv. Payment | AP4: (合約負債) | AQ4: Revenue | AR4: IPC from Client | AS4: Under(Over) Bill | AT4: Adv. Payment | AU4: (合約負債) | AV4: Revenue | AW4: IPC from Client | AX4: Under(Over) Bill | AY4: Adv. Payment | AZ4: (合約負債) | BA4: Revenue | BB4: IPC from Client | BC4: Under(Over) Bill | BD4: Adv. Payment | BE4: (合約負債) | BF4: Revenue | BG4: IPC from Client | BH4: Under(Over) Bill | BI4: Adv. Payment | BJ4: (合約負債) | BK4: Revenue | BL4: IPC from Client | BM4: Under(Over) Bill | BN4: Adv. Payment | BO4: (合約負債) | BP4: Revenue | BQ4: IPC from Client | BR4: Under(Over) Bill | BS4: Adv. Payment | BT4: (合約負債) | BU4: Revenue | BV4: IPC from Client | BW4: Under(Over) Bill | BX4: Adv. Payment | BY4: (合約負債) | BZ4: Revenue | CA4: IPC from Client | CB4: Under(Over) Bill | CC4: Adv. Payment | CD4: (合約負債) | CE4: Revenue | CF4: IPC from Client | CG4: Under(Over) Bill | CH4: Adv. Payment | CI4: (合約負債) | CJ4: Revenue | CK4: IPC from Client | CL4: Under(Over) Bill | CM4: Adv. Payment | CN4: (合約負債) | CP4: Under(Over) Bill | CQ4: Under Bill | CR4: Over Bill | CU4: Under(Over) Bill | CV4: Under Bill | CW4: Over Bill | CY4: 2年年底皆應收 | CZ4: 由應收轉應付 | DA4: 由應付轉應收 | DB4: 上年應收，本年0 | DD4: 2年年底皆應付 | DE4: 由應付轉應收 | DF4: 由應收轉應付 | DG4: 上年0，本年應付
A5: C/4120P | B5: 大安洞道(含未來損失) | C5: =IFERROR(VLOOKUP($A5,'A0 BS 1240在建'!$1:$1048576,5,0),0) -> 0 | D5: =IFERROR(VLOOKUP($A5,'B0 2264預收'!$1:$1048576,5,0),0) -> 0 | E5: =+C5-D5 -> 0 | F5: =IFERROR(VLOOKUP($A5,'B0 2264預收'!$1:$1048576,6,0),0) -> 0 | G5: =+E5-F5 -> 0 | H5: =IFERROR(VLOOKUP($A5,'A0 BS 1240在建'!$1:$1048576,13,0),0) -> 0 | I5: =IFERROR(VLOOKUP($A5,'B0 2264預收'!$1:$1048576,13,0),0) -> 0 | J5: =+H5-I5 -> 0 | K5: =IFERROR(VLOOKUP($A5,'B0 2264預收'!$1:$1048576,14,0),0) -> 0 | L5: =+H5-I5-K5 -> 0 | M5: =H5+IFERROR(VLOOKUP($A5,'A0 BS 1240在建'!$1:$1048576,17,0),0) -> 0 | N5: =I5+IFERROR(VLOOKUP($A5,'B0 2264預收'!$1:$1048576,17,0),0) -> 0 | O5: =+M5-N5 -> 0 | P5: =K5+IFERROR(+VLOOKUP($A5,'B0 2264預收'!$1:$1048576,18,0),0) -> 0 | Q5: =+O5-P5 -> 0 | R5: =M5+IFERROR(VLOOKUP($A5,'A0 BS 1240在建'!$1:$1048576,21,0),0) -> 0 | S5: =+N5+IFERROR(VLOOKUP($A5,'B0 2264預收'!$1:$1048576,21,0),0) -> 0 | T5: =+R5-S5 -> 0 | U5: =+P5+IFERROR(+VLOOKUP($A5,'B0 2264預收'!$1:$1048576,22,0),0) -> 0 | V5: =+T5-U5 -> 0 | W5: =+R5+IFERROR(VLOOKUP($A5,'A0 BS 1240在建'!$1:$1048576,25,0),0) -> 0 | X5: =+S5+IFERROR(VLOOKUP($A5,'B0 2264預收'!$1:$1048576,25,0),0) -> 0 | Y5: =+W5-X5 -> 0 | Z5: =+U5+IFERROR(+VLOOKUP($A5,'B0 2264預收'!$1:$1048576,26,0),0) -> 0 | AA5: =+Y5-Z5 -> 0 | AB5: =+W5+IFERROR(VLOOKUP($A5,'A0 BS 1240在建'!$1:$1048576,29,0),0) -> 0 | AC5: =+X5+IFERROR(VLOOKUP($A5,'B0 2264預收'!$1:$1048576,29,0),0) -> 0 | AD5: =+AB5-AC5 -> 0 | AE5: =+Z5+IFERROR(+VLOOKUP($A5,'B0 2264預收'!$1:$1048576,30,0),0) -> 0 | AF5: =+AD5-AE5 -> 0 | AG5: =+AB5+IFERROR(VLOOKUP($A5,'A0 BS 1240在建'!$1:$1048576,33,0),0) -> 0 | AH5: =+AC5+IFERROR(VLOOKUP($A5,'B0 2264預收'!$1:$1048576,33,0),0) -> 0 | AI5: =+AG5-AH5 -> 0 | AJ5: =+AE5+IFERROR(+VLOOKUP($A5,'B0 2264預收'!$1:$1048576,34,0),0) -> 0 | AK5: =+AI5-AJ5 -> 0 | AL5: =+AG5+IFERROR(VLOOKUP($A5,'A0 BS 1240在建'!$1:$1048576,37,0),0) -> 0 | AM5: =+AH5+IFERROR(VLOOKUP($A5,'B0 2264預收'!$1:$1048576,37,0),0) -> 0 | AN5: =+AL5-AM5 -> 0 | AO5: =+AJ5+IFERROR(+VLOOKUP($A5,'B0 2264預收'!$1:$1048576,38,0),0) -> 0 | AP5: =+AN5-AO5 -> 0 | AQ5: =+AL5+IFERROR(VLOOKUP($A5,'A0 BS 1240在建'!$1:$1048576,41,0),0) -> 0 | AR5: =+AM5+IFERROR(VLOOKUP($A5,'B0 2264預收'!$1:$1048576,41,0),0) -> 0 | AS5: =+AQ5-AR5 -> 0 | AT5: =+AO5+IFERROR(+VLOOKUP($A5,'B0 2264預收'!$1:$1048576,42,0),0) -> 0 | AU5: =+AS5-AT5 -> 0 | AV5: =+AQ5+IFERROR(VLOOKUP($A5,'A0 BS 1240在建'!$1:$1048576,45,0),0) -> 0 | AW5: =+AR5+IFERROR(VLOOKUP($A5,'B0 2264預收'!$1:$1048576,45,0),0) -> 0 | AX5: =+AV5-AW5 -> 0 | AY5: =+AT5+IFERROR(+VLOOKUP($A5,'B0 2264預收'!$1:$1048576,46,0),0) -> 0 | AZ5: =+AX5-AY5 -> 0 | BA5: =+AV5+IFERROR(VLOOKUP($A5,'A0 BS 1240在建'!$1:$1048576,49,0),0) -> 0 | BB5: =+AW5+IFERROR(VLOOKUP($A5,'B0 2264預收'!$1:$1048576,49,0),0) -> 0 | BC5: =+BA5-BB5 -> 0 | BD5: =+AY5+IFERROR(+VLOOKUP($A5,'B0 2264預收'!$1:$1048576,50,0),0) -> 0 | BE5: =+BC5-BD5 -> 0 | BF5: =+BA5+IFERROR(VLOOKUP($A5,'A0 BS 1240在建'!$1:$1048576,53,0),0) -> 0 | BG5: =+BB5+IFERROR(VLOOKUP($A5,'B0 2264預收'!$1:$1048576,53,0),0) -> 0 | BH5: =+BF5-BG5 -> 0 | BI5: =+BD5+IFERROR(+VLOOKUP($A5,'B0 2264預收'!$1:$1048576,54,0),0) -> 0 | BJ5: =+BH5-BI5 -> 0 | BK5: =+BF5+IFERROR(VLOOKUP($A5,'A0 BS 1240在建'!$1:$1048576,57,0),0) -> 0 | BL5: =+BG5+IFERROR(VLOOKUP($A5,'B0 2264預收'!$1:$1048576,57,0),0) -> 0 | BM5: =+BK5-BL5 -> 0 | BN5: =+BI5+IFERROR(+VLOOKUP($A5,'B0 2264預收'!$1:$1048576,58,0),0) -> 0 | BO5: =+BM5-BN5 -> 0 | BP5: =+BK5+IFERROR(VLOOKUP($A5,'A0 BS 1240在建'!$1:$1048576,61,0),0) -> 0 | BQ5: =+BL5+IFERROR(VLOOKUP($A5,'B0 2264預收'!$1:$1048576,61,0),0) -> 0 | BR5: =+BP5-BQ5 -> 0 | BS5: =+BN5+IFERROR(+VLOOKUP($A5,'B0 2264預收'!$1:$1048576,62,0),0) -> 0 | BT5: =+BR5-BS5 -> 0 | BU5: =+IFERROR(VLOOKUP($A5,'A0 BS 1240在建'!$1:$1048576,77,0),0) -> 0 | BV5: =+IFERROR(VLOOKUP($A5,'B0 2264預收'!$1:$1048576,77,0),0) -> 0 | BW5: =+BU5-BV5 -> 0 | BX5: =+IFERROR(+VLOOKUP($A5,'B0 2264預收'!$1:$1048576,78,0),0) -> 0 | BY5: =+BW5-BX5 -> 0 | BZ5: =IFERROR(+VLOOKUP($A5,'A0 BS 1240在建'!$1:$1048576,85,0),0) -> 0 | CA5: =IFERROR(+VLOOKUP($A5,'B0 2264預收'!$1:$1048576,85,0),0) -> 0 | CB5: =+BZ5-CA5 -> 0 | CC5: =+IFERROR(+VLOOKUP($A5,'B0 2264預收'!$1:$1048576,86,0),0) -> 0 | CD5: =+CB5-CC5 -> 0 | CE5: =+IFERROR(VLOOKUP($A5,'A0 BS 1240在建'!$1:$1048576,93,0),0) -> 0 | CF5: =+IFERROR(VLOOKUP($A5,'B0 2264預收'!$1:$1048576,93,0),0) -> 0 | CG5: =+CE5-CF5 -> 0 | CH5: =+IFERROR(+VLOOKUP($A5,'B0 2264預收'!$1:$1048576,94,0),0) -> 0 | CI5: =+CG5-CH5 -> 0 | CJ5: =IFERROR(+VLOOKUP($A5,'A0 BS 1240在建'!$1:$1048576,101,0),0) -> 0 | CK5: =IFERROR(+VLOOKUP($A5,'B0 2264預收'!$1:$1048576,101,0),0) -> 0 | CL5: =+CJ5-CK5 -> 0 | CM5: =+IFERROR(+VLOOKUP($A5,'B0 2264預收'!$1:$1048576,102,0),0) -> 0 | CN5: =+CL5-CM5 -> 0 | CP5: =+J5-E5 -> 0 | CQ5: =-E5 -> 0 | CR5: =+J5 -> 0 | CU5: =+BR5-J5 -> 0 | CV5: =+BR5 -> 0 | CW5: =-J5 -> 0 | CY5: =IF(AND(BR5>0, J5>0), BR5-J5, "") | CZ5: =IF(AND(BR5<0,J5>0),-J5," ") | DA5: =IF(AND(BR5>0,J5<0),BR5," ") | DB5: =IF(AND(L5=0,BR5<0),-BR5," ") | DC5: =SUM(CY5:DB5) -> 0 | DD5: =IF(AND(BR5<0, J5<0), BR5-J5, "") | DE5: =IF(AND(BR5<0,J5>0),BR5," ") | DF5: =IF(AND(BR5>0,J5<0),-J5," ") | DG5: =IF(AND(L5<0,BR5=0),-L5," ") | DH5: =SUM(DD5:DG5) -> 0
A6: C/4130P | B6: CM01機場捷運 | C6: =IFERROR(VLOOKUP($A6,'A0 BS 1240在建'!$1:$1048576,5,0),0) -> 0 | D6: =IFERROR(VLOOKUP($A6,'B0 2264預收'!$1:$1048576,5,0),0) -> 0 | E6: =+C6-D6 -> 0 | F6: =IFERROR(VLOOKUP($A6,'B0 2264預收'!$1:$1048576,6,0),0) -> 0 | G6: =+E6-F6 -> 0 | H6: =IFERROR(VLOOKUP($A6,'A0 BS 1240在建'!$1:$1048576,13,0),0) -> 0 | I6: =IFERROR(VLOOKUP($A6,'B0 2264預收'!$1:$1048576,13,0),0) -> 0 | J6: =+H6-I6 -> 0 | K6: =IFERROR(VLOOKUP($A6,'B0 2264預收'!$1:$1048576,14,0),0) -> 0 | L6: =+H6-I6-K6 -> 0 | M6: =H6+IFERROR(VLOOKUP($A6,'A0 BS 1240在建'!$1:$1048576,17,0),0) -> 0 | N6: =I6+IFERROR(VLOOKUP($A6,'B0 2264預收'!$1:$1048576,17,0),0) -> 0 | O6: =+M6-N6 -> 0 | P6: =K6+IFERROR(+VLOOKUP($A6,'B0 2264預收'!$1:$1048576,18,0),0) -> 0 | Q6: =+O6-P6 -> 0 | R6: =M6+IFERROR(VLOOKUP($A6,'A0 BS 1240在建'!$1:$1048576,21,0),0) -> 0 | S6: =+N6+IFERROR(VLOOKUP($A6,'B0 2264預收'!$1:$1048576,21,0),0) -> 0 | T6: =+R6-S6 -> 0 | U6: =+P6+IFERROR(+VLOOKUP($A6,'B0 2264預收'!$1:$1048576,22,0),0) -> 0 | V6: =+T6-U6 -> 0 | W6: =+R6+IFERROR(VLOOKUP($A6,'A0 BS 1240在建'!$1:$1048576,25,0),0) -> 0 | X6: =+S6+IFERROR(VLOOKUP($A6,'B0 2264預收'!$1:$1048576,25,0),0) -> 0 | Y6: =+W6-X6 -> 0 | Z6: =+U6+IFERROR(+VLOOKUP($A6,'B0 2264預收'!$1:$1048576,26,0),0) -> 0 | AA6: =+Y6-Z6 -> 0 | AB6: =+W6+IFERROR(VLOOKUP($A6,'A0 BS 1240在建'!$1:$1048576,29,0),0) -> 0 | AC6: =+X6+IFERROR(VLOOKUP($A6,'B0 2264預收'!$1:$1048576,29,0),0) -> 0 | AD6: =+AB6-AC6 -> 0 | AE6: =+Z6+IFERROR(+VLOOKUP($A6,'B0 2264預收'!$1:$1048576,30,0),0) -> 0 | AF6: =+AD6-AE6 -> 0 | AG6: =+AB6+IFERROR(VLOOKUP($A6,'A0 BS 1240在建'!$1:$1048576,33,0),0) -> 0 | AH6: =+AC6+IFERROR(VLOOKUP($A6,'B0 2264預收'!$1:$1048576,33,0),0) -> 0 | AI6: =+AG6-AH6 -> 0 | AJ6: =+AE6+IFERROR(+VLOOKUP($A6,'B0 2264預收'!$1:$1048576,34,0),0) -> 0 | AK6: =+AI6-AJ6 -> 0 | AL6: =+AG6+IFERROR(VLOOKUP($A6,'A0 BS 1240在建'!$1:$1048576,37,0),0) -> 0 | AM6: =+AH6+IFERROR(VLOOKUP($A6,'B0 2264預收'!$1:$1048576,37,0),0) -> 0 | AN6: =+AL6-AM6 -> 0 | AO6: =+AJ6+IFERROR(+VLOOKUP($A6,'B0 2264預收'!$1:$1048576,38,0),0) -> 0 | AP6: =+AN6-AO6 -> 0 | AQ6: =+AL6+IFERROR(VLOOKUP($A6,'A0 BS 1240在建'!$1:$1048576,41,0),0) -> 0 | AR6: =+AM6+IFERROR(VLOOKUP($A6,'B0 2264預收'!$1:$1048576,41,0),0) -> 0 | AS6: =+AQ6-AR6 -> 0 | AT6: =+AO6+IFERROR(+VLOOKUP($A6,'B0 2264預收'!$1:$1048576,42,0),0) -> 0 | AU6: =+AS6-AT6 -> 0 | AV6: =+AQ6+IFERROR(VLOOKUP($A6,'A0 BS 1240在建'!$1:$1048576,45,0),0) -> 0 | AW6: =+AR6+IFERROR(VLOOKUP($A6,'B0 2264預收'!$1:$1048576,45,0),0) -> 0 | AX6: =+AV6-AW6 -> 0 | AY6: =+AT6+IFERROR(+VLOOKUP($A6,'B0 2264預收'!$1:$1048576,46,0),0) -> 0 | AZ6: =+AX6-AY6 -> 0 | BA6: =+AV6+IFERROR(VLOOKUP($A6,'A0 BS 1240在建'!$1:$1048576,49,0),0) -> 0 | BB6: =+AW6+IFERROR(VLOOKUP($A6,'B0 2264預收'!$1:$1048576,49,0),0) -> 0 | BC6: =+BA6-BB6 -> 0 | BD6: =+AY6+IFERROR(+VLOOKUP($A6,'B0 2264預收'!$1:$1048576,50,0),0) -> 0 | BE6: =+BC6-BD6 -> 0 | BF6: =+BA6+IFERROR(VLOOKUP($A6,'A0 BS 1240在建'!$1:$1048576,53,0),0) -> 0 | BG6: =+BB6+IFERROR(VLOOKUP($A6,'B0 2264預收'!$1:$1048576,53,0),0) -> 0 | BH6: =+BF6-BG6 -> 0 | BI6: =+BD6+IFERROR(+VLOOKUP($A6,'B0 2264預收'!$1:$1048576,54,0),0) -> 0 | BJ6: =+BH6-BI6 -> 0 | BK6: =+BF6+IFERROR(VLOOKUP($A6,'A0 BS 1240在建'!$1:$1048576,57,0),0) -> 0 | BL6: =+BG6+IFERROR(VLOOKUP($A6,'B0 2264預收'!$1:$1048576,57,0),0) -> 0 | BM6: =+BK6-BL6 -> 0 | BN6: =+BI6+IFERROR(+VLOOKUP($A6,'B0 2264預收'!$1:$1048576,58,0),0) -> 0 | BO6: =+BM6-BN6 -> 0 | BP6: =+BK6+IFERROR(VLOOKUP($A6,'A0 BS 1240在建'!$1:$1048576,61,0),0) -> 0 | BQ6: =+BL6+IFERROR(VLOOKUP($A6,'B0 2264預收'!$1:$1048576,61,0),0) -> 0 | BR6: =+BP6-BQ6 -> 0 | BS6: =+BN6+IFERROR(+VLOOKUP($A6,'B0 2264預收'!$1:$1048576,62,0),0) -> 0 | BT6: =+BR6-BS6 -> 0 | BU6: =+IFERROR(VLOOKUP($A6,'A0 BS 1240在建'!$1:$1048576,77,0),0) -> 0 | BV6: =+IFERROR(VLOOKUP($A6,'B0 2264預收'!$1:$1048576,77,0),0) -> 0 | BW6: =+BU6-BV6 -> 0 | BX6: =+IFERROR(+VLOOKUP($A6,'B0 2264預收'!$1:$1048576,78,0),0) -> 0 | BY6: =+BW6-BX6 -> 0 | BZ6: =IFERROR(+VLOOKUP($A6,'A0 BS 1240在建'!$1:$1048576,85,0),0) -> 0 | CA6: =IFERROR(+VLOOKUP($A6,'B0 2264預收'!$1:$1048576,85,0),0) -> 0 | CB6: =+BZ6-CA6 -> 0 | CC6: =+IFERROR(+VLOOKUP($A6,'B0 2264預收'!$1:$1048576,86,0),0) -> 0 | CD6: =+CB6-CC6 -> 0 | CE6: =+IFERROR(VLOOKUP($A6,'A0 BS 1240在建'!$1:$1048576,93,0),0) -> 0 | CF6: =+IFERROR(VLOOKUP($A6,'B0 2264預收'!$1:$1048576,93,0),0) -> 0 | CG6: =+CE6-CF6 -> 0 | CH6: =+IFERROR(+VLOOKUP($A6,'B0 2264預收'!$1:$1048576,94,0),0) -> 0 | CI6: =+CG6-CH6 -> 0 | CJ6: =IFERROR(+VLOOKUP($A6,'A0 BS 1240在建'!$1:$1048576,101,0),0) -> 0 | CK6: =IFERROR(+VLOOKUP($A6,'B0 2264預收'!$1:$1048576,101,0),0) -> 0 | CL6: =+CJ6-CK6 -> 0 | CM6: =+IFERROR(+VLOOKUP($A6,'B0 2264預收'!$1:$1048576,102,0),0) -> 0 | CN6: =+CL6-CM6 -> 0 | CP6: =+J6-E6 -> 0 | CR6: =+CP6 -> 0 | CU6: =+BR6-J6 -> 0 | CW6: =+CU6 -> 0 | CY6: =IF(AND(BR6>0, J6>0), BR6-J6, "") | CZ6: =IF(AND(BR6<0,J6>0),-J6," ") | DA6: =IF(AND(BR6>0,J6<0),BR6," ") | DB6: =IF(AND(L6=0,BR6<0),-BR6," ") | DC6: =SUM(CY6:DB6) -> 0 | DD6: =IF(AND(BR6<0, J6<0), (BR6-J6)*-1, "") | DE6: =IF(AND(BR6<0,J6>0),-BR6," ") | DF6: =IF(AND(BR6>0,J6<0),-J6*-1," ") | DG6: =IF(AND(L6<0,BR6=0),-L6*-1," ") | DH6: =SUM(DD6:DG6) -> 0
A7: C/4140N | B7: CQ842萬大線 | C7: =IFERROR(VLOOKUP($A7,'A0 BS 1240在建'!$1:$1048576,5,0),0) -> 0 | D7: =IFERROR(VLOOKUP($A7,'B0 2264預收'!$1:$1048576,5,0),0) -> 0 | E7: =+C7-D7 -> 0 | F7: =IFERROR(VLOOKUP($A7,'B0 2264預收'!$1:$1048576,6,0),0) -> 0 | G7: =+E7-F7 -> 0 | H7: =IFERROR(VLOOKUP($A7,'A0 BS 1240在建'!$1:$1048576,13,0),0) -> 0 | I7: =IFERROR(VLOOKUP($A7,'B0 2264預收'!$1:$1048576,13,0),0) -> 0 | J7: =+H7-I7 -> 0 | K7: =IFERROR(VLOOKUP($A7,'B0 2264預收'!$1:$1048576,14,0),0) -> 0 | L7: =+H7-I7-K7 -> 0 | M7: =H7+IFERROR(VLOOKUP($A7,'A0 BS 1240在建'!$1:$1048576,17,0),0) -> 0 | N7: =I7+IFERROR(VLOOKUP($A7,'B0 2264預收'!$1:$1048576,17,0),0) -> 0 | O7: =+M7-N7 -> 0 | P7: =K7+IFERROR(+VLOOKUP($A7,'B0 2264預收'!$1:$1048576,18,0),0) -> 0 | Q7: =+O7-P7 -> 0 | R7: =M7+IFERROR(VLOOKUP($A7,'A0 BS 1240在建'!$1:$1048576,21,0),0) -> 0 | S7: =+N7+IFERROR(VLOOKUP($A7,'B0 2264預收'!$1:$1048576,21,0),0) -> 0 | T7: =+R7-S7 -> 0 | U7: =+P7+IFERROR(+VLOOKUP($A7,'B0 2264預收'!$1:$1048576,22,0),0) -> 0 | V7: =+T7-U7 -> 0 | W7: =+R7+IFERROR(VLOOKUP($A7,'A0 BS 1240在建'!$1:$1048576,25,0),0) -> 0 | X7: =+S7+IFERROR(VLOOKUP($A7,'B0 2264預收'!$1:$1048576,25,0),0) -> 0 | Y7: =+W7-X7 -> 0 | Z7: =+U7+IFERROR(+VLOOKUP($A7,'B0 2264預收'!$1:$1048576,26,0),0) -> 0 | AA7: =+Y7-Z7 -> 0 | AB7: =+W7+IFERROR(VLOOKUP($A7,'A0 BS 1240在建'!$1:$1048576,29,0),0) -> 0 | AC7: =+X7+IFERROR(VLOOKUP($A7,'B0 2264預收'!$1:$1048576,29,0),0) -> 0 | AD7: =+AB7-AC7 -> 0 | AE7: =+Z7+IFERROR(+VLOOKUP($A7,'B0 2264預收'!$1:$1048576,30,0),0) -> 0 | AF7: =+AD7-AE7 -> 0 | AG7: =+AB7+IFERROR(VLOOKUP($A7,'A0 BS 1240在建'!$1:$1048576,33,0),0) -> 0 | AH7: =+AC7+IFERROR(VLOOKUP($A7,'B0 2264預收'!$1:$1048576,33,0),0) -> 0 | AI7: =+AG7-AH7 -> 0 | AJ7: =+AE7+IFERROR(+VLOOKUP($A7,'B0 2264預收'!$1:$1048576,34,0),0) -> 0 | AK7: =+AI7-AJ7 -> 0 | AL7: =+AG7+IFERROR(VLOOKUP($A7,'A0 BS 1240在建'!$1:$1048576,37,0),0) -> 0 | AM7: =+AH7+IFERROR(VLOOKUP($A7,'B0 2264預收'!$1:$1048576,37,0),0) -> 0 | AN7: =+AL7-AM7 -> 0 | AO7: =+AJ7+IFERROR(+VLOOKUP($A7,'B0 2264預收'!$1:$1048576,38,0),0) -> 0 | AP7: =+AN7-AO7 -> 0 | AQ7: =+AL7+IFERROR(VLOOKUP($A7,'A0 BS 1240在建'!$1:$1048576,41,0),0) -> 0 | AR7: =+AM7+IFERROR(VLOOKUP($A7,'B0 2264預收'!$1:$1048576,41,0),0) -> 0 | AS7: =+AQ7-AR7 -> 0 | AT7: =+AO7+IFERROR(+VLOOKUP($A7,'B0 2264預收'!$1:$1048576,42,0),0) -> 0 | AU7: =+AS7-AT7 -> 0 | AV7: =+AQ7+IFERROR(VLOOKUP($A7,'A0 BS 1240在建'!$1:$1048576,45,0),0) -> 0 | AW7: =+AR7+IFERROR(VLOOKUP($A7,'B0 2264預收'!$1:$1048576,45,0),0) -> 0 | AX7: =+AV7-AW7 -> 0 | AY7: =+AT7+IFERROR(+VLOOKUP($A7,'B0 2264預收'!$1:$1048576,46,0),0) -> 0 | AZ7: =+AX7-AY7 -> 0 | BA7: =+AV7+IFERROR(VLOOKUP($A7,'A0 BS 1240在建'!$1:$1048576,49,0),0) -> 0 | BB7: =+AW7+IFERROR(VLOOKUP($A7,'B0 2264預收'!$1:$1048576,49,0),0) -> 0 | BC7: =+BA7-BB7 -> 0 | BD7: =+AY7+IFERROR(+VLOOKUP($A7,'B0 2264預收'!$1:$1048576,50,0),0) -> 0 | BE7: =+BC7-BD7 -> 0 | BF7: =+BA7+IFERROR(VLOOKUP($A7,'A0 BS 1240在建'!$1:$1048576,53,0),0) -> 0 | BG7: =+BB7+IFERROR(VLOOKUP($A7,'B0 2264預收'!$1:$1048576,53,0),0) -> 0 | BH7: =+BF7-BG7 -> 0 | BI7: =+BD7+IFERROR(+VLOOKUP($A7,'B0 2264預收'!$1:$1048576,54,0),0) -> 0 | BJ7: =+BH7-BI7 -> 0 | BK7: =+BF7+IFERROR(VLOOKUP($A7,'A0 BS 1240在建'!$1:$1048576,57,0),0) -> 0 | BL7: =+BG7+IFERROR(VLOOKUP($A7,'B0 2264預收'!$1:$1048576,57,0),0) -> 0 | BM7: =+BK7-BL7 -> 0 | BN7: =+BI7+IFERROR(+VLOOKUP($A7,'B0 2264預收'!$1:$1048576,58,0),0) -> 0 | BO7: =+BM7-BN7 -> 0 | BP7: =+BK7+IFERROR(VLOOKUP($A7,'A0 BS 1240在建'!$1:$1048576,61,0),0) -> 0 | BQ7: =+BL7+IFERROR(VLOOKUP($A7,'B0 2264預收'!$1:$1048576,61,0),0) -> 0 | BR7: =+BP7-BQ7 -> 0 | BS7: =+BN7+IFERROR(+VLOOKUP($A7,'B0 2264預收'!$1:$1048576,62,0),0) -> 0 | BT7: =+BR7-BS7 -> 0 | BU7: =+IFERROR(VLOOKUP($A7,'A0 BS 1240在建'!$1:$1048576,77,0),0) -> 0 | BV7: =+IFERROR(VLOOKUP($A7,'B0 2264預收'!$1:$1048576,77,0),0) -> 0 | BW7: =+BU7-BV7 -> 0 | BX7: =+IFERROR(+VLOOKUP($A7,'B0 2264預收'!$1:$1048576,78,0),0) -> 0 | BY7: =+BW7-BX7 -> 0 | BZ7: =IFERROR(+VLOOKUP($A7,'A0 BS 1240在建'!$1:$1048576,85,0),0) -> 0 | CA7: =IFERROR(+VLOOKUP($A7,'B0 2264預收'!$1:$1048576,85,0),0) -> 0 | CB7: =+BZ7-CA7 -> 0 | CC7: =+IFERROR(+VLOOKUP($A7,'B0 2264預收'!$1:$1048576,86,0),0) -> 0 | CD7: =+CB7-CC7 -> 0 | CE7: =+IFERROR(VLOOKUP($A7,'A0 BS 1240在建'!$1:$1048576,93,0),0) -> 0 | CF7: =+IFERROR(VLOOKUP($A7,'B0 2264預收'!$1:$1048576,93,0),0) -> 0 | CG7: =+CE7-CF7 -> 0 | CH7: =+IFERROR(+VLOOKUP($A7,'B0 2264預收'!$1:$1048576,94,0),0) -> 0 | CI7: =+CG7-CH7 -> 0 | CJ7: =IFERROR(+VLOOKUP($A7,'A0 BS 1240在建'!$1:$1048576,101,0),0) -> 0 | CK7: =IFERROR(+VLOOKUP($A7,'B0 2264預收'!$1:$1048576,101,0),0) -> 0 | CL7: =+CJ7-CK7 -> 0 | CM7: =+IFERROR(+VLOOKUP($A7,'B0 2264預收'!$1:$1048576,102,0),0) -> 0 | CN7: =+CL7-CM7 -> 0 | CP7: =+J7-E7 -> 0 | CR7: =+CP7 -> 0 | CU7: =+BR7-J7 -> 0 | CW7: =+CU7 -> 0 | CY7: =IF(AND(BR7>0, J7>0), BR7-J7, "") | CZ7: =IF(AND(BR7<0,J7>0),-J7," ") | DA7: =IF(AND(BR7>0,J7<0),BR7," ") | DB7: =IF(AND(L7=0,BR7<0),-BR7," ") | DC7: =SUM(CY7:DB7) -> 0 | DD7: =IF(AND(BR7<0, J7<0), (BR7-J7)*-1, "") | DE7: =IF(AND(BR7<0,J7>0),-BR7," ") | DF7: =IF(AND(BR7>0,J7<0),-J7*-1," ") | DG7: =IF(AND(L7<0,BR7=0),-L7*-1," ") | DH7: =SUM(DD7:DG7) -> 0
A8: C/4160H | B8: CQ850A標萬大線 | C8: =IFERROR(VLOOKUP($A8,'A0 BS 1240在建'!$1:$1048576,5,0),0) -> 0 | D8: =IFERROR(VLOOKUP($A8,'B0 2264預收'!$1:$1048576,5,0),0) -> 0 | E8: =+C8-D8 -> 0 | F8: =IFERROR(VLOOKUP($A8,'B0 2264預收'!$1:$1048576,6,0),0) -> 0 | G8: =+E8-F8 -> 0 | H8: =IFERROR(VLOOKUP($A8,'A0 BS 1240在建'!$1:$1048576,13,0),0) -> 0 | I8: =IFERROR(VLOOKUP($A8,'B0 2264預收'!$1:$1048576,13,0),0) -> 0 | J8: =+H8-I8 -> 0 | K8: =IFERROR(VLOOKUP($A8,'B0 2264預收'!$1:$1048576,14,0),0) -> 0 | L8: =+H8-I8-K8 -> 0 | M8: =H8+IFERROR(VLOOKUP($A8,'A0 BS 1240在建'!$1:$1048576,17,0),0) -> 0 | N8: =I8+IFERROR(VLOOKUP($A8,'B0 2264預收'!$1:$1048576,17,0),0) -> 0 | O8: =+M8-N8 -> 0 | P8: =K8+IFERROR(+VLOOKUP($A8,'B0 2264預收'!$1:$1048576,18,0),0) -> 0 | Q8: =+O8-P8 -> 0 | R8: =M8+IFERROR(VLOOKUP($A8,'A0 BS 1240在建'!$1:$1048576,21,0),0) -> 0 | S8: =+N8+IFERROR(VLOOKUP($A8,'B0 2264預收'!$1:$1048576,21,0),0) -> 0 | T8: =+R8-S8 -> 0 | U8: =+P8+IFERROR(+VLOOKUP($A8,'B0 2264預收'!$1:$1048576,22,0),0) -> 0 | V8: =+T8-U8 -> 0 | W8: =+R8+IFERROR(VLOOKUP($A8,'A0 BS 1240在建'!$1:$1048576,25,0),0) -> 0 | X8: =+S8+IFERROR(VLOOKUP($A8,'B0 2264預收'!$1:$1048576,25,0),0) -> 0 | Y8: =+W8-X8 -> 0 | Z8: =+U8+IFERROR(+VLOOKUP($A8,'B0 2264預收'!$1:$1048576,26,0),0) -> 0 | AA8: =+Y8-Z8 -> 0 | AB8: =+W8+IFERROR(VLOOKUP($A8,'A0 BS 1240在建'!$1:$1048576,29,0),0) -> 0 | AC8: =+X8+IFERROR(VLOOKUP($A8,'B0 2264預收'!$1:$1048576,29,0),0) -> 0 | AD8: =+AB8-AC8 -> 0 | AE8: =+Z8+IFERROR(+VLOOKUP($A8,'B0 2264預收'!$1:$1048576,30,0),0) -> 0 | AF8: =+AD8-AE8 -> 0 | AG8: =+AB8+IFERROR(VLOOKUP($A8,'A0 BS 1240在建'!$1:$1048576,33,0),0) -> 0 | AH8: =+AC8+IFERROR(VLOOKUP($A8,'B0 2264預收'!$1:$1048576,33,0),0) -> 0 | AI8: =+AG8-AH8 -> 0 | AJ8: =+AE8+IFERROR(+VLOOKUP($A8,'B0 2264預收'!$1:$1048576,34,0),0) -> 0 | AK8: =+AI8-AJ8 -> 0 | AL8: =+AG8+IFERROR(VLOOKUP($A8,'A0 BS 1240在建'!$1:$1048576,37,0),0) -> 0 | AM8: =+AH8+IFERROR(VLOOKUP($A8,'B0 2264預收'!$1:$1048576,37,0),0) -> 0 | AN8: =+AL8-AM8 -> 0 | AO8: =+AJ8+IFERROR(+VLOOKUP($A8,'B0 2264預收'!$1:$1048576,38,0),0) -> 0 | AP8: =+AN8-AO8 -> 0 | AQ8: =+AL8+IFERROR(VLOOKUP($A8,'A0 BS 1240在建'!$1:$1048576,41,0),0) -> 0 | AR8: =+AM8+IFERROR(VLOOKUP($A8,'B0 2264預收'!$1:$1048576,41,0),0) -> 0 | AS8: =+AQ8-AR8 -> 0 | AT8: =+AO8+IFERROR(+VLOOKUP($A8,'B0 2264預收'!$1:$1048576,42,0),0) -> 0 | AU8: =+AS8-AT8 -> 0 | AV8: =+AQ8+IFERROR(VLOOKUP($A8,'A0 BS 1240在建'!$1:$1048576,45,0),0) -> 0 | AW8: =+AR8+IFERROR(VLOOKUP($A8,'B0 2264預收'!$1:$1048576,45,0),0) -> 0 | AX8: =+AV8-AW8 -> 0 | AY8: =+AT8+IFERROR(+VLOOKUP($A8,'B0 2264預收'!$1:$1048576,46,0),0) -> 0 | AZ8: =+AX8-AY8 -> 0 | BA8: =+AV8+IFERROR(VLOOKUP($A8,'A0 BS 1240在建'!$1:$1048576,49,0),0) -> 0 | BB8: =+AW8+IFERROR(VLOOKUP($A8,'B0 2264預收'!$1:$1048576,49,0),0) -> 0 | BC8: =+BA8-BB8 -> 0 | BD8: =+AY8+IFERROR(+VLOOKUP($A8,'B0 2264預收'!$1:$1048576,50,0),0) -> 0 | BE8: =+BC8-BD8 -> 0 | BF8: =+BA8+IFERROR(VLOOKUP($A8,'A0 BS 1240在建'!$1:$1048576,53,0),0) -> 0 | BG8: =+BB8+IFERROR(VLOOKUP($A8,'B0 2264預收'!$1:$1048576,53,0),0) -> 0 | BH8: =+BF8-BG8 -> 0 | BI8: =+BD8+IFERROR(+VLOOKUP($A8,'B0 2264預收'!$1:$1048576,54,0),0) -> 0 | BJ8: =+BH8-BI8 -> 0 | BK8: =+BF8+IFERROR(VLOOKUP($A8,'A0 BS 1240在建'!$1:$1048576,57,0),0) -> 0 | BL8: =+BG8+IFERROR(VLOOKUP($A8,'B0 2264預收'!$1:$1048576,57,0),0) -> 0 | BM8: =+BK8-BL8 -> 0 | BN8: =+BI8+IFERROR(+VLOOKUP($A8,'B0 2264預收'!$1:$1048576,58,0),0) -> 0 | BO8: =+BM8-BN8 -> 0 | BP8: =+BK8+IFERROR(VLOOKUP($A8,'A0 BS 1240在建'!$1:$1048576,61,0),0) -> 0 | BQ8: =+BL8+IFERROR(VLOOKUP($A8,'B0 2264預收'!$1:$1048576,61,0),0) -> 0 | BR8: =+BP8-BQ8 -> 0 | BS8: =+BN8+IFERROR(+VLOOKUP($A8,'B0 2264預收'!$1:$1048576,62,0),0) -> 0 | BT8: =+BR8-BS8 -> 0 | BU8: =+IFERROR(VLOOKUP($A8,'A0 BS 1240在建'!$1:$1048576,77,0),0) -> 0 | BV8: =+IFERROR(VLOOKUP($A8,'B0 2264預收'!$1:$1048576,77,0),0) -> 0 | BW8: =+BU8-BV8 -> 0 | BX8: =+IFERROR(+VLOOKUP($A8,'B0 2264預收'!$1:$1048576,78,0),0) -> 0 | BY8: =+BW8-BX8 -> 0 | BZ8: =IFERROR(+VLOOKUP($A8,'A0 BS 1240在建'!$1:$1048576,85,0),0) -> 0 | CA8: =IFERROR(+VLOOKUP($A8,'B0 2264預收'!$1:$1048576,85,0),0) -> 0 | CB8: =+BZ8-CA8 -> 0 | CC8: =+IFERROR(+VLOOKUP($A8,'B0 2264預收'!$1:$1048576,86,0),0) -> 0 | CD8: =+CB8-CC8 -> 0 | CE8: =+IFERROR(VLOOKUP($A8,'A0 BS 1240在建'!$1:$1048576,93,0),0) -> 0 | CF8: =+IFERROR(VLOOKUP($A8,'B0 2264預收'!$1:$1048576,93,0),0) -> 0 | CG8: =+CE8-CF8 -> 0 | CH8: =+IFERROR(+VLOOKUP($A8,'B0 2264預收'!$1:$1048576,94,0),0) -> 0 | CI8: =+CG8-CH8 -> 0 | CJ8: =IFERROR(+VLOOKUP($A8,'A0 BS 1240在建'!$1:$1048576,101,0),0) -> 0 | CK8: =IFERROR(+VLOOKUP($A8,'B0 2264預收'!$1:$1048576,101,0),0) -> 0 | CL8: =+CJ8-CK8 -> 0 | CM8: =+IFERROR(+VLOOKUP($A8,'B0 2264預收'!$1:$1048576,102,0),0) -> 0 | CN8: =+CL8-CM8 -> 0 | CP8: =+J8-E8 -> 0 | CQ8: =+CP8 -> 0 | CU8: =+BR8-J8 -> 0 | CV8: =-J8 -> 0 | CW8: =+BR8 -> 0 | CY8: =IF(AND(BR8>0, J8>0), BR8-J8, "") | CZ8: =IF(AND(BR8<0,J8>0),-J8," ") | DA8: =IF(AND(BR8>0,J8<0),BR8," ") | DB8: =IF(AND(L8=0,BR8<0),-BR8," ") | DC8: =SUM(CY8:DB8) -> 0 | DD8: =IF(AND(BR8<0, J8<0), (BR8-J8)*-1, "") | DE8: =IF(AND(BR8<0,J8>0),-BR8," ") | DF8: =IF(AND(BR8>0,J8<0),-J8*-1," ") | DG8: =IF(AND(L8<0,BR8=0),-L8*-1," ") | DH8: =SUM(DD8:DG8) -> 0
A9: C/4160J | B9: CQ840標萬大線 | C9: =IFERROR(VLOOKUP($A9,'A0 BS 1240在建'!$1:$1048576,5,0),0) -> 0 | D9: =IFERROR(VLOOKUP($A9,'B0 2264預收'!$1:$1048576,5,0),0) -> 0 | E9: =+C9-D9 -> 0 | F9: =IFERROR(VLOOKUP($A9,'B0 2264預收'!$1:$1048576,6,0),0) -> 0 | G9: =+E9-F9 -> 0 | H9: =IFERROR(VLOOKUP($A9,'A0 BS 1240在建'!$1:$1048576,13,0),0) -> 0 | I9: =IFERROR(VLOOKUP($A9,'B0 2264預收'!$1:$1048576,13,0),0) -> 0 | J9: =+H9-I9 -> 0 | K9: =IFERROR(VLOOKUP($A9,'B0 2264預收'!$1:$1048576,14,0),0) -> 0 | L9: =+H9-I9-K9 -> 0 | M9: =H9+IFERROR(VLOOKUP($A9,'A0 BS 1240在建'!$1:$1048576,17,0),0) -> 0 | N9: =I9+IFERROR(VLOOKUP($A9,'B0 2264預收'!$1:$1048576,17,0),0) -> 0 | O9: =+M9-N9 -> 0 | P9: =K9+IFERROR(+VLOOKUP($A9,'B0 2264預收'!$1:$1048576,18,0),0) -> 0 | Q9: =+O9-P9 -> 0 | R9: =M9+IFERROR(VLOOKUP($A9,'A0 BS 1240在建'!$1:$1048576,21,0),0) -> 0 | S9: =+N9+IFERROR(VLOOKUP($A9,'B0 2264預收'!$1:$1048576,21,0),0) -> 0 | T9: =+R9-S9 -> 0 | U9: =+P9+IFERROR(+VLOOKUP($A9,'B0 2264預收'!$1:$1048576,22,0),0) -> 0 | V9: =+T9-U9 -> 0 | W9: =+R9+IFERROR(VLOOKUP($A9,'A0 BS 1240在建'!$1:$1048576,25,0),0) -> 0 | X9: =+S9+IFERROR(VLOOKUP($A9,'B0 2264預收'!$1:$1048576,25,0),0) -> 0 | Y9: =+W9-X9 -> 0 | Z9: =+U9+IFERROR(+VLOOKUP($A9,'B0 2264預收'!$1:$1048576,26,0),0) -> 0 | AA9: =+Y9-Z9 -> 0 | AB9: =+W9+IFERROR(VLOOKUP($A9,'A0 BS 1240在建'!$1:$1048576,29,0),0) -> 0 | AC9: =+X9+IFERROR(VLOOKUP($A9,'B0 2264預收'!$1:$1048576,29,0),0) -> 0 | AD9: =+AB9-AC9 -> 0 | AE9: =+Z9+IFERROR(+VLOOKUP($A9,'B0 2264預收'!$1:$1048576,30,0),0) -> 0 | AF9: =+AD9-AE9 -> 0 | AG9: =+AB9+IFERROR(VLOOKUP($A9,'A0 BS 1240在建'!$1:$1048576,33,0),0) -> 0 | AH9: =+AC9+IFERROR(VLOOKUP($A9,'B0 2264預收'!$1:$1048576,33,0),0) -> 0 | AI9: =+AG9-AH9 -> 0 | AJ9: =+AE9+IFERROR(+VLOOKUP($A9,'B0 2264預收'!$1:$1048576,34,0),0) -> 0 | AK9: =+AI9-AJ9 -> 0 | AL9: =+AG9+IFERROR(VLOOKUP($A9,'A0 BS 1240在建'!$1:$1048576,37,0),0) -> 0 | AM9: =+AH9+IFERROR(VLOOKUP($A9,'B0 2264預收'!$1:$1048576,37,0),0) -> 0 | AN9: =+AL9-AM9 -> 0 | AO9: =+AJ9+IFERROR(+VLOOKUP($A9,'B0 2264預收'!$1:$1048576,38,0),0) -> 0 | AP9: =+AN9-AO9 -> 0 | AQ9: =+AL9+IFERROR(VLOOKUP($A9,'A0 BS 1240在建'!$1:$1048576,41,0),0) -> 0 | AR9: =+AM9+IFERROR(VLOOKUP($A9,'B0 2264預收'!$1:$1048576,41,0),0) -> 0 | AS9: =+AQ9-AR9 -> 0 | AT9: =+AO9+IFERROR(+VLOOKUP($A9,'B0 2264預收'!$1:$1048576,42,0),0) -> 0 | AU9: =+AS9-AT9 -> 0 | AV9: =+AQ9+IFERROR(VLOOKUP($A9,'A0 BS 1240在建'!$1:$1048576,45,0),0) -> 0 | AW9: =+AR9+IFERROR(VLOOKUP($A9,'B0 2264預收'!$1:$1048576,45,0),0) -> 0 | AX9: =+AV9-AW9 -> 0 | AY9: =+AT9+IFERROR(+VLOOKUP($A9,'B0 2264預收'!$1:$1048576,46,0),0) -> 0 | AZ9: =+AX9-AY9 -> 0 | BA9: =+AV9+IFERROR(VLOOKUP($A9,'A0 BS 1240在建'!$1:$1048576,49,0),0) -> 0 | BB9: =+AW9+IFERROR(VLOOKUP($A9,'B0 2264預收'!$1:$1048576,49,0),0) -> 0 | BC9: =+BA9-BB9 -> 0 | BD9: =+AY9+IFERROR(+VLOOKUP($A9,'B0 2264預收'!$1:$1048576,50,0),0) -> 0 | BE9: =+BC9-BD9 -> 0 | BF9: =+BA9+IFERROR(VLOOKUP($A9,'A0 BS 1240在建'!$1:$1048576,53,0),0) -> 0 | BG9: =+BB9+IFERROR(VLOOKUP($A9,'B0 2264預收'!$1:$1048576,53,0),0) -> 0 | BH9: =+BF9-BG9 -> 0 | BI9: =+BD9+IFERROR(+VLOOKUP($A9,'B0 2264預收'!$1:$1048576,54,0),0) -> 0 | BJ9: =+BH9-BI9 -> 0 | BK9: =+BF9+IFERROR(VLOOKUP($A9,'A0 BS 1240在建'!$1:$1048576,57,0),0) -> 0 | BL9: =+BG9+IFERROR(VLOOKUP($A9,'B0 2264預收'!$1:$1048576,57,0),0) -> 0 | BM9: =+BK9-BL9 -> 0 | BN9: =+BI9+IFERROR(+VLOOKUP($A9,'B0 2264預收'!$1:$1048576,58,0),0) -> 0 | BO9: =+BM9-BN9 -> 0 | BP9: =+BK9+IFERROR(VLOOKUP($A9,'A0 BS 1240在建'!$1:$1048576,61,0),0) -> 0 | BQ9: =+BL9+IFERROR(VLOOKUP($A9,'B0 2264預收'!$1:$1048576,61,0),0) -> 0 | BR9: =+BP9-BQ9 -> 0 | BS9: =+BN9+IFERROR(+VLOOKUP($A9,'B0 2264預收'!$1:$1048576,62,0),0) -> 0 | BT9: =+BR9-BS9 -> 0 | BU9: =+IFERROR(VLOOKUP($A9,'A0 BS 1240在建'!$1:$1048576,77,0),0) -> 0 | BV9: =+IFERROR(VLOOKUP($A9,'B0 2264預收'!$1:$1048576,77,0),0) -> 0 | BW9: =+BU9-BV9 -> 0 | BX9: =+IFERROR(+VLOOKUP($A9,'B0 2264預收'!$1:$1048576,78,0),0) -> 0 | BY9: =+BW9-BX9 -> 0 | BZ9: =IFERROR(+VLOOKUP($A9,'A0 BS 1240在建'!$1:$1048576,85,0),0) -> 0 | CA9: =IFERROR(+VLOOKUP($A9,'B0 2264預收'!$1:$1048576,85,0),0) -> 0 | CB9: =+BZ9-CA9 -> 0 | CC9: =+IFERROR(+VLOOKUP($A9,'B0 2264預收'!$1:$1048576,86,0),0) -> 0 | CD9: =+CB9-CC9 -> 0 | CE9: =+IFERROR(VLOOKUP($A9,'A0 BS 1240在建'!$1:$1048576,93,0),0) -> 0 | CF9: =+IFERROR(VLOOKUP($A9,'B0 2264預收'!$1:$1048576,93,0),0) -> 0 | CG9: =+CE9-CF9 -> 0 | CH9: =+IFERROR(+VLOOKUP($A9,'B0 2264預收'!$1:$1048576,94,0),0) -> 0 | CI9: =+CG9-CH9 -> 0 | CJ9: =IFERROR(+VLOOKUP($A9,'A0 BS 1240在建'!$1:$1048576,101,0),0) -> 0 | CK9: =IFERROR(+VLOOKUP($A9,'B0 2264預收'!$1:$1048576,101,0),0) -> 0 | CL9: =+CJ9-CK9 -> 0 | CM9: =+IFERROR(+VLOOKUP($A9,'B0 2264預收'!$1:$1048576,102,0),0) -> 0 | CN9: =+CL9-CM9 -> 0 | CP9: =+J9-E9 -> 0 | CQ9: =-E9 -> 0 | CR9: =+J9 -> 0 | CU9: =+BR9-J9 -> 0 | CW9: =+CU9 -> 0 | CY9: =IF(AND(BR9>0, J9>0), BR9-J9, "") | CZ9: =IF(AND(BR9<0,J9>0),-J9," ") | DA9: =IF(AND(BR9>0,J9<0),BR9," ") | DB9: =IF(AND(L9=0,BR9<0),-BR9," ") | DC9: =SUM(CY9:DB9) -> 0 | DD9: =IF(AND(BR9<0, J9<0), (BR9-J9)*-1, "") | DE9: =IF(AND(BR9<0,J9>0),-BR9," ") | DF9: =IF(AND(BR9>0,J9<0),-J9*-1," ") | DG9: =IF(AND(L9<0,BR9=0),-L9*-1," ") | DH9: =SUM(DD9:DG9) -> 0
A10: C/4170A | B10: C214標台南鐵路 | C10: =IFERROR(VLOOKUP($A10,'A0 BS 1240在建'!$1:$1048576,5,0),0) -> 0 | D10: =IFERROR(VLOOKUP($A10,'B0 2264預收'!$1:$1048576,5,0),0) -> 0 | E10: =+C10-D10 -> 0 | F10: =IFERROR(VLOOKUP($A10,'B0 2264預收'!$1:$1048576,6,0),0) -> 0 | G10: =+E10-F10 -> 0 | H10: =IFERROR(VLOOKUP($A10,'A0 BS 1240在建'!$1:$1048576,13,0),0) -> 0 | I10: =IFERROR(VLOOKUP($A10,'B0 2264預收'!$1:$1048576,13,0),0) -> 0 | J10: =+H10-I10 -> 0 | K10: =IFERROR(VLOOKUP($A10,'B0 2264預收'!$1:$1048576,14,0),0) -> 0 | L10: =+H10-I10-K10 -> 0 | M10: =H10+IFERROR(VLOOKUP($A10,'A0 BS 1240在建'!$1:$1048576,17,0),0) -> 0 | N10: =I10+IFERROR(VLOOKUP($A10,'B0 2264預收'!$1:$1048576,17,0),0) -> 0 | O10: =+M10-N10 -> 0 | P10: =K10+IFERROR(+VLOOKUP($A10,'B0 2264預收'!$1:$1048576,18,0),0) -> 0 | Q10: =+O10-P10 -> 0 | R10: =M10+IFERROR(VLOOKUP($A10,'A0 BS 1240在建'!$1:$1048576,21,0),0) -> 0 | S10: =+N10+IFERROR(VLOOKUP($A10,'B0 2264預收'!$1:$1048576,21,0),0) -> 0 | T10: =+R10-S10 -> 0 | U10: =+P10+IFERROR(+VLOOKUP($A10,'B0 2264預收'!$1:$1048576,22,0),0) -> 0 | V10: =+T10-U10 -> 0 | W10: =+R10+IFERROR(VLOOKUP($A10,'A0 BS 1240在建'!$1:$1048576,25,0),0) -> 0 | X10: =+S10+IFERROR(VLOOKUP($A10,'B0 2264預收'!$1:$1048576,25,0),0) -> 0 | Y10: =+W10-X10 -> 0 | Z10: =+U10+IFERROR(+VLOOKUP($A10,'B0 2264預收'!$1:$1048576,26,0),0) -> 0 | AA10: =+Y10-Z10 -> 0 | AB10: =+W10+IFERROR(VLOOKUP($A10,'A0 BS 1240在建'!$1:$1048576,29,0),0) -> 0 | AC10: =+X10+IFERROR(VLOOKUP($A10,'B0 2264預收'!$1:$1048576,29,0),0) -> 0 | AD10: =+AB10-AC10 -> 0 | AE10: =+Z10+IFERROR(+VLOOKUP($A10,'B0 2264預收'!$1:$1048576,30,0),0) -> 0 | AF10: =+AD10-AE10 -> 0 | AG10: =+AB10+IFERROR(VLOOKUP($A10,'A0 BS 1240在建'!$1:$1048576,33,0),0) -> 0 | AH10: =+AC10+IFERROR(VLOOKUP($A10,'B0 2264預收'!$1:$1048576,33,0),0) -> 0 | AI10: =+AG10-AH10 -> 0 | AJ10: =+AE10+IFERROR(+VLOOKUP($A10,'B0 2264預收'!$1:$1048576,34,0),0) -> 0 | AK10: =+AI10-AJ10 -> 0 | AL10: =+AG10+IFERROR(VLOOKUP($A10,'A0 BS 1240在建'!$1:$1048576,37,0),0) -> 0 | AM10: =+AH10+IFERROR(VLOOKUP($A10,'B0 2264預收'!$1:$1048576,37,0),0) -> 0 | AN10: =+AL10-AM10 -> 0 | AO10: =+AJ10+IFERROR(+VLOOKUP($A10,'B0 2264預收'!$1:$1048576,38,0),0) -> 0 | AP10: =+AN10-AO10 -> 0 | AQ10: =+AL10+IFERROR(VLOOKUP($A10,'A0 BS 1240在建'!$1:$1048576,41,0),0) -> 0 | AR10: =+AM10+IFERROR(VLOOKUP($A10,'B0 2264預收'!$1:$1048576,41,0),0) -> 0 | AS10: =+AQ10-AR10 -> 0 | AT10: =+AO10+IFERROR(+VLOOKUP($A10,'B0 2264預收'!$1:$1048576,42,0),0) -> 0 | AU10: =+AS10-AT10 -> 0 | AV10: =+AQ10+IFERROR(VLOOKUP($A10,'A0 BS 1240在建'!$1:$1048576,45,0),0) -> 0 | AW10: =+AR10+IFERROR(VLOOKUP($A10,'B0 2264預收'!$1:$1048576,45,0),0) -> 0 | AX10: =+AV10-AW10 -> 0 | AY10: =+AT10+IFERROR(+VLOOKUP($A10,'B0 2264預收'!$1:$1048576,46,0),0) -> 0 | AZ10: =+AX10-AY10 -> 0 | BA10: =+AV10+IFERROR(VLOOKUP($A10,'A0 BS 1240在建'!$1:$1048576,49,0),0) -> 0 | BB10: =+AW10+IFERROR(VLOOKUP($A10,'B0 2264預收'!$1:$1048576,49,0),0) -> 0 | BC10: =+BA10-BB10 -> 0 | BD10: =+AY10+IFERROR(+VLOOKUP($A10,'B0 2264預收'!$1:$1048576,50,0),0) -> 0 | BE10: =+BC10-BD10 -> 0 | BF10: =+BA10+IFERROR(VLOOKUP($A10,'A0 BS 1240在建'!$1:$1048576,53,0),0) -> 0 | BG10: =+BB10+IFERROR(VLOOKUP($A10,'B0 2264預收'!$1:$1048576,53,0),0) -> 0 | BH10: =+BF10-BG10 -> 0 | BI10: =+BD10+IFERROR(+VLOOKUP($A10,'B0 2264預收'!$1:$1048576,54,0),0) -> 0 | BJ10: =+BH10-BI10 -> 0 | BK10: =+BF10+IFERROR(VLOOKUP($A10,'A0 BS 1240在建'!$1:$1048576,57,0),0) -> 0 | BL10: =+BG10+IFERROR(VLOOKUP($A10,'B0 2264預收'!$1:$1048576,57,0),0) -> 0 | BM10: =+BK10-BL10 -> 0 | BN10: =+BI10+IFERROR(+VLOOKUP($A10,'B0 2264預收'!$1:$1048576,58,0),0) -> 0 | BO10: =+BM10-BN10 -> 0 | BP10: =+BK10+IFERROR(VLOOKUP($A10,'A0 BS 1240在建'!$1:$1048576,61,0),0) -> 0 | BQ10: =+BL10+IFERROR(VLOOKUP($A10,'B0 2264預收'!$1:$1048576,61,0),0) -> 0 | BR10: =+BP10-BQ10 -> 0 | BS10: =+BN10+IFERROR(+VLOOKUP($A10,'B0 2264預收'!$1:$1048576,62,0),0) -> 0 | BT10: =+BR10-BS10 -> 0 | BU10: =+IFERROR(VLOOKUP($A10,'A0 BS 1240在建'!$1:$1048576,77,0),0) -> 0 | BV10: =+IFERROR(VLOOKUP($A10,'B0 2264預收'!$1:$1048576,77,0),0) -> 0 | BW10: =+BU10-BV10 -> 0 | BX10: =+IFERROR(+VLOOKUP($A10,'B0 2264預收'!$1:$1048576,78,0),0) -> 0 | BY10: =+BW10-BX10 -> 0 | BZ10: =IFERROR(+VLOOKUP($A10,'A0 BS 1240在建'!$1:$1048576,85,0),0) -> 0 | CA10: =IFERROR(+VLOOKUP($A10,'B0 2264預收'!$1:$1048576,85,0),0) -> 0 | CB10: =+BZ10-CA10 -> 0 | CC10: =+IFERROR(+VLOOKUP($A10,'B0 2264預收'!$1:$1048576,86,0),0) -> 0 | CD10: =+CB10-CC10 -> 0 | CE10: =+IFERROR(VLOOKUP($A10,'A0 BS 1240在建'!$1:$1048576,93,0),0) -> 0 | CF10: =+IFERROR(VLOOKUP($A10,'B0 2264預收'!$1:$1048576,93,0),0) -> 0 | CG10: =+CE10-CF10 -> 0 | CH10: =+IFERROR(+VLOOKUP($A10,'B0 2264預收'!$1:$1048576,94,0),0) -> 0 | CI10: =+CG10-CH10 -> 0 | CJ10: =IFERROR(+VLOOKUP($A10,'A0 BS 1240在建'!$1:$1048576,101,0),0) -> 0 | CK10: =IFERROR(+VLOOKUP($A10,'B0 2264預收'!$1:$1048576,101,0),0) -> 0 | CL10: =+CJ10-CK10 -> 0 | CM10: =+IFERROR(+VLOOKUP($A10,'B0 2264預收'!$1:$1048576,102,0),0) -> 0 | CN10: =+CL10-CM10 -> 0 | CP10: =+J10-E10 -> 0 | CR10: =+CP10 -> 0 | CU10: =+BR10-J10 -> 0 | CW10: =+CU10 -> 0 | CY10: =IF(AND(BR10>0, J10>0), BR10-J10, "") | CZ10: =IF(AND(BR10<0,J10>0),-J10," ") | DA10: =IF(AND(BR10>0,J10<0),BR10," ") | DB10: =IF(AND(L10=0,BR10<0),-BR10," ") | DC10: =SUM(CY10:DB10) -> 0 | DD10: =IF(AND(BR10<0, J10<0), (BR10-J10)*-1, "") | DE10: =IF(AND(BR10<0,J10>0),-BR10," ") | DF10: =IF(AND(BR10>0,J10<0),-J10*-1," ") | DG10: =IF(AND(L10<0,BR10=0),-L10*-1," ") | DH10: =SUM(DD10:DG10) -> 0
