Workbook

Sheet 分錄
A1: BIM 分錄（2026/09~12、2027 分月、2028~2031 分年）
A2: 金額：+借／−貸。來源：A0 BS 1240在建（在建工程、在建損益、收入、負債準備）、B0 2264預收（預收開票）。分類依 C 欄：內部→內案、外部→外案、內/無・雜項→雜項、備標→備標。費用入帳、支付AP、收取AR 無資料未列。
A4: 分類 | B4: No. | C4: 交易性質 | D4: 借/貸 | E4: 會科代號 | F4: 會科名稱 | G4: 金額來源 | H4: 2026/09 ~ 2026/12 | I4: 2027/1 | J4: 2027/2 | K4: 2027/3 | L4: 2027/4 | M4: 2027/5 | N4: 2027/6 | O4: 2027/7 | P4: 2027/8 | Q4: 2027/9 | R4: 2027/10 | S4: 2027/11 | T4: 2027/12 | U4: Year 2028 | V4: Year 2029 | W4: Year 2030 | X4: Year 2031
A5: 內案 | B5: 3 | C5: BIM月底結轉在建(CJ88) | D5: Dr. | E5: 12400000 | F5: 在建工程 | G5: A0 在建工程 | H5: =SUMIFS('來源明細'!$F$2:$F$1401,'來源明細'!$A$2:$A$1401,H$4,'來源明細'!$E$2:$E$1401,"內案") | I5: =SUMIFS('來源明細'!$F$2:$F$1401,'來源明細'!$A$2:$A$1401,I$4,'來源明細'!$E$2:$E$1401,"內案") | J5: =SUMIFS('來源明細'!$F$2:$F$1401,'來源明細'!$A$2:$A$1401,J$4,'來源明細'!$E$2:$E$1401,"內案") | K5: =SUMIFS('來源明細'!$F$2:$F$1401,'來源明細'!$A$2:$A$1401,K$4,'來源明細'!$E$2:$E$1401,"內案") | L5: =SUMIFS('來源明細'!$F$2:$F$1401,'來源明細'!$A$2:$A$1401,L$4,'來源明細'!$E$2:$E$1401,"內案") | M5: =SUMIFS('來源明細'!$F$2:$F$1401,'來源明細'!$A$2:$A$1401,M$4,'來源明細'!$E$2:$E$1401,"內案") | N5: =SUMIFS('來源明細'!$F$2:$F$1401,'來源明細'!$A$2:$A$1401,N$4,'來源明細'!$E$2:$E$1401,"內案") | O5: =SUMIFS('來源明細'!$F$2:$F$1401,'來源明細'!$A$2:$A$1401,O$4,'來源明細'!$E$2:$E$1401,"內案") | ... X5: =SUMIFS('來源明細'!$F$2:$F$1401,'來源明細'!$A$2:$A$1401,X$4,'來源明細'!$E$2:$E$1401,"內案")
A6: 內案 | B6: 3 | D6: Cr. | E6: 63810030 | F6: 工程費用轉在建工程 | G6: 上列反向 | H6: =-H5 | I6: =-I5 | J6: =-J5 | K6: =-K5 | L6: =-L5 | M6: =-M5 | N6: =-N5 | O6: =-O5 | ... X6: =-X5
F7: 借貸差（應為0） | H7: =ROUND(SUM(H5:H6),2) | I7: =ROUND(SUM(I5:I6),2) | J7: =ROUND(SUM(J5:J6),2) | K7: =ROUND(SUM(K5:K6),2) | L7: =ROUND(SUM(L5:L6),2) | M7: =ROUND(SUM(M5:M6),2) | N7: =ROUND(SUM(N5:N6),2) | O7: =ROUND(SUM(O5:O6),2) | ... X7: =ROUND(SUM(X5:X6),2)
A9: 內案 | B9: 4 | C9: BIM完工百分比損益認列 | D9: Dr. | E9: 55110000 | F9: 承攬工程成本 | G9: A0 在建工程 | H9: =SUMIFS('來源明細'!$F$2:$F$1401,'來源明細'!$A$2:$A$1401,H$4,'來源明細'!$E$2:$E$1401,"內案") | I9: =SUMIFS('來源明細'!$F$2:$F$1401,'來源明細'!$A$2:$A$1401,I$4,'來源明細'!$E$2:$E$1401,"內案") | J9: =SUMIFS('來源明細'!$F$2:$F$1401,'來源明細'!$A$2:$A$1401,J$4,'來源明細'!$E$2:$E$1401,"內案") | K9: =SUMIFS('來源明細'!$F$2:$F$1401,'來源明細'!$A$2:$A$1401,K$4,'來源明細'!$E$2:$E$1401,"內案") | L9: =SUMIFS('來源明細'!$F$2:$F$1401,'來源明細'!$A$2:$A$1401,L$4,'來源明細'!$E$2:$E$1401,"內案") | M9: =SUMIFS('來源明細'!$F$2:$F$1401,'來源明細'!$A$2:$A$1401,M$4,'來源明細'!$E$2:$E$1401,"內案") | N9: =SUMIFS('來源明細'!$F$2:$F$1401,'來源明細'!$A$2:$A$1401,N$4,'來源明細'!$E$2:$E$1401,"內案") | O9: =SUMIFS('來源明細'!$F$2:$F$1401,'來源明細'!$A$2:$A$1401,O$4,'來源明細'!$E$2:$E$1401,"內案") | ... X9: =SUMIFS('來源明細'!$F$2:$F$1401,'來源明細'!$A$2:$A$1401,X$4,'來源明細'!$E$2:$E$1401,"內案")
A10: 內案 | B10: 4 | D10: Dr. | E10: 12470000 | F10: 在建損益-承攬案 | G10: A0 在建損益 | H10: =SUMIFS('來源明細'!$G$2:$G$1401,'來源明細'!$A$2:$A$1401,H$4,'來源明細'!$E$2:$E$1401,"內案") | I10: =SUMIFS('來源明細'!$G$2:$G$1401,'來源明細'!$A$2:$A$1401,I$4,'來源明細'!$E$2:$E$1401,"內案") | J10: =SUMIFS('來源明細'!$G$2:$G$1401,'來源明細'!$A$2:$A$1401,J$4,'來源明細'!$E$2:$E$1401,"內案") | K10: =SUMIFS('來源明細'!$G$2:$G$1401,'來源明細'!$A$2:$A$1401,K$4,'來源明細'!$E$2:$E$1401,"內案") | L10: =SUMIFS('來源明細'!$G$2:$G$1401,'來源明細'!$A$2:$A$1401,L$4,'來源明細'!$E$2:$E$1401,"內案") | M10: =SUMIFS('來源明細'!$G$2:$G$1401,'來源明細'!$A$2:$A$1401,M$4,'來源明細'!$E$2:$E$1401,"內案") | N10: =SUMIFS('來源明細'!$G$2:$G$1401,'來源明細'!$A$2:$A$1401,N$4,'來源明細'!$E$2:$E$1401,"內案") | O10: =SUMIFS('來源明細'!$G$2:$G$1401,'來源明細'!$A$2:$A$1401,O$4,'來源明細'!$E$2:$E$1401,"內案") | ... X10: =SUMIFS('來源明細'!$G$2:$G$1401,'來源明細'!$A$2:$A$1401,X$4,'來源明細'!$E$2:$E$1401,"內案")
A11: 內案 | B11: 4 | D11: Cr. | E11: 45110000 | F11: 承攬工程收入 | G11: A0 收入Total | H11: =-SUMIFS('來源明細'!$H$2:$H$1401,'來源明細'!$A$2:$A$1401,H$4,'來源明細'!$E$2:$E$1401,"內案") | I11: =-SUMIFS('來源明細'!$H$2:$H$1401,'來源明細'!$A$2:$A$1401,I$4,'來源明細'!$E$2:$E$1401,"內案") | J11: =-SUMIFS('來源明細'!$H$2:$H$1401,'來源明細'!$A$2:$A$1401,J$4,'來源明細'!$E$2:$E$1401,"內案") | K11: =-SUMIFS('來源明細'!$H$2:$H$1401,'來源明細'!$A$2:$A$1401,K$4,'來源明細'!$E$2:$E$1401,"內案") | L11: =-SUMIFS('來源明細'!$H$2:$H$1401,'來源明細'!$A$2:$A$1401,L$4,'來源明細'!$E$2:$E$1401,"內案") | M11: =-SUMIFS('來源明細'!$H$2:$H$1401,'來源明細'!$A$2:$A$1401,M$4,'來源明細'!$E$2:$E$1401,"內案") | N11: =-SUMIFS('來源明細'!$H$2:$H$1401,'來源明細'!$A$2:$A$1401,N$4,'來源明細'!$E$2:$E$1401,"內案") | O11: =-SUMIFS('來源明細'!$H$2:$H$1401,'來源明細'!$A$2:$A$1401,O$4,'來源明細'!$E$2:$E$1401,"內案") | ... X11: =-SUMIFS('來源明細'!$H$2:$H$1401,'來源明細'!$A$2:$A$1401,X$4,'來源明細'!$E$2:$E$1401,"內案")
F12: 借貸差（應為0） | H12: =ROUND(SUM(H9:H11),2) | I12: =ROUND(SUM(I9:I11),2) | J12: =ROUND(SUM(J9:J11),2) | K12: =ROUND(SUM(K9:K11),2) | L12: =ROUND(SUM(L9:L11),2) | M12: =ROUND(SUM(M9:M11),2) | N12: =ROUND(SUM(N9:N11),2) | O12: =ROUND(SUM(O9:O11),2) | ... X12: =ROUND(SUM(X9:X11),2)
A14: 內案 | B14: 5 | C14: BIM開立發票(內部計價) | D14: Dr. | E14: 11430000 | F14: 公司內部往來-TO & BIM | G14: B0 預收開票 | H14: =SUMIFS('來源明細'!$J$2:$J$1401,'來源明細'!$A$2:$A$1401,H$4,'來源明細'!$E$2:$E$1401,"內案") | I14: =SUMIFS('來源明細'!$J$2:$J$1401,'來源明細'!$A$2:$A$1401,I$4,'來源明細'!$E$2:$E$1401,"內案") | J14: =SUMIFS('來源明細'!$J$2:$J$1401,'來源明細'!$A$2:$A$1401,J$4,'來源明細'!$E$2:$E$1401,"內案") | K14: =SUMIFS('來源明細'!$J$2:$J$1401,'來源明細'!$A$2:$A$1401,K$4,'來源明細'!$E$2:$E$1401,"內案") | L14: =SUMIFS('來源明細'!$J$2:$J$1401,'來源明細'!$A$2:$A$1401,L$4,'來源明細'!$E$2:$E$1401,"內案") | M14: =SUMIFS('來源明細'!$J$2:$J$1401,'來源明細'!$A$2:$A$1401,M$4,'來源明細'!$E$2:$E$1401,"內案") | N14: =SUMIFS('來源明細'!$J$2:$J$1401,'來源明細'!$A$2:$A$1401,N$4,'來源明細'!$E$2:$E$1401,"內案") | O14: =SUMIFS('來源明細'!$J$2:$J$1401,'來源明細'!$A$2:$A$1401,O$4,'來源明細'!$E$2:$E$1401,"內案") | ... X14: =SUMIFS('來源明細'!$J$2:$J$1401,'來源明細'!$A$2:$A$1401,X$4,'來源明細'!$E$2:$E$1401,"內案")
A15: 內案 | B15: 5 | D15: Cr. | E15: 22640000 | F15: 預收工程款 | G15: 上列反向 | H15: =-H14 | I15: =-I14 | J15: =-J14 | K15: =-K14 | L15: =-L14 | M15: =-M14 | N15: =-N14 | O15: =-O14 | ... X15: =-X14
F16: 借貸差（應為0） | H16: =ROUND(SUM(H14:H15),2) | I16: =ROUND(SUM(I14:I15),2) | J16: =ROUND(SUM(J14:J15),2) | K16: =ROUND(SUM(K14:K15),2) | L16: =ROUND(SUM(L14:L15),2) | M16: =ROUND(SUM(M14:M15),2) | N16: =ROUND(SUM(N14:N15),2) | O16: =ROUND(SUM(O14:O15),2) | ... X16: =ROUND(SUM(X14:X15),2)
A18: 內案 | B18: 6 | C18: 毛損認列負債準備 | D18: Dr. | E18: 55110000 | F18: 承攬工程成本 | G18: A0 負債準備反向 | H18: =-SUMIFS('來源明細'!$I$2:$I$1401,'來源明細'!$A$2:$A$1401,H$4,'來源明細'!$E$2:$E$1401,"內案") | I18: =-SUMIFS('來源明細'!$I$2:$I$1401,'來源明細'!$A$2:$A$1401,I$4,'來源明細'!$E$2:$E$1401,"內案") | J18: =-SUMIFS('來源明細'!$I$2:$I$1401,'來源明細'!$A$2:$A$1401,J$4,'來源明細'!$E$2:$E$1401,"內案") | K18: =-SUMIFS('來源明細'!$I$2:$I$1401,'來源明細'!$A$2:$A$1401,K$4,'來源明細'!$E$2:$E$1401,"內案") | L18: =-SUMIFS('來源明細'!$I$2:$I$1401,'來源明細'!$A$2:$A$1401,L$4,'來源明細'!$E$2:$E$1401,"內案") | M18: =-SUMIFS('來源明細'!$I$2:$I$1401,'來源明細'!$A$2:$A$1401,M$4,'來源明細'!$E$2:$E$1401,"內案") | N18: =-SUMIFS('來源明細'!$I$2:$I$1401,'來源明細'!$A$2:$A$1401,N$4,'來源明細'!$E$2:$E$1401,"內案") | O18: =-SUMIFS('來源明細'!$I$2:$I$1401,'來源明細'!$A$2:$A$1401,O$4,'來源明細'!$E$2:$E$1401,"內案") | ... X18: =-SUMIFS('來源明細'!$I$2:$I$1401,'來源明細'!$A$2:$A$1401,X$4,'來源明細'!$E$2:$E$1401,"內案")
A19: 內案 | B19: 6 | D19: Cr. | F19: 負債準備-在建損失 | G19: A0 負債準備 | H19: =-H18 | I19: =-I18 | J19: =-J18 | K19: =-K18 | L19: =-L18 | M19: =-M18 | N19: =-N18 | O19: =-O18 | ... X19: =-X18
F20: 借貸差（應為0） | H20: =ROUND(SUM(H18:H19),2) | I20: =ROUND(SUM(I18:I19),2) | J20: =ROUND(SUM(J18:J19),2) | K20: =ROUND(SUM(K18:K19),2) | L20: =ROUND(SUM(L18:L19),2) | M20: =ROUND(SUM(M18:M19),2) | N20: =ROUND(SUM(N18:N19),2) | O20: =ROUND(SUM(O18:O19),2) | ... X20: =ROUND(SUM(X18:X19),2)
A22: 外案 | B22: 3 | C22: BIM月底結轉在建(CJ88) | D22: Dr. | E22: 12400000 | F22: 在建工程 | G22: A0 在建工程 | H22: =SUMIFS('來源明細'!$F$2:$F$1401,'來源明細'!$A$2:$A$1401,H$4,'來源明細'!$E$2:$E$1401,"外案") | I22: =SUMIFS('來源明細'!$F$2:$F$1401,'來源明細'!$A$2:$A$1401,I$4,'來源明細'!$E$2:$E$1401,"外案") | J22: =SUMIFS('來源明細'!$F$2:$F$1401,'來源明細'!$A$2:$A$1401,J$4,'來源明細'!$E$2:$E$1401,"外案") | K22: =SUMIFS('來源明細'!$F$2:$F$1401,'來源明細'!$A$2:$A$1401,K$4,'來源明細'!$E$2:$E$1401,"外案") | L22: =SUMIFS('來源明細'!$F$2:$F$1401,'來源明細'!$A$2:$A$1401,L$4,'來源明細'!$E$2:$E$1401,"外案") | M22: =SUMIFS('來源明細'!$F$2:$F$1401,'來源明細'!$A$2:$A$1401,M$4,'來源明細'!$E$2:$E$1401,"外案") | N22: =SUMIFS('來源明細'!$F$2:$F$1401,'來源明細'!$A$2:$A$1401,N$4,'來源明細'!$E$2:$E$1401,"外案") | O22: =SUMIFS('來源明細'!$F$2:$F$1401,'來源明細'!$A$2:$A$1401,O$4,'來源明細'!$E$2:$E$1401,"外案") | ... X22: =SUMIFS('來源明細'!$F$2:$F$1401,'來源明細'!$A$2:$A$1401,X$4,'來源明細'!$E$2:$E$1401,"外案")
A23: 外案 | B23: 3 | D23: Cr. | E23: 63810030 | F23: 工程費用轉在建工程 | G23: 上列反向 | H23: =-H22 | I23: =-I22 | J23: =-J22 | K23: =-K22 | L23: =-L22 | M23: =-M22 | N23: =-N22 | O23: =-O22 | ... X23: =-X22
F24: 借貸差（應為0） | H24: =ROUND(SUM(H22:H23),2) | I24: =ROUND(SUM(I22:I23),2) | J24: =ROUND(SUM(J22:J23),2) | K24: =ROUND(SUM(K22:K23),2) | L24: =ROUND(SUM(L22:L23),2) | M24: =ROUND(SUM(M22:M23),2) | N24: =ROUND(SUM(N22:N23),2) | O24: =ROUND(SUM(O22:O23),2) | ... X24: =ROUND(SUM(X22:X23),2)
A26: 外案 | B26: 4 | C26: BIM完工百分比損益認列 | D26: Dr. | E26: 55110000 | F26: 承攬工程成本 | G26: A0 在建工程 | H26: =SUMIFS('來源明細'!$F$2:$F$1401,'來源明細'!$A$2:$A$1401,H$4,'來源明細'!$E$2:$E$1401,"外案") | I26: =SUMIFS('來源明細'!$F$2:$F$1401,'來源明細'!$A$2:$A$1401,I$4,'來源明細'!$E$2:$E$1401,"外案") | J26: =SUMIFS('來源明細'!$F$2:$F$1401,'來源明細'!$A$2:$A$1401,J$4,'來源明細'!$E$2:$E$1401,"外案") | K26: =SUMIFS('來源明細'!$F$2:$F$1401,'來源明細'!$A$2:$A$1401,K$4,'來源明細'!$E$2:$E$1401,"外案") | L26: =SUMIFS('來源明細'!$F$2:$F$1401,'來源明細'!$A$2:$A$1401,L$4,'來源明細'!$E$2:$E$1401,"外案") | M26: =SUMIFS('來源明細'!$F$2:$F$1401,'來源明細'!$A$2:$A$1401,M$4,'來源明細'!$E$2:$E$1401,"外案") | N26: =SUMIFS('來源明細'!$F$2:$F$1401,'來源明細'!$A$2:$A$1401,N$4,'來源明細'!$E$2:$E$1401,"外案") | O26: =SUMIFS('來源明細'!$F$2:$F$1401,'來源明細'!$A$2:$A$1401,O$4,'來源明細'!$E$2:$E$1401,"外案") | ... X26: =SUMIFS('來源明細'!$F$2:$F$1401,'來源明細'!$A$2:$A$1401,X$4,'來源明細'!$E$2:$E$1401,"外案")
A27: 外案 | B27: 4 | D27: Dr. | E27: 12470000 | F27: 在建損益-承攬案 | G27: A0 在建損益 | H27: =SUMIFS('來源明細'!$G$2:$G$1401,'來源明細'!$A$2:$A$1401,H$4,'來源明細'!$E$2:$E$1401,"外案") | I27: =SUMIFS('來源明細'!$G$2:$G$1401,'來源明細'!$A$2:$A$1401,I$4,'來源明細'!$E$2:$E$1401,"外案") | J27: =SUMIFS('來源明細'!$G$2:$G$1401,'來源明細'!$A$2:$A$1401,J$4,'來源明細'!$E$2:$E$1401,"外案") | K27: =SUMIFS('來源明細'!$G$2:$G$1401,'來源明細'!$A$2:$A$1401,K$4,'來源明細'!$E$2:$E$1401,"外案") | L27: =SUMIFS('來源明細'!$G$2:$G$1401,'來源明細'!$A$2:$A$1401,L$4,'來源明細'!$E$2:$E$1401,"外案") | M27: =SUMIFS('來源明細'!$G$2:$G$1401,'來源明細'!$A$2:$A$1401,M$4,'來源明細'!$E$2:$E$1401,"外案") | N27: =SUMIFS('來源明細'!$G$2:$G$1401,'來源明細'!$A$2:$A$1401,N$4,'來源明細'!$E$2:$E$1401,"外案") | O27: =SUMIFS('來源明細'!$G$2:$G$1401,'來源明細'!$A$2:$A$1401,O$4,'來源明細'!$E$2:$E$1401,"外案") | ... X27: =SUMIFS('來源明細'!$G$2:$G$1401,'來源明細'!$A$2:$A$1401,X$4,'來源明細'!$E$2:$E$1401,"外案")
A28: 外案 | B28: 4 | D28: Cr. | E28: 45110000 | F28: 承攬工程收入 | G28: A0 收入Total | H28: =-SUMIFS('來源明細'!$H$2:$H$1401,'來源明細'!$A$2:$A$1401,H$4,'來源明細'!$E$2:$E$1401,"外案") | I28: =-SUMIFS('來源明細'!$H$2:$H$1401,'來源明細'!$A$2:$A$1401,I$4,'來源明細'!$E$2:$E$1401,"外案") | J28: =-SUMIFS('來源明細'!$H$2:$H$1401,'來源明細'!$A$2:$A$1401,J$4,'來源明細'!$E$2:$E$1401,"外案") | K28: =-SUMIFS('來源明細'!$H$2:$H$1401,'來源明細'!$A$2:$A$1401,K$4,'來源明細'!$E$2:$E$1401,"外案") | L28: =-SUMIFS('來源明細'!$H$2:$H$1401,'來源明細'!$A$2:$A$1401,L$4,'來源明細'!$E$2:$E$1401,"外案") | M28: =-SUMIFS('來源明細'!$H$2:$H$1401,'來源明細'!$A$2:$A$1401,M$4,'來源明細'!$E$2:$E$1401,"外案") | N28: =-SUMIFS('來源明細'!$H$2:$H$1401,'來源明細'!$A$2:$A$1401,N$4,'來源明細'!$E$2:$E$1401,"外案") | O28: =-SUMIFS('來源明細'!$H$2:$H$1401,'來源明細'!$A$2:$A$1401,O$4,'來源明細'!$E$2:$E$1401,"外案") | ... X28: =-SUMIFS('來源明細'!$H$2:$H$1401,'來源明細'!$A$2:$A$1401,X$4,'來源明細'!$E$2:$E$1401,"外案")
F29: 借貸差（應為0） | H29: =ROUND(SUM(H26:H28),2) | I29: =ROUND(SUM(I26:I28),2) | J29: =ROUND(SUM(J26:J28),2) | K29: =ROUND(SUM(K26:K28),2) | L29: =ROUND(SUM(L26:L28),2) | M29: =ROUND(SUM(M26:M28),2) | N29: =ROUND(SUM(N26:N28),2) | O29: =ROUND(SUM(O26:O28),2) | ... X29: =ROUND(SUM(X26:X28),2)
A31: 外案 | B31: 5 | C31: BIM開立業主發票 | D31: Dr. | E31: 11430000 | F31: 應收帳款 | G31: 預收＋銷項 | H31: =-(H32+H33) | I31: =-(I32+I33) | J31: =-(J32+J33) | K31: =-(K32+K33) | L31: =-(L32+L33) | M31: =-(M32+M33) | N31: =-(N32+N33) | O31: =-(O32+O33) | ... X31: =-(X32+X33)
A32: 外案 | B32: 5 | D32: Cr. | E32: 22640000 | F32: 預收工程款 | G32: B0 預收開票 | H32: =-SUMIFS('來源明細'!$J$2:$J$1401,'來源明細'!$A$2:$A$1401,H$4,'來源明細'!$E$2:$E$1401,"外案") | I32: =-SUMIFS('來源明細'!$J$2:$J$1401,'來源明細'!$A$2:$A$1401,I$4,'來源明細'!$E$2:$E$1401,"外案") | J32: =-SUMIFS('來源明細'!$J$2:$J$1401,'來源明細'!$A$2:$A$1401,J$4,'來源明細'!$E$2:$E$1401,"外案") | K32: =-SUMIFS('來源明細'!$J$2:$J$1401,'來源明細'!$A$2:$A$1401,K$4,'來源明細'!$E$2:$E$1401,"外案") | L32: =-SUMIFS('來源明細'!$J$2:$J$1401,'來源明細'!$A$2:$A$1401,L$4,'來源明細'!$E$2:$E$1401,"外案") | M32: =-SUMIFS('來源明細'!$J$2:$J$1401,'來源明細'!$A$2:$A$1401,M$4,'來源明細'!$E$2:$E$1401,"外案") | N32: =-SUMIFS('來源明細'!$J$2:$J$1401,'來源明細'!$A$2:$A$1401,N$4,'來源明細'!$E$2:$E$1401,"外案") | O32: =-SUMIFS('來源明細'!$J$2:$J$1401,'來源明細'!$A$2:$A$1401,O$4,'來源明細'!$E$2:$E$1401,"外案") | ... X32: =-SUMIFS('來源明細'!$J$2:$J$1401,'來源明細'!$A$2:$A$1401,X$4,'來源明細'!$E$2:$E$1401,"外案")
A33: 外案 | B33: 5 | D33: Cr. | E33: 22140000 | F33: 銷項稅額 | G33: 預收×5%(四捨五入) | H33: =-ROUND(-H32*0.05,0) | I33: =-ROUND(-I32*0.05,0) | J33: =-ROUND(-J32*0.05,0) | K33: =-ROUND(-K32*0.05,0) | L33: =-ROUND(-L32*0.05,0) | M33: =-ROUND(-M32*0.05,0) | N33: =-ROUND(-N32*0.05,0) | O33: =-ROUND(-O32*0.05,0) | ... X33: =-ROUND(-X32*0.05,0)
F34: 借貸差（應為0） | H34: =ROUND(SUM(H31:H33),2) | I34: =ROUND(SUM(I31:I33),2) | J34: =ROUND(SUM(J31:J33),2) | K34: =ROUND(SUM(K31:K33),2) | L34: =ROUND(SUM(L31:L33),2) | M34: =ROUND(SUM(M31:M33),2) | N34: =ROUND(SUM(N31:N33),2) | O34: =ROUND(SUM(O31:O33),2) | ... X34: =ROUND(SUM(X31:X33),2)
A36: 外案 | B36: 6 | C36: 毛損認列負債準備 | D36: Dr. | E36: 55110000 | F36: 承攬工程成本 | G36: A0 負債準備反向 | H36: =-SUMIFS('來源明細'!$I$2:$I$1401,'來源明細'!$A$2:$A$1401,H$4,'來源明細'!$E$2:$E$1401,"外案") | I36: =-SUMIFS('來源明細'!$I$2:$I$1401,'來源明細'!$A$2:$A$1401,I$4,'來源明細'!$E$2:$E$1401,"外案") | J36: =-SUMIFS('來源明細'!$I$2:$I$1401,'來源明細'!$A$2:$A$1401,J$4,'來源明細'!$E$2:$E$1401,"外案") | K36: =-SUMIFS('來源明細'!$I$2:$I$1401,'來源明細'!$A$2:$A$1401,K$4,'來源明細'!$E$2:$E$1401,"外案") | L36: =-SUMIFS('來源明細'!$I$2:$I$1401,'來源明細'!$A$2:$A$1401,L$4,'來源明細'!$E$2:$E$1401,"外案") | M36: =-SUMIFS('來源明細'!$I$2:$I$1401,'來源明細'!$A$2:$A$1401,M$4,'來源明細'!$E$2:$E$1401,"外案") | N36: =-SUMIFS('來源明細'!$I$2:$I$1401,'來源明細'!$A$2:$A$1401,N$4,'來源明細'!$E$2:$E$1401,"外案") | O36: =-SUMIFS('來源明細'!$I$2:$I$1401,'來源明細'!$A$2:$A$1401,O$4,'來源明細'!$E$2:$E$1401,"外案") | ... X36: =-SUMIFS('來源明細'!$I$2:$I$1401,'來源明細'!$A$2:$A$1401,X$4,'來源明細'!$E$2:$E$1401,"外案")
A37: 外案 | B37: 6 | D37: Cr. | F37: 負債準備-在建損失 | G37: A0 負債準備 | H37: =-H36 | I37: =-I36 | J37: =-J36 | K37: =-K36 | L37: =-L36 | M37: =-M36 | N37: =-N36 | O37: =-O36 | ... X37: =-X36
F38: 借貸差（應為0） | H38: =ROUND(SUM(H36:H37),2) | I38: =ROUND(SUM(I36:I37),2) | J38: =ROUND(SUM(J36:J37),2) | K38: =ROUND(SUM(K36:K37),2) | L38: =ROUND(SUM(L36:L37),2) | M38: =ROUND(SUM(M36:M37),2) | N38: =ROUND(SUM(N36:N37),2) | O38: =ROUND(SUM(O36:O37),2) | ... X38: =ROUND(SUM(X36:X37),2)
A40: 雜項 | B40: 2 | C40: BIM費用轉列成本 | D40: Dr. | E40: 55/56xxxxxx | F40: 專案成本 | G40: A0 在建工程欄(成本) | H40: =SUMIFS('來源明細'!$F$2:$F$1401,'來源明細'!$A$2:$A$1401,H$4,'來源明細'!$E$2:$E$1401,"雜項") | I40: =SUMIFS('來源明細'!$F$2:$F$1401,'來源明細'!$A$2:$A$1401,I$4,'來源明細'!$E$2:$E$1401,"雜項") | J40: =SUMIFS('來源明細'!$F$2:$F$1401,'來源明細'!$A$2:$A$1401,J$4,'來源明細'!$E$2:$E$1401,"雜項") | K40: =SUMIFS('來源明細'!$F$2:$F$1401,'來源明細'!$A$2:$A$1401,K$4,'來源明細'!$E$2:$E$1401,"雜項") | L40: =SUMIFS('來源明細'!$F$2:$F$1401,'來源明細'!$A$2:$A$1401,L$4,'來源明細'!$E$2:$E$1401,"雜項") | M40: =SUMIFS('來源明細'!$F$2:$F$1401,'來源明細'!$A$2:$A$1401,M$4,'來源明細'!$E$2:$E$1401,"雜項") | N40: =SUMIFS('來源明細'!$F$2:$F$1401,'來源明細'!$A$2:$A$1401,N$4,'來源明細'!$E$2:$E$1401,"雜項") | O40: =SUMIFS('來源明細'!$F$2:$F$1401,'來源明細'!$A$2:$A$1401,O$4,'來源明細'!$E$2:$E$1401,"雜項") | ... X40: =SUMIFS('來源明細'!$F$2:$F$1401,'來源明細'!$A$2:$A$1401,X$4,'來源明細'!$E$2:$E$1401,"雜項")
A41: 雜項 | B41: 2 | D41: Cr. | E41: 62109999/62350099 | F41: 人事分攤／電腦out charge（合計，拆分無資料） | G41: 上列反向 | H41: =-H40 | I41: =-I40 | J41: =-J40 | K41: =-K40 | L41: =-L40 | M41: =-M40 | N41: =-N40 | O41: =-O40 | ... X41: =-X40
F42: 借貸差（應為0） | H42: =ROUND(SUM(H40:H41),2) | I42: =ROUND(SUM(I40:I41),2) | J42: =ROUND(SUM(J40:J41),2) | K42: =ROUND(SUM(K40:K41),2) | L42: =ROUND(SUM(L40:L41),2) | M42: =ROUND(SUM(M40:M41),2) | N42: =ROUND(SUM(N40:N41),2) | O42: =ROUND(SUM(O40:O41),2) | ... X42: =ROUND(SUM(X40:X41),2)
A44: 雜項 | B44: 5 | C44: BIM開立發票(內部計價) | D44: Dr. | E44: 11430000 | F44: 公司內部往來-TO & BIM | G44: B0 預收開票 | H44: =SUMIFS('來源明細'!$J$2:$J$1401,'來源明細'!$A$2:$A$1401,H$4,'來源明細'!$E$2:$E$1401,"雜項") | I44: =SUMIFS('來源明細'!$J$2:$J$1401,'來源明細'!$A$2:$A$1401,I$4,'來源明細'!$E$2:$E$1401,"雜項") | J44: =SUMIFS('來源明細'!$J$2:$J$1401,'來源明細'!$A$2:$A$1401,J$4,'來源明細'!$E$2:$E$1401,"雜項") | K44: =SUMIFS('來源明細'!$J$2:$J$1401,'來源明細'!$A$2:$A$1401,K$4,'來源明細'!$E$2:$E$1401,"雜項") | L44: =SUMIFS('來源明細'!$J$2:$J$1401,'來源明細'!$A$2:$A$1401,L$4,'來源明細'!$E$2:$E$1401,"雜項") | M44: =SUMIFS('來源明細'!$J$2:$J$1401,'來源明細'!$A$2:$A$1401,M$4,'來源明細'!$E$2:$E$1401,"雜項") | N44: =SUMIFS('來源明細'!$J$2:$J$1401,'來源明細'!$A$2:$A$1401,N$4,'來源明細'!$E$2:$E$1401,"雜項") | O44: =SUMIFS('來源明細'!$J$2:$J$1401,'來源明細'!$A$2:$A$1401,O$4,'來源明細'!$E$2:$E$1401,"雜項") | ... X44: =SUMIFS('來源明細'!$J$2:$J$1401,'來源明細'!$A$2:$A$1401,X$4,'來源明細'!$E$2:$E$1401,"雜項")
A45: 雜項 | B45: 5 | D45: Cr. | E45: 46110050 | F45: 勞務收入-內部計價 | G45: 上列反向 | H45: =-H44 | I45: =-I44 | J45: =-J44 | K45: =-K44 | L45: =-L44 | M45: =-M44 | N45: =-N44 | O45: =-O44 | ... X45: =-X44
F46: 借貸差（應為0） | H46: =ROUND(SUM(H44:H45),2) | I46: =ROUND(SUM(I44:I45),2) | J46: =ROUND(SUM(J44:J45),2) | K46: =ROUND(SUM(K44:K45),2) | L46: =ROUND(SUM(L44:L45),2) | M46: =ROUND(SUM(M44:M45),2) | N46: =ROUND(SUM(N44:N45),2) | O46: =ROUND(SUM(O44:O45),2) | ... X46: =ROUND(SUM(X44:X45),2)
A48: 備標 | B48: 2 | C48: BIM費用轉列成本 | D48: Dr. | E48: 55/56xxxxxx | F48: 專案成本 | G48: A0 在建工程欄(成本) | H48: =SUMIFS('來源明細'!$F$2:$F$1401,'來源明細'!$A$2:$A$1401,H$4,'來源明細'!$E$2:$E$1401,"備標") | I48: =SUMIFS('來源明細'!$F$2:$F$1401,'來源明細'!$A$2:$A$1401,I$4,'來源明細'!$E$2:$E$1401,"備標") | J48: =SUMIFS('來源明細'!$F$2:$F$1401,'來源明細'!$A$2:$A$1401,J$4,'來源明細'!$E$2:$E$1401,"備標") | K48: =SUMIFS('來源明細'!$F$2:$F$1401,'來源明細'!$A$2:$A$1401,K$4,'來源明細'!$E$2:$E$1401,"備標") | L48: =SUMIFS('來源明細'!$F$2:$F$1401,'來源明細'!$A$2:$A$1401,L$4,'來源明細'!$E$2:$E$1401,"備標") | M48: =SUMIFS('來源明細'!$F$2:$F$1401,'來源明細'!$A$2:$A$1401,M$4,'來源明細'!$E$2:$E$1401,"備標") | N48: =SUMIFS('來源明細'!$F$2:$F$1401,'來源明細'!$A$2:$A$1401,N$4,'來源明細'!$E$2:$E$1401,"備標") | O48: =SUMIFS('來源明細'!$F$2:$F$1401,'來源明細'!$A$2:$A$1401,O$4,'來源明細'!$E$2:$E$1401,"備標") | ... X48: =SUMIFS('來源明細'!$F$2:$F$1401,'來源明細'!$A$2:$A$1401,X$4,'來源明細'!$E$2:$E$1401,"備標")
A49: 備標 | B49: 2 | D49: Cr. | E49: 62109999/62350099 | F49: 人事分攤／電腦out charge（合計，拆分無資料） | G49: 上列反向 | H49: =-H48 | I49: =-I48 | J49: =-J48 | K49: =-K48 | L49: =-L48 | M49: =-M48 | N49: =-N48 | O49: =-O48 | ... X49: =-X48
F50: 借貸差（應為0） | H50: =ROUND(SUM(H48:H49),2) | I50: =ROUND(SUM(I48:I49),2) | J50: =ROUND(SUM(J48:J49),2) | K50: =ROUND(SUM(K48:K49),2) | L50: =ROUND(SUM(L48:L49),2) | M50: =ROUND(SUM(M48:M49),2) | N50: =ROUND(SUM(N48:N49),2) | O50: =ROUND(SUM(O48:O49),2) | ... X50: =ROUND(SUM(X48:X49),2)
A52: 備標 | B52: 5 | C52: BIM開立發票(內部計價) | D52: Dr. | E52: 11430000 | F52: 公司內部往來-TO & BIM | G52: B0 預收開票 | H52: =SUMIFS('來源明細'!$J$2:$J$1401,'來源明細'!$A$2:$A$1401,H$4,'來源明細'!$E$2:$E$1401,"備標") | I52: =SUMIFS('來源明細'!$J$2:$J$1401,'來源明細'!$A$2:$A$1401,I$4,'來源明細'!$E$2:$E$1401,"備標") | J52: =SUMIFS('來源明細'!$J$2:$J$1401,'來源明細'!$A$2:$A$1401,J$4,'來源明細'!$E$2:$E$1401,"備標") | K52: =SUMIFS('來源明細'!$J$2:$J$1401,'來源明細'!$A$2:$A$1401,K$4,'來源明細'!$E$2:$E$1401,"備標") | L52: =SUMIFS('來源明細'!$J$2:$J$1401,'來源明細'!$A$2:$A$1401,L$4,'來源明細'!$E$2:$E$1401,"備標") | M52: =SUMIFS('來源明細'!$J$2:$J$1401,'來源明細'!$A$2:$A$1401,M$4,'來源明細'!$E$2:$E$1401,"備標") | N52: =SUMIFS('來源明細'!$J$2:$J$1401,'來源明細'!$A$2:$A$1401,N$4,'來源明細'!$E$2:$E$1401,"備標") | O52: =SUMIFS('來源明細'!$J$2:$J$1401,'來源明細'!$A$2:$A$1401,O$4,'來源明細'!$E$2:$E$1401,"備標") | ... X52: =SUMIFS('來源明細'!$J$2:$J$1401,'來源明細'!$A$2:$A$1401,X$4,'來源明細'!$E$2:$E$1401,"備標")
...

Sheet 期末總結
A1: 各期科目彙總（依分錄頁加總，+借／−貸）與在建・預收餘額滾算
A3: 分類 | B3: 類別 | C3: 會科代號 | D3: 會科名稱 | E3: 2026/09 ~ 2026/12 | F3: 2027/1 | G3: 2027/2 | H3: 2027/3 | I3: 2027/4 | J3: 2027/5 | K3: 2027/6 | L3: 2027/7 | M3: 2027/8 | N3: 2027/9 | O3: 2027/10 | P3: 2027/11 | Q3: 2027/12 | R3: Year 2028 | S3: Year 2029 | T3: Year 2030 | U3: Year 2031
A4: 內案 | B4: B/S | C4: 12400000 | D4: 在建工程 | E4: =SUMIFS('分錄'!H$5:H$54,'分錄'!$A$5:$A$54,$A4,'分錄'!$E$5:$E$54,$C4) | F4: =SUMIFS('分錄'!I$5:I$54,'分錄'!$A$5:$A$54,$A4,'分錄'!$E$5:$E$54,$C4) | G4: =SUMIFS('分錄'!J$5:J$54,'分錄'!$A$5:$A$54,$A4,'分錄'!$E$5:$E$54,$C4) | H4: =SUMIFS('分錄'!K$5:K$54,'分錄'!$A$5:$A$54,$A4,'分錄'!$E$5:$E$54,$C4) | I4: =SUMIFS('分錄'!L$5:L$54,'分錄'!$A$5:$A$54,$A4,'分錄'!$E$5:$E$54,$C4) | J4: =SUMIFS('分錄'!M$5:M$54,'分錄'!$A$5:$A$54,$A4,'分錄'!$E$5:$E$54,$C4) | K4: =SUMIFS('分錄'!N$5:N$54,'分錄'!$A$5:$A$54,$A4,'分錄'!$E$5:$E$54,$C4) | L4: =SUMIFS('分錄'!O$5:O$54,'分錄'!$A$5:$A$54,$A4,'分錄'!$E$5:$E$54,$C4) | ... U4: =SUMIFS('分錄'!X$5:X$54,'分錄'!$A$5:$A$54,$A4,'分錄'!$E$5:$E$54,$C4)
A5: 內案 | B5: B/S | C5: 12470000 | D5: 在建損益-承攬案 | E5: =SUMIFS('分錄'!H$5:H$54,'分錄'!$A$5:$A$54,$A5,'分錄'!$E$5:$E$54,$C5) | F5: =SUMIFS('分錄'!I$5:I$54,'分錄'!$A$5:$A$54,$A5,'分錄'!$E$5:$E$54,$C5) | G5: =SUMIFS('分錄'!J$5:J$54,'分錄'!$A$5:$A$54,$A5,'分錄'!$E$5:$E$54,$C5) | H5: =SUMIFS('分錄'!K$5:K$54,'分錄'!$A$5:$A$54,$A5,'分錄'!$E$5:$E$54,$C5) | I5: =SUMIFS('分錄'!L$5:L$54,'分錄'!$A$5:$A$54,$A5,'分錄'!$E$5:$E$54,$C5) | J5: =SUMIFS('分錄'!M$5:M$54,'分錄'!$A$5:$A$54,$A5,'分錄'!$E$5:$E$54,$C5) | K5: =SUMIFS('分錄'!N$5:N$54,'分錄'!$A$5:$A$54,$A5,'分錄'!$E$5:$E$54,$C5) | L5: =SUMIFS('分錄'!O$5:O$54,'分錄'!$A$5:$A$54,$A5,'分錄'!$E$5:$E$54,$C5) | ... U5: =SUMIFS('分錄'!X$5:X$54,'分錄'!$A$5:$A$54,$A5,'分錄'!$E$5:$E$54,$C5)
A6: 內案 | B6: B/S | C6: 22640000 | D6: 預收工程款 | E6: =SUMIFS('分錄'!H$5:H$54,'分錄'!$A$5:$A$54,$A6,'分錄'!$E$5:$E$54,$C6) | F6: =SUMIFS('分錄'!I$5:I$54,'分錄'!$A$5:$A$54,$A6,'分錄'!$E$5:$E$54,$C6) | G6: =SUMIFS('分錄'!J$5:J$54,'分錄'!$A$5:$A$54,$A6,'分錄'!$E$5:$E$54,$C6) | H6: =SUMIFS('分錄'!K$5:K$54,'分錄'!$A$5:$A$54,$A6,'分錄'!$E$5:$E$54,$C6) | I6: =SUMIFS('分錄'!L$5:L$54,'分錄'!$A$5:$A$54,$A6,'分錄'!$E$5:$E$54,$C6) | J6: =SUMIFS('分錄'!M$5:M$54,'分錄'!$A$5:$A$54,$A6,'分錄'!$E$5:$E$54,$C6) | K6: =SUMIFS('分錄'!N$5:N$54,'分錄'!$A$5:$A$54,$A6,'分錄'!$E$5:$E$54,$C6) | L6: =SUMIFS('分錄'!O$5:O$54,'分錄'!$A$5:$A$54,$A6,'分錄'!$E$5:$E$54,$C6) | ... U6: =SUMIFS('分錄'!X$5:X$54,'分錄'!$A$5:$A$54,$A6,'分錄'!$E$5:$E$54,$C6)
A7: 內案 | B7: B/S | C7: 11430000 | D7: 公司內部往來-TO & BIM | E7: =SUMIFS('分錄'!H$5:H$54,'分錄'!$A$5:$A$54,$A7,'分錄'!$E$5:$E$54,$C7) | F7: =SUMIFS('分錄'!I$5:I$54,'分錄'!$A$5:$A$54,$A7,'分錄'!$E$5:$E$54,$C7) | G7: =SUMIFS('分錄'!J$5:J$54,'分錄'!$A$5:$A$54,$A7,'分錄'!$E$5:$E$54,$C7) | H7: =SUMIFS('分錄'!K$5:K$54,'分錄'!$A$5:$A$54,$A7,'分錄'!$E$5:$E$54,$C7) | I7: =SUMIFS('分錄'!L$5:L$54,'分錄'!$A$5:$A$54,$A7,'分錄'!$E$5:$E$54,$C7) | J7: =SUMIFS('分錄'!M$5:M$54,'分錄'!$A$5:$A$54,$A7,'分錄'!$E$5:$E$54,$C7) | K7: =SUMIFS('分錄'!N$5:N$54,'分錄'!$A$5:$A$54,$A7,'分錄'!$E$5:$E$54,$C7) | L7: =SUMIFS('分錄'!O$5:O$54,'分錄'!$A$5:$A$54,$A7,'分錄'!$E$5:$E$54,$C7) | ... U7: =SUMIFS('分錄'!X$5:X$54,'分錄'!$A$5:$A$54,$A7,'分錄'!$E$5:$E$54,$C7)
A8: 內案 | B8: B/S | D8: 負債準備-在建損失 | E8: =SUMIFS('分錄'!H$5:H$54,'分錄'!$A$5:$A$54,$A8,'分錄'!$F$5:$F$54,$D8) | F8: =SUMIFS('分錄'!I$5:I$54,'分錄'!$A$5:$A$54,$A8,'分錄'!$F$5:$F$54,$D8) | G8: =SUMIFS('分錄'!J$5:J$54,'分錄'!$A$5:$A$54,$A8,'分錄'!$F$5:$F$54,$D8) | H8: =SUMIFS('分錄'!K$5:K$54,'分錄'!$A$5:$A$54,$A8,'分錄'!$F$5:$F$54,$D8) | I8: =SUMIFS('分錄'!L$5:L$54,'分錄'!$A$5:$A$54,$A8,'分錄'!$F$5:$F$54,$D8) | J8: =SUMIFS('分錄'!M$5:M$54,'分錄'!$A$5:$A$54,$A8,'分錄'!$F$5:$F$54,$D8) | K8: =SUMIFS('分錄'!N$5:N$54,'分錄'!$A$5:$A$54,$A8,'分錄'!$F$5:$F$54,$D8) | L8: =SUMIFS('分錄'!O$5:O$54,'分錄'!$A$5:$A$54,$A8,'分錄'!$F$5:$F$54,$D8) | ... U8: =SUMIFS('分錄'!X$5:X$54,'分錄'!$A$5:$A$54,$A8,'分錄'!$F$5:$F$54,$D8)
A9: 內案 | B9: P/L | C9: 45110000 | D9: 承攬工程收入 | E9: =SUMIFS('分錄'!H$5:H$54,'分錄'!$A$5:$A$54,$A9,'分錄'!$E$5:$E$54,$C9) | F9: =SUMIFS('分錄'!I$5:I$54,'分錄'!$A$5:$A$54,$A9,'分錄'!$E$5:$E$54,$C9) | G9: =SUMIFS('分錄'!J$5:J$54,'分錄'!$A$5:$A$54,$A9,'分錄'!$E$5:$E$54,$C9) | H9: =SUMIFS('分錄'!K$5:K$54,'分錄'!$A$5:$A$54,$A9,'分錄'!$E$5:$E$54,$C9) | I9: =SUMIFS('分錄'!L$5:L$54,'分錄'!$A$5:$A$54,$A9,'分錄'!$E$5:$E$54,$C9) | J9: =SUMIFS('分錄'!M$5:M$54,'分錄'!$A$5:$A$54,$A9,'分錄'!$E$5:$E$54,$C9) | K9: =SUMIFS('分錄'!N$5:N$54,'分錄'!$A$5:$A$54,$A9,'分錄'!$E$5:$E$54,$C9) | L9: =SUMIFS('分錄'!O$5:O$54,'分錄'!$A$5:$A$54,$A9,'分錄'!$E$5:$E$54,$C9) | ... U9: =SUMIFS('分錄'!X$5:X$54,'分錄'!$A$5:$A$54,$A9,'分錄'!$E$5:$E$54,$C9)
A10: 內案 | B10: P/L | C10: 55110000 | D10: 承攬工程成本 | E10: =SUMIFS('分錄'!H$5:H$54,'分錄'!$A$5:$A$54,$A10,'分錄'!$E$5:$E$54,$C10) | F10: =SUMIFS('分錄'!I$5:I$54,'分錄'!$A$5:$A$54,$A10,'分錄'!$E$5:$E$54,$C10) | G10: =SUMIFS('分錄'!J$5:J$54,'分錄'!$A$5:$A$54,$A10,'分錄'!$E$5:$E$54,$C10) | H10: =SUMIFS('分錄'!K$5:K$54,'分錄'!$A$5:$A$54,$A10,'分錄'!$E$5:$E$54,$C10) | I10: =SUMIFS('分錄'!L$5:L$54,'分錄'!$A$5:$A$54,$A10,'分錄'!$E$5:$E$54,$C10) | J10: =SUMIFS('分錄'!M$5:M$54,'分錄'!$A$5:$A$54,$A10,'分錄'!$E$5:$E$54,$C10) | K10: =SUMIFS('分錄'!N$5:N$54,'分錄'!$A$5:$A$54,$A10,'分錄'!$E$5:$E$54,$C10) | L10: =SUMIFS('分錄'!O$5:O$54,'分錄'!$A$5:$A$54,$A10,'分錄'!$E$5:$E$54,$C10) | ... U10: =SUMIFS('分錄'!X$5:X$54,'分錄'!$A$5:$A$54,$A10,'分錄'!$E$5:$E$54,$C10)
A11: 內案 | B11: P/L | C11: 63810030 | D11: 工程費用轉在建工程 | E11: =SUMIFS('分錄'!H$5:H$54,'分錄'!$A$5:$A$54,$A11,'分錄'!$E$5:$E$54,$C11) | F11: =SUMIFS('分錄'!I$5:I$54,'分錄'!$A$5:$A$54,$A11,'分錄'!$E$5:$E$54,$C11) | G11: =SUMIFS('分錄'!J$5:J$54,'分錄'!$A$5:$A$54,$A11,'分錄'!$E$5:$E$54,$C11) | H11: =SUMIFS('分錄'!K$5:K$54,'分錄'!$A$5:$A$54,$A11,'分錄'!$E$5:$E$54,$C11) | I11: =SUMIFS('分錄'!L$5:L$54,'分錄'!$A$5:$A$54,$A11,'分錄'!$E$5:$E$54,$C11) | J11: =SUMIFS('分錄'!M$5:M$54,'分錄'!$A$5:$A$54,$A11,'分錄'!$E$5:$E$54,$C11) | K11: =SUMIFS('分錄'!N$5:N$54,'分錄'!$A$5:$A$54,$A11,'分錄'!$E$5:$E$54,$C11) | L11: =SUMIFS('分錄'!O$5:O$54,'分錄'!$A$5:$A$54,$A11,'分錄'!$E$5:$E$54,$C11) | ... U11: =SUMIFS('分錄'!X$5:X$54,'分錄'!$A$5:$A$54,$A11,'分錄'!$E$5:$E$54,$C11)
A12: 內案 | D12: B/S 合計 | E12: =SUMIFS(E4:E11,$B4:$B11,"B/S") | F12: =SUMIFS(F4:F11,$B4:$B11,"B/S") | G12: =SUMIFS(G4:G11,$B4:$B11,"B/S") | H12: =SUMIFS(H4:H11,$B4:$B11,"B/S") | I12: =SUMIFS(I4:I11,$B4:$B11,"B/S") | J12: =SUMIFS(J4:J11,$B4:$B11,"B/S") | K12: =SUMIFS(K4:K11,$B4:$B11,"B/S") | L12: =SUMIFS(L4:L11,$B4:$B11,"B/S") | ... U12: =SUMIFS(U4:U11,$B4:$B11,"B/S")
A13: 內案 | D13: P/L 合計（本期損益，負＝利益） | E13: =SUMIFS(E4:E11,$B4:$B11,"P/L") | F13: =SUMIFS(F4:F11,$B4:$B11,"P/L") | G13: =SUMIFS(G4:G11,$B4:$B11,"P/L") | H13: =SUMIFS(H4:H11,$B4:$B11,"P/L") | I13: =SUMIFS(I4:I11,$B4:$B11,"P/L") | J13: =SUMIFS(J4:J11,$B4:$B11,"P/L") | K13: =SUMIFS(K4:K11,$B4:$B11,"P/L") | L13: =SUMIFS(L4:L11,$B4:$B11,"P/L") | ... U13: =SUMIFS(U4:U11,$B4:$B11,"P/L")
A14: 內案 | D14: B/S＋P/L（應為0） | E14: =ROUND(E12+E13,2) | F14: =ROUND(F12+F13,2) | G14: =ROUND(G12+G13,2) | H14: =ROUND(H12+H13,2) | I14: =ROUND(I12+I13,2) | J14: =ROUND(J12+J13,2) | K14: =ROUND(K12+K13,2) | L14: =ROUND(L12+L13,2) | ... U14: =ROUND(U12+U13,2)
A16: 外案 | B16: B/S | C16: 12400000 | D16: 在建工程 | E16: =SUMIFS('分錄'!H$5:H$54,'分錄'!$A$5:$A$54,$A16,'分錄'!$E$5:$E$54,$C16) | F16: =SUMIFS('分錄'!I$5:I$54,'分錄'!$A$5:$A$54,$A16,'分錄'!$E$5:$E$54,$C16) | G16: =SUMIFS('分錄'!J$5:J$54,'分錄'!$A$5:$A$54,$A16,'分錄'!$E$5:$E$54,$C16) | H16: =SUMIFS('分錄'!K$5:K$54,'分錄'!$A$5:$A$54,$A16,'分錄'!$E$5:$E$54,$C16) | I16: =SUMIFS('分錄'!L$5:L$54,'分錄'!$A$5:$A$54,$A16,'分錄'!$E$5:$E$54,$C16) | J16: =SUMIFS('分錄'!M$5:M$54,'分錄'!$A$5:$A$54,$A16,'分錄'!$E$5:$E$54,$C16) | K16: =SUMIFS('分錄'!N$5:N$54,'分錄'!$A$5:$A$54,$A16,'分錄'!$E$5:$E$54,$C16) | L16: =SUMIFS('分錄'!O$5:O$54,'分錄'!$A$5:$A$54,$A16,'分錄'!$E$5:$E$54,$C16) | ... U16: =SUMIFS('分錄'!X$5:X$54,'分錄'!$A$5:$A$54,$A16,'分錄'!$E$5:$E$54,$C16)
A17: 外案 | B17: B/S | C17: 12470000 | D17: 在建損益-承攬案 | E17: =SUMIFS('分錄'!H$5:H$54,'分錄'!$A$5:$A$54,$A17,'分錄'!$E$5:$E$54,$C17) | F17: =SUMIFS('分錄'!I$5:I$54,'分錄'!$A$5:$A$54,$A17,'分錄'!$E$5:$E$54,$C17) | G17: =SUMIFS('分錄'!J$5:J$54,'分錄'!$A$5:$A$54,$A17,'分錄'!$E$5:$E$54,$C17) | H17: =SUMIFS('分錄'!K$5:K$54,'分錄'!$A$5:$A$54,$A17,'分錄'!$E$5:$E$54,$C17) | I17: =SUMIFS('分錄'!L$5:L$54,'分錄'!$A$5:$A$54,$A17,'分錄'!$E$5:$E$54,$C17) | J17: =SUMIFS('分錄'!M$5:M$54,'分錄'!$A$5:$A$54,$A17,'分錄'!$E$5:$E$54,$C17) | K17: =SUMIFS('分錄'!N$5:N$54,'分錄'!$A$5:$A$54,$A17,'分錄'!$E$5:$E$54,$C17) | L17: =SUMIFS('分錄'!O$5:O$54,'分錄'!$A$5:$A$54,$A17,'分錄'!$E$5:$E$54,$C17) | ... U17: =SUMIFS('分錄'!X$5:X$54,'分錄'!$A$5:$A$54,$A17,'分錄'!$E$5:$E$54,$C17)
A18: 外案 | B18: B/S | C18: 22640000 | D18: 預收工程款 | E18: =SUMIFS('分錄'!H$5:H$54,'分錄'!$A$5:$A$54,$A18,'分錄'!$E$5:$E$54,$C18) | F18: =SUMIFS('分錄'!I$5:I$54,'分錄'!$A$5:$A$54,$A18,'分錄'!$E$5:$E$54,$C18) | G18: =SUMIFS('分錄'!J$5:J$54,'分錄'!$A$5:$A$54,$A18,'分錄'!$E$5:$E$54,$C18) | H18: =SUMIFS('分錄'!K$5:K$54,'分錄'!$A$5:$A$54,$A18,'分錄'!$E$5:$E$54,$C18) | I18: =SUMIFS('分錄'!L$5:L$54,'分錄'!$A$5:$A$54,$A18,'分錄'!$E$5:$E$54,$C18) | J18: =SUMIFS('分錄'!M$5:M$54,'分錄'!$A$5:$A$54,$A18,'分錄'!$E$5:$E$54,$C18) | K18: =SUMIFS('分錄'!N$5:N$54,'分錄'!$A$5:$A$54,$A18,'分錄'!$E$5:$E$54,$C18) | L18: =SUMIFS('分錄'!O$5:O$54,'分錄'!$A$5:$A$54,$A18,'分錄'!$E$5:$E$54,$C18) | ... U18: =SUMIFS('分錄'!X$5:X$54,'分錄'!$A$5:$A$54,$A18,'分錄'!$E$5:$E$54,$C18)
A19: 外案 | B19: B/S | C19: 11430000 | D19: 應收帳款 | E19: =SUMIFS('分錄'!H$5:H$54,'分錄'!$A$5:$A$54,$A19,'分錄'!$E$5:$E$54,$C19) | F19: =SUMIFS('分錄'!I$5:I$54,'分錄'!$A$5:$A$54,$A19,'分錄'!$E$5:$E$54,$C19) | G19: =SUMIFS('分錄'!J$5:J$54,'分錄'!$A$5:$A$54,$A19,'分錄'!$E$5:$E$54,$C19) | H19: =SUMIFS('分錄'!K$5:K$54,'分錄'!$A$5:$A$54,$A19,'分錄'!$E$5:$E$54,$C19) | I19: =SUMIFS('分錄'!L$5:L$54,'分錄'!$A$5:$A$54,$A19,'分錄'!$E$5:$E$54,$C19) | J19: =SUMIFS('分錄'!M$5:M$54,'分錄'!$A$5:$A$54,$A19,'分錄'!$E$5:$E$54,$C19) | K19: =SUMIFS('分錄'!N$5:N$54,'分錄'!$A$5:$A$54,$A19,'分錄'!$E$5:$E$54,$C19) | L19: =SUMIFS('分錄'!O$5:O$54,'分錄'!$A$5:$A$54,$A19,'分錄'!$E$5:$E$54,$C19) | ... U19: =SUMIFS('分錄'!X$5:X$54,'分錄'!$A$5:$A$54,$A19,'分錄'!$E$5:$E$54,$C19)
A20: 外案 | B20: B/S | C20: 22140000 | D20: 銷項稅額 | E20: =SUMIFS('分錄'!H$5:H$54,'分錄'!$A$5:$A$54,$A20,'分錄'!$E$5:$E$54,$C20) | F20: =SUMIFS('分錄'!I$5:I$54,'分錄'!$A$5:$A$54,$A20,'分錄'!$E$5:$E$54,$C20) | G20: =SUMIFS('分錄'!J$5:J$54,'分錄'!$A$5:$A$54,$A20,'分錄'!$E$5:$E$54,$C20) | H20: =SUMIFS('分錄'!K$5:K$54,'分錄'!$A$5:$A$54,$A20,'分錄'!$E$5:$E$54,$C20) | I20: =SUMIFS('分錄'!L$5:L$54,'分錄'!$A$5:$A$54,$A20,'分錄'!$E$5:$E$54,$C20) | J20: =SUMIFS('分錄'!M$5:M$54,'分錄'!$A$5:$A$54,$A20,'分錄'!$E$5:$E$54,$C20) | K20: =SUMIFS('分錄'!N$5:N$54,'分錄'!$A$5:$A$54,$A20,'分錄'!$E$5:$E$54,$C20) | L20: =SUMIFS('分錄'!O$5:O$54,'分錄'!$A$5:$A$54,$A20,'分錄'!$E$5:$E$54,$C20) | ... U20: =SUMIFS('分錄'!X$5:X$54,'分錄'!$A$5:$A$54,$A20,'分錄'!$E$5:$E$54,$C20)
A21: 外案 | B21: B/S | D21: 負債準備-在建損失 | E21: =SUMIFS('分錄'!H$5:H$54,'分錄'!$A$5:$A$54,$A21,'分錄'!$F$5:$F$54,$D21) | F21: =SUMIFS('分錄'!I$5:I$54,'分錄'!$A$5:$A$54,$A21,'分錄'!$F$5:$F$54,$D21) | G21: =SUMIFS('分錄'!J$5:J$54,'分錄'!$A$5:$A$54,$A21,'分錄'!$F$5:$F$54,$D21) | H21: =SUMIFS('分錄'!K$5:K$54,'分錄'!$A$5:$A$54,$A21,'分錄'!$F$5:$F$54,$D21) | I21: =SUMIFS('分錄'!L$5:L$54,'分錄'!$A$5:$A$54,$A21,'分錄'!$F$5:$F$54,$D21) | J21: =SUMIFS('分錄'!M$5:M$54,'分錄'!$A$5:$A$54,$A21,'分錄'!$F$5:$F$54,$D21) | K21: =SUMIFS('分錄'!N$5:N$54,'分錄'!$A$5:$A$54,$A21,'分錄'!$F$5:$F$54,$D21) | L21: =SUMIFS('分錄'!O$5:O$54,'分錄'!$A$5:$A$54,$A21,'分錄'!$F$5:$F$54,$D21) | ... U21: =SUMIFS('分錄'!X$5:X$54,'分錄'!$A$5:$A$54,$A21,'分錄'!$F$5:$F$54,$D21)
A22: 外案 | B22: P/L | C22: 45110000 | D22: 承攬工程收入 | E22: =SUMIFS('分錄'!H$5:H$54,'分錄'!$A$5:$A$54,$A22,'分錄'!$E$5:$E$54,$C22) | F22: =SUMIFS('分錄'!I$5:I$54,'分錄'!$A$5:$A$54,$A22,'分錄'!$E$5:$E$54,$C22) | G22: =SUMIFS('分錄'!J$5:J$54,'分錄'!$A$5:$A$54,$A22,'分錄'!$E$5:$E$54,$C22) | H22: =SUMIFS('分錄'!K$5:K$54,'分錄'!$A$5:$A$54,$A22,'分錄'!$E$5:$E$54,$C22) | I22: =SUMIFS('分錄'!L$5:L$54,'分錄'!$A$5:$A$54,$A22,'分錄'!$E$5:$E$54,$C22) | J22: =SUMIFS('分錄'!M$5:M$54,'分錄'!$A$5:$A$54,$A22,'分錄'!$E$5:$E$54,$C22) | K22: =SUMIFS('分錄'!N$5:N$54,'分錄'!$A$5:$A$54,$A22,'分錄'!$E$5:$E$54,$C22) | L22: =SUMIFS('分錄'!O$5:O$54,'分錄'!$A$5:$A$54,$A22,'分錄'!$E$5:$E$54,$C22) | ... U22: =SUMIFS('分錄'!X$5:X$54,'分錄'!$A$5:$A$54,$A22,'分錄'!$E$5:$E$54,$C22)
A23: 外案 | B23: P/L | C23: 55110000 | D23: 承攬工程成本 | E23: =SUMIFS('分錄'!H$5:H$54,'分錄'!$A$5:$A$54,$A23,'分錄'!$E$5:$E$54,$C23) | F23: =SUMIFS('分錄'!I$5:I$54,'分錄'!$A$5:$A$54,$A23,'分錄'!$E$5:$E$54,$C23) | G23: =SUMIFS('分錄'!J$5:J$54,'分錄'!$A$5:$A$54,$A23,'分錄'!$E$5:$E$54,$C23) | H23: =SUMIFS('分錄'!K$5:K$54,'分錄'!$A$5:$A$54,$A23,'分錄'!$E$5:$E$54,$C23) | I23: =SUMIFS('分錄'!L$5:L$54,'分錄'!$A$5:$A$54,$A23,'分錄'!$E$5:$E$54,$C23) | J23: =SUMIFS('分錄'!M$5:M$54,'分錄'!$A$5:$A$54,$A23,'分錄'!$E$5:$E$54,$C23) | K23: =SUMIFS('分錄'!N$5:N$54,'分錄'!$A$5:$A$54,$A23,'分錄'!$E$5:$E$54,$C23) | L23: =SUMIFS('分錄'!O$5:O$54,'分錄'!$A$5:$A$54,$A23,'分錄'!$E$5:$E$54,$C23) | ... U23: =SUMIFS('分錄'!X$5:X$54,'分錄'!$A$5:$A$54,$A23,'分錄'!$E$5:$E$54,$C23)
A24: 外案 | B24: P/L | C24: 63810030 | D24: 工程費用轉在建工程 | E24: =SUMIFS('分錄'!H$5:H$54,'分錄'!$A$5:$A$54,$A24,'分錄'!$E$5:$E$54,$C24) | F24: =SUMIFS('分錄'!I$5:I$54,'分錄'!$A$5:$A$54,$A24,'分錄'!$E$5:$E$54,$C24) | G24: =SUMIFS('分錄'!J$5:J$54,'分錄'!$A$5:$A$54,$A24,'分錄'!$E$5:$E$54,$C24) | H24: =SUMIFS('分錄'!K$5:K$54,'分錄'!$A$5:$A$54,$A24,'分錄'!$E$5:$E$54,$C24) | I24: =SUMIFS('分錄'!L$5:L$54,'分錄'!$A$5:$A$54,$A24,'分錄'!$E$5:$E$54,$C24) | J24: =SUMIFS('分錄'!M$5:M$54,'分錄'!$A$5:$A$54,$A24,'分錄'!$E$5:$E$54,$C24) | K24: =SUMIFS('分錄'!N$5:N$54,'分錄'!$A$5:$A$54,$A24,'分錄'!$E$5:$E$54,$C24) | L24: =SUMIFS('分錄'!O$5:O$54,'分錄'!$A$5:$A$54,$A24,'分錄'!$E$5:$E$54,$C24) | ... U24: =SUMIFS('分錄'!X$5:X$54,'分錄'!$A$5:$A$54,$A24,'分錄'!$E$5:$E$54,$C24)
A25: 外案 | D25: B/S 合計 | E25: =SUMIFS(E16:E24,$B16:$B24,"B/S") | F25: =SUMIFS(F16:F24,$B16:$B24,"B/S") | G25: =SUMIFS(G16:G24,$B16:$B24,"B/S") | H25: =SUMIFS(H16:H24,$B16:$B24,"B/S") | I25: =SUMIFS(I16:I24,$B16:$B24,"B/S") | J25: =SUMIFS(J16:J24,$B16:$B24,"B/S") | K25: =SUMIFS(K16:K24,$B16:$B24,"B/S") | L25: =SUMIFS(L16:L24,$B16:$B24,"B/S") | ... U25: =SUMIFS(U16:U24,$B16:$B24,"B/S")
A26: 外案 | D26: P/L 合計（本期損益，負＝利益） | E26: =SUMIFS(E16:E24,$B16:$B24,"P/L") | F26: =SUMIFS(F16:F24,$B16:$B24,"P/L") | G26: =SUMIFS(G16:G24,$B16:$B24,"P/L") | H26: =SUMIFS(H16:H24,$B16:$B24,"P/L") | I26: =SUMIFS(I16:I24,$B16:$B24,"P/L") | J26: =SUMIFS(J16:J24,$B16:$B24,"P/L") | K26: =SUMIFS(K16:K24,$B16:$B24,"P/L") | L26: =SUMIFS(L16:L24,$B16:$B24,"P/L") | ... U26: =SUMIFS(U16:U24,$B16:$B24,"P/L")
A27: 外案 | D27: B/S＋P/L（應為0） | E27: =ROUND(E25+E26,2) | F27: =ROUND(F25+F26,2) | G27: =ROUND(G25+G26,2) | H27: =ROUND(H25+H26,2) | I27: =ROUND(I25+I26,2) | J27: =ROUND(J25+J26,2) | K27: =ROUND(K25+K26,2) | L27: =ROUND(L25+L26,2) | ... U27: =ROUND(U25+U26,2)
A29: 雜項 | B29: B/S | C29: 11430000 | D29: 公司內部往來-TO & BIM | E29: =SUMIFS('分錄'!H$5:H$54,'分錄'!$A$5:$A$54,$A29,'分錄'!$E$5:$E$54,$C29) | F29: =SUMIFS('分錄'!I$5:I$54,'分錄'!$A$5:$A$54,$A29,'分錄'!$E$5:$E$54,$C29) | G29: =SUMIFS('分錄'!J$5:J$54,'分錄'!$A$5:$A$54,$A29,'分錄'!$E$5:$E$54,$C29) | H29: =SUMIFS('分錄'!K$5:K$54,'分錄'!$A$5:$A$54,$A29,'分錄'!$E$5:$E$54,$C29) | I29: =SUMIFS('分錄'!L$5:L$54,'分錄'!$A$5:$A$54,$A29,'分錄'!$E$5:$E$54,$C29) | J29: =SUMIFS('分錄'!M$5:M$54,'分錄'!$A$5:$A$54,$A29,'分錄'!$E$5:$E$54,$C29) | K29: =SUMIFS('分錄'!N$5:N$54,'分錄'!$A$5:$A$54,$A29,'分錄'!$E$5:$E$54,$C29) | L29: =SUMIFS('分錄'!O$5:O$54,'分錄'!$A$5:$A$54,$A29,'分錄'!$E$5:$E$54,$C29) | ... U29: =SUMIFS('分錄'!X$5:X$54,'分錄'!$A$5:$A$54,$A29,'分錄'!$E$5:$E$54,$C29)
A30: 雜項 | B30: P/L | C30: 46110050 | D30: 勞務收入-內部計價 | E30: =SUMIFS('分錄'!H$5:H$54,'分錄'!$A$5:$A$54,$A30,'分錄'!$E$5:$E$54,$C30) | F30: =SUMIFS('分錄'!I$5:I$54,'分錄'!$A$5:$A$54,$A30,'分錄'!$E$5:$E$54,$C30) | G30: =SUMIFS('分錄'!J$5:J$54,'分錄'!$A$5:$A$54,$A30,'分錄'!$E$5:$E$54,$C30) | H30: =SUMIFS('分錄'!K$5:K$54,'分錄'!$A$5:$A$54,$A30,'分錄'!$E$5:$E$54,$C30) | I30: =SUMIFS('分錄'!L$5:L$54,'分錄'!$A$5:$A$54,$A30,'分錄'!$E$5:$E$54,$C30) | J30: =SUMIFS('分錄'!M$5:M$54,'分錄'!$A$5:$A$54,$A30,'分錄'!$E$5:$E$54,$C30) | K30: =SUMIFS('分錄'!N$5:N$54,'分錄'!$A$5:$A$54,$A30,'分錄'!$E$5:$E$54,$C30) | L30: =SUMIFS('分錄'!O$5:O$54,'分錄'!$A$5:$A$54,$A30,'分錄'!$E$5:$E$54,$C30) | ... U30: =SUMIFS('分錄'!X$5:X$54,'分錄'!$A$5:$A$54,$A30,'分錄'!$E$5:$E$54,$C30)
A31: 雜項 | B31: P/L | C31: 55/56xxxxxx | D31: 專案成本 | E31: =SUMIFS('分錄'!H$5:H$54,'分錄'!$A$5:$A$54,$A31,'分錄'!$E$5:$E$54,$C31) | F31: =SUMIFS('分錄'!I$5:I$54,'分錄'!$A$5:$A$54,$A31,'分錄'!$E$5:$E$54,$C31) | G31: =SUMIFS('分錄'!J$5:J$54,'分錄'!$A$5:$A$54,$A31,'分錄'!$E$5:$E$54,$C31) | H31: =SUMIFS('分錄'!K$5:K$54,'分錄'!$A$5:$A$54,$A31,'分錄'!$E$5:$E$54,$C31) | I31: =SUMIFS('分錄'!L$5:L$54,'分錄'!$A$5:$A$54,$A31,'分錄'!$E$5:$E$54,$C31) | J31: =SUMIFS('分錄'!M$5:M$54,'分錄'!$A$5:$A$54,$A31,'分錄'!$E$5:$E$54,$C31) | K31: =SUMIFS('分錄'!N$5:N$54,'分錄'!$A$5:$A$54,$A31,'分錄'!$E$5:$E$54,$C31) | L31: =SUMIFS('分錄'!O$5:O$54,'分錄'!$A$5:$A$54,$A31,'分錄'!$E$5:$E$54,$C31) | ... U31: =SUMIFS('分錄'!X$5:X$54,'分錄'!$A$5:$A$54,$A31,'分錄'!$E$5:$E$54,$C31)
A32: 雜項 | B32: P/L | C32: 62109999/62350099 | D32: 人事分攤／電腦out charge（合計，拆分無資料） | E32: =SUMIFS('分錄'!H$5:H$54,'分錄'!$A$5:$A$54,$A32,'分錄'!$E$5:$E$54,$C32) | F32: =SUMIFS('分錄'!I$5:I$54,'分錄'!$A$5:$A$54,$A32,'分錄'!$E$5:$E$54,$C32) | G32: =SUMIFS('分錄'!J$5:J$54,'分錄'!$A$5:$A$54,$A32,'分錄'!$E$5:$E$54,$C32) | H32: =SUMIFS('分錄'!K$5:K$54,'分錄'!$A$5:$A$54,$A32,'分錄'!$E$5:$E$54,$C32) | I32: =SUMIFS('分錄'!L$5:L$54,'分錄'!$A$5:$A$54,$A32,'分錄'!$E$5:$E$54,$C32) | J32: =SUMIFS('分錄'!M$5:M$54,'分錄'!$A$5:$A$54,$A32,'分錄'!$E$5:$E$54,$C32) | K32: =SUMIFS('分錄'!N$5:N$54,'分錄'!$A$5:$A$54,$A32,'分錄'!$E$5:$E$54,$C32) | L32: =SUMIFS('分錄'!O$5:O$54,'分錄'!$A$5:$A$54,$A32,'分錄'!$E$5:$E$54,$C32) | ... U32: =SUMIFS('分錄'!X$5:X$54,'分錄'!$A$5:$A$54,$A32,'分錄'!$E$5:$E$54,$C32)
A33: 雜項 | D33: B/S 合計 | E33: =SUMIFS(E29:E32,$B29:$B32,"B/S") | F33: =SUMIFS(F29:F32,$B29:$B32,"B/S") | G33: =SUMIFS(G29:G32,$B29:$B32,"B/S") | H33: =SUMIFS(H29:H32,$B29:$B32,"B/S") | I33: =SUMIFS(I29:I32,$B29:$B32,"B/S") | J33: =SUMIFS(J29:J32,$B29:$B32,"B/S") | K33: =SUMIFS(K29:K32,$B29:$B32,"B/S") | L33: =SUMIFS(L29:L32,$B29:$B32,"B/S") | ... U33: =SUMIFS(U29:U32,$B29:$B32,"B/S")
A34: 雜項 | D34: P/L 合計（本期損益，負＝利益） | E34: =SUMIFS(E29:E32,$B29:$B32,"P/L") | F34: =SUMIFS(F29:F32,$B29:$B32,"P/L") | G34: =SUMIFS(G29:G32,$B29:$B32,"P/L") | H34: =SUMIFS(H29:H32,$B29:$B32,"P/L") | I34: =SUMIFS(I29:I32,$B29:$B32,"P/L") | J34: =SUMIFS(J29:J32,$B29:$B32,"P/L") | K34: =SUMIFS(K29:K32,$B29:$B32,"P/L") | L34: =SUMIFS(L29:L32,$B29:$B32,"P/L") | ... U34: =SUMIFS(U29:U32,$B29:$B32,"P/L")
A35: 雜項 | D35: B/S＋P/L（應為0） | E35: =ROUND(E33+E34,2) | F35: =ROUND(F33+F34,2) | G35: =ROUND(G33+G34,2) | H35: =ROUND(H33+H34,2) | I35: =ROUND(I33+I34,2) | J35: =ROUND(J33+J34,2) | K35: =ROUND(K33+K34,2) | L35: =ROUND(L33+L34,2) | ... U35: =ROUND(U33+U34,2)
A37: 備標 | B37: B/S | C37: 11430000 | D37: 公司內部往來-TO & BIM | E37: =SUMIFS('分錄'!H$5:H$54,'分錄'!$A$5:$A$54,$A37,'分錄'!$E$5:$E$54,$C37) | F37: =SUMIFS('分錄'!I$5:I$54,'分錄'!$A$5:$A$54,$A37,'分錄'!$E$5:$E$54,$C37) | G37: =SUMIFS('分錄'!J$5:J$54,'分錄'!$A$5:$A$54,$A37,'分錄'!$E$5:$E$54,$C37) | H37: =SUMIFS('分錄'!K$5:K$54,'分錄'!$A$5:$A$54,$A37,'分錄'!$E$5:$E$54,$C37) | I37: =SUMIFS('分錄'!L$5:L$54,'分錄'!$A$5:$A$54,$A37,'分錄'!$E$5:$E$54,$C37) | J37: =SUMIFS('分錄'!M$5:M$54,'分錄'!$A$5:$A$54,$A37,'分錄'!$E$5:$E$54,$C37) | K37: =SUMIFS('分錄'!N$5:N$54,'分錄'!$A$5:$A$54,$A37,'分錄'!$E$5:$E$54,$C37) | L37: =SUMIFS('分錄'!O$5:O$54,'分錄'!$A$5:$A$54,$A37,'分錄'!$E$5:$E$54,$C37) | ... U37: =SUMIFS('分錄'!X$5:X$54,'分錄'!$A$5:$A$54,$A37,'分錄'!$E$5:$E$54,$C37)
A38: 備標 | B38: P/L | C38: 46110050 | D38: 勞務收入-內部計價 | E38: =SUMIFS('分錄'!H$5:H$54,'分錄'!$A$5:$A$54,$A38,'分錄'!$E$5:$E$54,$C38) | F38: =SUMIFS('分錄'!I$5:I$54,'分錄'!$A$5:$A$54,$A38,'分錄'!$E$5:$E$54,$C38) | G38: =SUMIFS('分錄'!J$5:J$54,'分錄'!$A$5:$A$54,$A38,'分錄'!$E$5:$E$54,$C38) | H38: =SUMIFS('分錄'!K$5:K$54,'分錄'!$A$5:$A$54,$A38,'分錄'!$E$5:$E$54,$C38) | I38: =SUMIFS('分錄'!L$5:L$54,'分錄'!$A$5:$A$54,$A38,'分錄'!$E$5:$E$54,$C38) | J38: =SUMIFS('分錄'!M$5:M$54,'分錄'!$A$5:$A$54,$A38,'分錄'!$E$5:$E$54,$C38) | K38: =SUMIFS('分錄'!N$5:N$54,'分錄'!$A$5:$A$54,$A38,'分錄'!$E$5:$E$54,$C38) | L38: =SUMIFS('分錄'!O$5:O$54,'分錄'!$A$5:$A$54,$A38,'分錄'!$E$5:$E$54,$C38) | ... U38: =SUMIFS('分錄'!X$5:X$54,'分錄'!$A$5:$A$54,$A38,'分錄'!$E$5:$E$54,$C38)
A39: 備標 | B39: P/L | C39: 55/56xxxxxx | D39: 專案成本 | E39: =SUMIFS('分錄'!H$5:H$54,'分錄'!$A$5:$A$54,$A39,'分錄'!$E$5:$E$54,$C39) | F39: =SUMIFS('分錄'!I$5:I$54,'分錄'!$A$5:$A$54,$A39,'分錄'!$E$5:$E$54,$C39) | G39: =SUMIFS('分錄'!J$5:J$54,'分錄'!$A$5:$A$54,$A39,'分錄'!$E$5:$E$54,$C39) | H39: =SUMIFS('分錄'!K$5:K$54,'分錄'!$A$5:$A$54,$A39,'分錄'!$E$5:$E$54,$C39) | I39: =SUMIFS('分錄'!L$5:L$54,'分錄'!$A$5:$A$54,$A39,'分錄'!$E$5:$E$54,$C39) | J39: =SUMIFS('分錄'!M$5:M$54,'分錄'!$A$5:$A$54,$A39,'分錄'!$E$5:$E$54,$C39) | K39: =SUMIFS('分錄'!N$5:N$54,'分錄'!$A$5:$A$54,$A39,'分錄'!$E$5:$E$54,$C39) | L39: =SUMIFS('分錄'!O$5:O$54,'分錄'!$A$5:$A$54,$A39,'分錄'!$E$5:$E$54,$C39) | ... U39: =SUMIFS('分錄'!X$5:X$54,'分錄'!$A$5:$A$54,$A39,'分錄'!$E$5:$E$54,$C39)
A40: 備標 | B40: P/L | C40: 62109999/62350099 | D40: 人事分攤／電腦out charge（合計，拆分無資料） | E40: =SUMIFS('分錄'!H$5:H$54,'分錄'!$A$5:$A$54,$A40,'分錄'!$E$5:$E$54,$C40) | F40: =SUMIFS('分錄'!I$5:I$54,'分錄'!$A$5:$A$54,$A40,'分錄'!$E$5:$E$54,$C40) | G40: =SUMIFS('分錄'!J$5:J$54,'分錄'!$A$5:$A$54,$A40,'分錄'!$E$5:$E$54,$C40) | H40: =SUMIFS('分錄'!K$5:K$54,'分錄'!$A$5:$A$54,$A40,'分錄'!$E$5:$E$54,$C40) | I40: =SUMIFS('分錄'!L$5:L$54,'分錄'!$A$5:$A$54,$A40,'分錄'!$E$5:$E$54,$C40) | J40: =SUMIFS('分錄'!M$5:M$54,'分錄'!$A$5:$A$54,$A40,'分錄'!$E$5:$E$54,$C40) | K40: =SUMIFS('分錄'!N$5:N$54,'分錄'!$A$5:$A$54,$A40,'分錄'!$E$5:$E$54,$C40) | L40: =SUMIFS('分錄'!O$5:O$54,'分錄'!$A$5:$A$54,$A40,'分錄'!$E$5:$E$54,$C40) | ... U40: =SUMIFS('分錄'!X$5:X$54,'分錄'!$A$5:$A$54,$A40,'分錄'!$E$5:$E$54,$C40)
A41: 備標 | D41: B/S 合計 | E41: =SUMIFS(E37:E40,$B37:$B40,"B/S") | F41: =SUMIFS(F37:F40,$B37:$B40,"B/S") | G41: =SUMIFS(G37:G40,$B37:$B40,"B/S") | H41: =SUMIFS(H37:H40,$B37:$B40,"B/S") | I41: =SUMIFS(I37:I40,$B37:$B40,"B/S") | J41: =SUMIFS(J37:J40,$B37:$B40,"B/S") | K41: =SUMIFS(K37:K40,$B37:$B40,"B/S") | L41: =SUMIFS(L37:L40,$B37:$B40,"B/S") | ... U41: =SUMIFS(U37:U40,$B37:$B40,"B/S")
A42: 備標 | D42: P/L 合計（本期損益，負＝利益） | E42: =SUMIFS(E37:E40,$B37:$B40,"P/L") | F42: =SUMIFS(F37:F40,$B37:$B40,"P/L") | G42: =SUMIFS(G37:G40,$B37:$B40,"P/L") | H42: =SUMIFS(H37:H40,$B37:$B40,"P/L") | I42: =SUMIFS(I37:I40,$B37:$B40,"P/L") | J42: =SUMIFS(J37:J40,$B37:$B40,"P/L") | K42: =SUMIFS(K37:K40,$B37:$B40,"P/L") | L42: =SUMIFS(L37:L40,$B37:$B40,"P/L") | ... U42: =SUMIFS(U37:U40,$B37:$B40,"P/L")
A43: 備標 | D43: B/S＋P/L（應為0） | E43: =ROUND(E41+E42,2) | F43: =ROUND(F41+F42,2) | G43: =ROUND(G41+G42,2) | H43: =ROUND(H41+H42,2) | I43: =ROUND(I41+I42,2) | J43: =ROUND(J41+J42,2) | K43: =ROUND(K41+K42,2) | L43: =ROUND(L41+L42,2) | ... U43: =ROUND(U41+U42,2)
A46: 在建・預收餘額滾算（期初＝A0/B0 累計2026/8；期末＝期初＋本表各期分錄累加）
...

Sheet 來源明細
A1: 期間 | B1: 工程代碼 | C1: 工程名稱 | D1: A0 C欄 | E1: 分類 | F1: 在建工程(A0) | G1: 在建損益(A0) | H1: 收入Total(A0) | I1: 負債準備(A0) | J1: 預收開票(B0)
A2: 累計2026/8 | B2: C/92103 | C2: CQ840 BIM | D2: 內部 | E2: 內案 | F2: 768190 | G2: 779203 | H2: 1547393 | I2: 0 | J2: 1547393
A3: 累計2026/8 | B3: C/92202 | C3: CF680C BIM | D3: 內部 | E3: 內案 | F3: 10035914 | G3: 6392086 | H3: 16428000 | I3: 0 | J3: 16428000
A4: 累計2026/8 | B4: C/92203 | C4: N－WH BIM | D4: 內部 | E4: 內案 | F4: 4815841 | G4: 3155677 | H4: 7971518 | I4: 0 | J4: 7971518
A5: 累計2026/8 | B5: C/92204 | C5: 國揚吉林機電 | D5: 內部 | E5: 內案 | F5: 1258917 | G5: 691083 | H5: 1950000 | I5: 0 | J5: 1950000
A6: 累計2026/8 | B6: C/92301 | C6: CF670A BIM 土木機電 | D6: 內部 | E6: 內案 | F6: 7934565 | G6: 3606435 | H6: 11541000 | I6: 0 | J6: 11541000
A7: 累計2026/8 | B7: C/92302 | C7: 富邦忠孝懷生BIM機電 | D7: 內部 | E7: 內案 | F7: 2941939 | G7: 673061 | H7: 3615000 | I7: 0 | J7: 3615000
A8: 累計2026/8 | B8: C/92303 | C8: 信義兒福BIM機電 | D8: 外部 | E8: 外案 | F8: 589788 | G8: -589788 | H8: 0 | I8: 0 | J8: 0
A9: 累計2026/8 | B9: C/92304 | C9: 捷運劍潭站TOD統包BIM機電 | D9: 內部 | E9: 內案 | F9: 4400912 | G9: 1064088 | H9: 5465000 | I9: 0 | J9: 5465000
A10: 累計2026/8 | B10: C/92401 | C10: CJ17 土木機電 | D10: 內部 | E10: 內案 | F10: 2185205 | G10: 4682795 | H10: 6868000 | I10: 0 | J10: 6868000
A11: 累計2026/8 | B11: C/92501 | C11: CF670 BIM土木機電 | D11: 內部 | E11: 內案 | F11: 2265868 | G11: 622882 | H11: 2888750 | I11: 0 | J11: 2888750
A12: 累計2026/8 | B12: C/92502 | C12: 擎邦-聯發科機電 | D12: 外部 | E12: 外案 | F12: 1707641 | G12: 2292359 | H12: 4000000 | I12: 0 | J12: 4000000
A13: 累計2026/8 | B13: C/92503 | C13: CF690B BIM土木 | D13: 外部 | E13: 外案 | F13: 257849 | G13: 2022151 | H13: 2280000 | I13: 0 | J13: 2280000
... A1401: 累計 Year 2031 | B1401: C/9999D | C1401: 備標BIM建築 | D1401: 備標 | E1401: 備標 | F1401: 1684733 | G1401: -389733 | H1401: 1295000 | I1401: 0 | J1401: 2015000
