Workbook

Sheet 工作表1
C1: poc | M1: 非POC
C2: 內案(POC) | H2: 外案(POC) | M2: 非POC之內案(雜項)C/99992、C/9999B | R2: 非POC之內案(備標)對象為公司業務部 C/99993、C/9999D
A3: No. | B3: 交易性質 | C3: 借/貸 | D3: 會科代號 | E3: 會科名稱 | F3: 金額 | G3: 備註 | H3: 借/貸 | I3: 會科代號 | J3: 會科名稱 | K3: 金額 | L3: 備註 | M3: 借/貸 | N3: 會科代號 | O3: 會科名稱 | P3: 金額 | Q3: 備註 | R3: 借/貸 | S3: 會科代號 | T3: 會科名稱 | U3: 金額 | V3: 備註
A4: 1 | B4: 費用入帳 | C4: Dr. | D4: 62xxxxxx | E4: 辦公室費用 | F4: =$E$79 | H4: Dr. | I4: 62xxxxxx | J4: 辦公室費用 | K4: =$E$79 | M4: Dr. | N4: 62xxxxxx | O4: 辦公室費用 | P4: =$E$79 | R4: Dr. | S4: 62xxxxxx | T4: 辦公室費用 | U4: =$E$79
C5: Dr. | D5: 12640000 | E5: 進項稅額 | F5: =F4*5% | H5: Dr. | I5: 12640000 | J5: 進項稅額 | K5: =K4*5% | M5: Dr. | N5: 12640000 | O5: 進項稅額 | P5: =P4*5% | R5: Dr. | S5: 12640000 | T5: 進項稅額 | U5: =U4*5%
C6: Cr. | D6: 21430000 | E6: 應付帳款 | F6: =-(F4+F5) | H6: Cr. | I6: 21430000 | J6: 應付帳款 | K6: =-(K4+K5) | M6: Cr. | N6: 21430000 | O6: 應付帳款 | P6: =-(P4+P5) | R6: Cr. | S6: 21430000 | T6: 應付帳款 | U6: =-(U4+U5)
A8: 2 | B8: 費用轉列成本 | C8: Dr. | D8: 63xxxxxx | E8: 工程費用 | F8: =-F9 | H8: Dr. | I8: 63xxxxxx | J8: 工程費用 | K8: =-K9 | M8: Dr. | N8: 55/56xxxxxx | O8: 專案成本 | P8: =-SUM(P9:P10) | Q8: (原作法:成本由管理費用分攤而來) | R8: Dr. | S8: 55/56xxxxxx | T8: 專案成本 | U8: =-SUM(U9:U10) | V8: (原作法:成本由管理費用分攤而來)
C9: Cr. | D9: 62xxxxxx | E9: 辦公室費用 | F9: =-F4 | H9: Cr. | I9: 62xxxxxx | J9: 辦公室費用 | K9: =-K4 | M9: Cr. | N9: 62109999 | O9: 人事分攤 | P9: -80 | R9: Cr. | S9: 62109999 | T9: 人事費用-分攤 | U9: -80
M10: Cr. | N10: 62350099 | O10: 電腦out charge | P10: -20 | R10: Cr. | S10: 62350099 | T10: 電腦費用-Out Charge | U10: -20
B12: ELIA內部沖銷 | R12: Dr. | S12: 62109999 | T12: 人事費用-分攤 | U12: =-U9 | V12: 備標沖銷
R13: Cr. | S13: 55/56xxxxxx | T13: 專案成本 | U13: =-U12 | V13: 55110099承攬工程成本-人事費
R14: Dr. | S14: 62350099 | T14: 電腦費用-Out Charge | U14: =-U10 | V14: 備標沖銷
R15: Cr. | S15: 55/56xxxxxx | T15: 專案成本 | U15: =-U14 | V15: 55110098承攬工程成本-非人事
A16: 3 | B16: 月底結轉在建 | C16: Dr. | D16: 12400000 | E16: 在建工程 | F16: =-F17 | H16: Dr. | I16: 12400000 | J16: 在建工程 | K16: =-K17
B17: (CJ88) | C17: Cr. | D17: 63810030 | E17: 工程費用轉在建工程 | F17: =-F8 | H17: Cr. | I17: 63810030 | J17: 工程費用轉在建工程 | K17: =-K8
A20: 4 | B20: 完工百分比 | C20: Dr. | D20: 55110000 | E20: 承攬工程成本 | F20: =F8 | H20: Dr. | I20: 55110000 | J20: 承攬工程成本 | K20: =K8
B21: 損益認列 | C21: Dr. | D21: 12470000 | E21: 在建損益-承攬案 | F21: =-F22-F20 | H21: Dr. | I21: 12470000 | J21: 在建損益-承攬案 | K21: =-K22-K20
C22: Cr. | D22: 45110000 | E22: 承攬工程收入 | F22: =-F20/(1-$E$77) | H22: Cr. | I22: 45110000 | J22: 承攬工程收入 | K22: =-K20/(1-$E$77)
B24: ELIA內部沖銷 | C24: Dr. | D24: 45110000 | E24: 承攬工程收入 | F24: =-F22
B25: TBU無分錄 | C25: Cr. | D25: 12470000 | E25: 在建損益-承攬案 | F25: =-F21
B26: 屬單邊沖銷 | C26: Cr. | D26: 55110000 | E26: 承攬工程成本 | F26: =-F20
C28: 此資產對全公司來說是「跟自己賺的錢」,不存在
A31: 5 | B31: 開立業主發票 | C31: Dr. | D31: 11430000 | E31: 公司內部往來-TO & BIM | F31: =$E$80 | G31: (B/S往來視為AR應收帳款) | H31: Dr. | I31: 11430000 | J31: 應收帳款 | K31: =-SUM(K32:K33) | L31: (真實應收) | M31: Dr. | N31: 11430000 | O31: 公司內部往來-TO & BIM | P31: =$E$80 | Q31: (B/S往來視為AR應收帳款) | R31: Dr. | S31: 11430000 | T31: 公司內部往來-TO & BIM | U31: =$E$80 | V31: (B/S往來視為AR應收帳款)
B32: BIM認列收入 | C32: Cr. | D32: 22640000 | E32: 預收工程款 | F32: =-F31 | H32: Cr. | I32: 22640000 | J32: 預收工程款 | K32: =-$E80 | M32: Cr. | N32: 46110050 | O32: 勞務收入-內部計價 | P32: =-P31 | R32: Cr. | S32: 46110050 | T32: 勞務收入-內部計價 | U32: =-U31
C33: Cr. | D33: 22140000 | E33: 銷項稅額 | H33: Cr. | I33: 22140000 | J33: 銷項稅額 | K33: =K32*0.05
B35: TBU認列成本 | C35: Dr. | D35: 63670100 | E35: 工程工務所費用-其他費用 | F35: =$E$80 | M35: Dr. | N35: 63670100 | O35: 工程工務所費用-其他費用 | P35: =$E$80 | R35: Dr. | S35: 62370030 | T35: 勞務費-其他 | U35: =$E$80
C36: Cr. | D36: 12872012 | E36: 公司內部往來-TO & BIM | F36: =-F35 | M36: Cr. | N36: 12872012 | O36: 公司內部往來-TO & BIM | P36: =-P35 | R36: Cr. | S36: 12872012 | T36: 公司內部往來-TO & BIM | U36: =-U35
B38: ELIA內部沖銷 | C38: Dr. | D38: 22640000 | E38: 預收工程款 | F38: =-F32 | M38: Dr. | N38: 46110050 | O38: 勞務收入-內部計價 | P38: =-P32 | R38: Dr. | S38: 46110050 | T38: 勞務收入-內部計價 | U38: =-U32
C39: Cr. | D39: 55110095 | E39: 承攬工程成本-其他 | F39: =-F38 | M39: Cr. | N39: 55110095 | O39: 承攬工程成本-其他 | P39: =-P38 | R39: Cr. | S39: 62370099 | T39: 勞務費-收回投標費 | U39: =-U38
A42: 6 | B42: 支付AP | C42: Dr. | D42: 21430000 | E42: 應付帳款 | F42: =-F6 | H42: Dr. | I42: 21430000 | J42: 應付帳款 | K42: =-K6 | M42: Dr. | N42: 21430000 | O42: 應付帳款 | P42: =-P6 | R42: Dr. | S42: 21430000 | T42: 應付帳款 | U42: =-U6
C43: Cr. | D43: 1103xxxx | E43: 銀行存款 | F43: =-F42 | H43: Cr. | I43: 1103xxxx | J43: 銀行存款 | K43: =-K42 | M43: Cr. | N43: 1103xxxx | O43: 銀行存款 | P43: =-P42 | R43: Cr. | S43: 1103xxxx | T43: 銀行存款 | U43: =-U42
A45: 7 | B45: 收取AR | C45: Dr. | D45: 1103xxxx | E45: 銀行存款 | H45: Dr. | I45: 1103xxxx | J45: 銀行存款 | K45: =-K46
C46: Cr. | D46: 11430000 | E46: 應收帳款 | H46: Cr. | I46: 11430000 | J46: 應收帳款 | K46: =-K31
A50: 期末總結 | B50: B/S | C50: 12400000 | D50: 在建工程 | E50: =SUMIF($D$4:$D$10,$C50,$F$4:$F$10)+SUMIF($D$16:$D$22,$C50,$F$16:$F$22)+SUMIF($D$31:$D$33,$C50,$F$31:$F$33)+SUMIF($D$42:$D$46,$C50,$F$42:$F$46) | F50: =SUM(E50:E52) | G50: =IF(F50>0,"應收建造合約款","應付建造合約款") | H50: 12400000 | I50: 在建工程 | J50: =SUMIF($I$4:$I$10,$H50,$K$4:$K$10)+SUMIF($I$16:$I$22,$H50,$K$16:$K$22)+SUMIF($I$31:$I$33,$H50,$K$31:$K$33)+SUMIF($I$42:$I$46,$H50,$K$42:$K$46) | K50: =SUM(J50:J52) | L50: =IF(K50>0,"應收建造合約款","應付建造合約款") | M50: 12400000 | N50: 在建工程 | O50: =SUMIF($N$4:$N$10,$M50,$P$4:$P$10)+SUMIF($N$16:$N$22,$M50,$P$16:$P$22)+SUMIF($N$31:$N$33,$M50,$P$31:$P$33)+SUMIF($N$42:$N$46,$M50,$P$42:$P$46) | P50: =SUM(O50:O52) | Q50: =IF(P50>0,"應收建造合約款","應付建造合約款") | R50: 12400000 | S50: 在建工程 | T50: =SUMIF($S$4:$S$10,$R50,$U$4:$U$10)+SUMIF($S$16:$S$22,$R50,$U$16:$U$22)+SUMIF($S$31:$S$33,$R50,$U$31:$U$33)+SUMIF($S$42:$S$46,$R50,$U$42:$U$46) | U50: =SUM(T50:T52) | V50: =IF(U50>0,"應收建造合約款","應付建造合約款")
C51: 12470000 | D51: 在建損益-承攬案 | E51: =SUMIF($D$4:$D$10,$C51,$F$4:$F$10)+SUMIF($D$16:$D$22,$C51,$F$16:$F$22)+SUMIF($D$31:$D$33,$C51,$F$31:$F$33)+SUMIF($D$42:$D$46,$C51,$F$42:$F$46) | H51: 12470000 | I51: 在建損益-承攬案 | J51: =SUMIF($I$4:$I$10,$H51,$K$4:$K$10)+SUMIF($I$16:$I$22,$H51,$K$16:$K$22)+SUMIF($I$31:$I$33,$H51,$K$31:$K$33)+SUMIF($I$42:$I$46,$H51,$K$42:$K$46) | M51: 12470000 | N51: 在建損益-承攬案 | O51: =SUMIF($N$4:$N$10,$M51,$P$4:$P$10)+SUMIF($N$16:$N$22,$M51,$P$16:$P$22)+SUMIF($N$31:$N$33,$M51,$P$31:$P$33)+SUMIF($N$42:$N$46,$M51,$P$42:$P$46) | R51: 12470000 | S51: 在建損益-承攬案 | T51: =SUMIF($S$4:$S$10,$R51,$U$4:$U$10)+SUMIF($S$16:$S$22,$R51,$U$16:$U$22)+SUMIF($S$31:$S$33,$R51,$U$31:$U$33)+SUMIF($S$42:$S$46,$R51,$U$42:$U$46)
C52: 22640000 | D52: 預收工程款 | E52: =SUMIF($D$4:$D$10,$C52,$F$4:$F$10)+SUMIF($D$16:$D$22,$C52,$F$16:$F$22)+SUMIF($D$31:$D$33,$C52,$F$31:$F$33)+SUMIF($D$42:$D$46,$C52,$F$42:$F$46) | H52: 22640000 | I52: 預收工程款 | J52: =SUMIF($I$4:$I$10,$H52,$K$4:$K$10)+SUMIF($I$16:$I$22,$H52,$K$16:$K$22)+SUMIF($I$31:$I$33,$H52,$K$31:$K$33)+SUMIF($I$42:$I$46,$H52,$K$42:$K$46) | M52: 22640000 | N52: 預收工程款 | O52: =SUMIF($N$4:$N$10,$M52,$P$4:$P$10)+SUMIF($N$16:$N$22,$M52,$P$16:$P$22)+SUMIF($N$31:$N$33,$M52,$P$31:$P$33)+SUMIF($N$42:$N$46,$M52,$P$42:$P$46) | R52: 22640000 | S52: 預收工程款 | T52: =SUMIF($S$4:$S$10,$R52,$U$4:$U$10)+SUMIF($S$16:$S$22,$R52,$U$16:$U$22)+SUMIF($S$31:$S$33,$R52,$U$31:$U$33)+SUMIF($S$42:$S$46,$R52,$U$42:$U$46)
C53: 1103xxxx | D53: 銀行存款 | E53: =SUMIF($D$4:$D$10,$C53,$F$4:$F$10)+SUMIF($D$16:$D$22,$C53,$F$16:$F$22)+SUMIF($D$31:$D$33,$C53,$F$31:$F$33)+SUMIF($D$42:$D$46,$C53,$F$42:$F$46) | F53: =E53 | G53: 銀行存款 | H53: 1103xxxx | I53: 銀行存款 | J53: =SUMIF($I$4:$I$10,$H53,$K$4:$K$10)+SUMIF($I$16:$I$22,$H53,$K$16:$K$22)+SUMIF($I$31:$I$33,$H53,$K$31:$K$33)+SUMIF($I$42:$I$46,$H53,$K$42:$K$46) | K53: =J53 | L53: 銀行存款 | M53: 1103xxxx | N53: 銀行存款 | O53: =SUMIF($N$4:$N$10,$M53,$P$4:$P$10)+SUMIF($N$16:$N$22,$M53,$P$16:$P$22)+SUMIF($N$31:$N$33,$M53,$P$31:$P$33)+SUMIF($N$42:$N$46,$M53,$P$42:$P$46) | P53: =O53 | Q53: 銀行存款 | R53: 1103xxxx | S53: 銀行存款 | T53: =SUMIF($S$4:$S$10,$R53,$U$4:$U$10)+SUMIF($S$16:$S$22,$R53,$U$16:$U$22)+SUMIF($S$31:$S$33,$R53,$U$31:$U$33)+SUMIF($S$42:$S$46,$R53,$U$42:$U$46) | U53: =T53 | V53: 銀行存款
C54: 11430000 | D54: 應收帳款 | E54: =SUMIF($D$4:$D$10,$C54,$F$4:$F$10)+SUMIF($D$16:$D$22,$C54,$F$16:$F$22)+SUMIF($D$31:$D$33,$C54,$F$31:$F$33)+SUMIF($D$42:$D$46,$C54,$F$42:$F$46) | F54: =E54 | G54: 應收帳款 | H54: 11430000 | I54: 應收帳款 | J54: =SUMIF($I$4:$I$10,$H54,$K$4:$K$10)+SUMIF($I$16:$I$22,$H54,$K$16:$K$22)+SUMIF($I$31:$I$33,$H54,$K$31:$K$33)+SUMIF($I$42:$I$46,$H54,$K$42:$K$46) | K54: =J54 | L54: 應收帳款 | M54: 11430000 | N54: 應收帳款 | O54: =SUMIF($N$4:$N$10,$M54,$P$4:$P$10)+SUMIF($N$16:$N$22,$M54,$P$16:$P$22)+SUMIF($N$31:$N$33,$M54,$P$31:$P$33)+SUMIF($N$42:$N$46,$M54,$P$42:$P$46) | P54: =O54 | Q54: 應收帳款 | R54: 11430000 | S54: 應收帳款 | T54: =SUMIF($S$4:$S$10,$R54,$U$4:$U$10)+SUMIF($S$16:$S$22,$R54,$U$16:$U$22)+SUMIF($S$31:$S$33,$R54,$U$31:$U$33)+SUMIF($S$42:$S$46,$R54,$U$42:$U$46) | U54: =T54 | V54: 應收帳款
C55: 21430000 | D55: 應付帳款 | E55: =SUMIF($D$4:$D$10,$C55,$F$4:$F$10)+SUMIF($D$16:$D$22,$C55,$F$16:$F$22)+SUMIF($D$31:$D$33,$C55,$F$31:$F$33)+SUMIF($D$42:$D$46,$C55,$F$42:$F$46) | F55: =E55 | G55: 應付帳款 | H55: 21430000 | I55: 應付帳款 | J55: =SUMIF($I$4:$I$10,$H55,$K$4:$K$10)+SUMIF($I$16:$I$22,$H55,$K$16:$K$22)+SUMIF($I$31:$I$33,$H55,$K$31:$K$33)+SUMIF($I$42:$I$46,$H55,$K$42:$K$46) | K55: =J55 | L55: 應付帳款 | M55: 21430000 | N55: 應付帳款 | O55: =SUMIF($N$4:$N$10,$M55,$P$4:$P$10)+SUMIF($N$16:$N$22,$M55,$P$16:$P$22)+SUMIF($N$31:$N$33,$M55,$P$31:$P$33)+SUMIF($N$42:$N$46,$M55,$P$42:$P$46) | P55: =O55 | Q55: 應付帳款 | R55: 21430000 | S55: 應付帳款 | T55: =SUMIF($S$4:$S$10,$R55,$U$4:$U$10)+SUMIF($S$16:$S$22,$R55,$U$16:$U$22)+SUMIF($S$31:$S$33,$R55,$U$31:$U$33)+SUMIF($S$42:$S$46,$R55,$U$42:$U$46) | U55: =T55 | V55: 應付帳款
C56: 12640000 | D56: 進項稅額 | E56: =SUMIF($D$4:$D$10,$C56,$F$4:$F$10)+SUMIF($D$16:$D$22,$C56,$F$16:$F$22)+SUMIF($D$31:$D$33,$C56,$F$31:$F$33)+SUMIF($D$42:$D$46,$C56,$F$42:$F$46) | F56: =E56 | G56: 進項稅額 | H56: 12640000 | I56: 進項稅額 | J56: =SUMIF($I$4:$I$10,$H56,$K$4:$K$10)+SUMIF($I$16:$I$22,$H56,$K$16:$K$22)+SUMIF($I$31:$I$33,$H56,$K$31:$K$33)+SUMIF($I$42:$I$46,$H56,$K$42:$K$46) | K56: =J56 | L56: 進項稅額 | M56: 12640000 | N56: 進項稅額 | O56: =SUMIF($N$4:$N$10,$M56,$P$4:$P$10)+SUMIF($N$16:$N$22,$M56,$P$16:$P$22)+SUMIF($N$31:$N$33,$M56,$P$31:$P$33)+SUMIF($N$42:$N$46,$M56,$P$42:$P$46) | P56: =O56 | Q56: 進項稅額 | R56: 12640000 | S56: 進項稅額 | T56: =SUMIF($S$4:$S$10,$R56,$U$4:$U$10)+SUMIF($S$16:$S$22,$R56,$U$16:$U$22)+SUMIF($S$31:$S$33,$R56,$U$31:$U$33)+SUMIF($S$42:$S$46,$R56,$U$42:$U$46) | U56: =T56 | V56: 進項稅額
...

Sheet 檢核
A1: A. 每筆分錄借貸差（應為0） | G1: 輔助：主表每列（非BIM列記為空）
A2: 分錄 | B2: 內案POC | C2: 外案POC | D2: 雜項 | E2: 備標
A3: 1 費用入帳（第4-6列） | B3: =ROUND(SUM('工作表1'!F4:F6),6) | C3: =ROUND(SUM('工作表1'!K4:K6),6) | D3: =ROUND(SUM('工作表1'!P4:P6),6) | E3: =ROUND(SUM('工作表1'!U4:U6),6) | H3: 內案POC類別 | I3: 內案POC金額 | J3: 內案POC未入總結 | K3: 外案POC類別 | L3: 外案POC金額 | M3: 外案POC未入總結 | N3: 雜項類別 | O3: 雜項金額 | P3: 雜項未入總結 | Q3: 備標類別 | R3: 備標金額 | S3: 備標未入總結
A4: 2 費用轉列成本（第8-10列） | B4: =ROUND(SUM('工作表1'!F8:F10),6) | C4: =ROUND(SUM('工作表1'!K8:K10),6) | D4: =ROUND(SUM('工作表1'!P8:P10),6) | E4: =ROUND(SUM('工作表1'!U8:U10),6) | H4: =IF('工作表1'!D4="","",LEFT('工作表1'!D4,1)) | I4: =IF(ISNUMBER('工作表1'!F4),'工作表1'!F4,0) | J4: =IF('工作表1'!D4="",0,IF(COUNTIF('工作表1'!$C$50:$C$68,'工作表1'!D4)>0,0,1)) | K4: =IF('工作表1'!I4="","",LEFT('工作表1'!I4,1)) | L4: =IF(ISNUMBER('工作表1'!K4),'工作表1'!K4,0) | M4: =IF('工作表1'!I4="",0,IF(COUNTIF('工作表1'!$H$50:$H$68,'工作表1'!I4)>0,0,1)) | N4: =IF('工作表1'!N4="","",LEFT('工作表1'!N4,1)) | O4: =IF(ISNUMBER('工作表1'!P4),'工作表1'!P4,0) | P4: =IF('工作表1'!N4="",0,IF(COUNTIF('工作表1'!$M$50:$M$68,'工作表1'!N4)>0,0,1)) | Q4: =IF('工作表1'!S4="","",LEFT('工作表1'!S4,1)) | R4: =IF(ISNUMBER('工作表1'!U4),'工作表1'!U4,0) | S4: =IF('工作表1'!S4="",0,IF(COUNTIF('工作表1'!$R$50:$R$68,'工作表1'!S4)>0,0,1))
A5: 2 ELIA(備標)（第12-15列） | B5: =ROUND(SUM('工作表1'!F12:F15),6) | C5: =ROUND(SUM('工作表1'!K12:K15),6) | D5: =ROUND(SUM('工作表1'!P12:P15),6) | E5: =ROUND(SUM('工作表1'!U12:U15),6) | H5: =IF('工作表1'!D5="","",LEFT('工作表1'!D5,1)) | I5: =IF(ISNUMBER('工作表1'!F5),'工作表1'!F5,0) | J5: =IF('工作表1'!D5="",0,IF(COUNTIF('工作表1'!$C$50:$C$68,'工作表1'!D5)>0,0,1)) | K5: =IF('工作表1'!I5="","",LEFT('工作表1'!I5,1)) | L5: =IF(ISNUMBER('工作表1'!K5),'工作表1'!K5,0) | M5: =IF('工作表1'!I5="",0,IF(COUNTIF('工作表1'!$H$50:$H$68,'工作表1'!I5)>0,0,1)) | N5: =IF('工作表1'!N5="","",LEFT('工作表1'!N5,1)) | O5: =IF(ISNUMBER('工作表1'!P5),'工作表1'!P5,0) | P5: =IF('工作表1'!N5="",0,IF(COUNTIF('工作表1'!$M$50:$M$68,'工作表1'!N5)>0,0,1)) | Q5: =IF('工作表1'!S5="","",LEFT('工作表1'!S5,1)) | R5: =IF(ISNUMBER('工作表1'!U5),'工作表1'!U5,0) | S5: =IF('工作表1'!S5="",0,IF(COUNTIF('工作表1'!$R$50:$R$68,'工作表1'!S5)>0,0,1))
A6: 3 月底結轉在建（第16-17列） | B6: =ROUND(SUM('工作表1'!F16:F17),6) | C6: =ROUND(SUM('工作表1'!K16:K17),6) | D6: =ROUND(SUM('工作表1'!P16:P17),6) | E6: =ROUND(SUM('工作表1'!U16:U17),6) | H6: =IF('工作表1'!D6="","",LEFT('工作表1'!D6,1)) | I6: =IF(ISNUMBER('工作表1'!F6),'工作表1'!F6,0) | J6: =IF('工作表1'!D6="",0,IF(COUNTIF('工作表1'!$C$50:$C$68,'工作表1'!D6)>0,0,1)) | K6: =IF('工作表1'!I6="","",LEFT('工作表1'!I6,1)) | L6: =IF(ISNUMBER('工作表1'!K6),'工作表1'!K6,0) | M6: =IF('工作表1'!I6="",0,IF(COUNTIF('工作表1'!$H$50:$H$68,'工作表1'!I6)>0,0,1)) | N6: =IF('工作表1'!N6="","",LEFT('工作表1'!N6,1)) | O6: =IF(ISNUMBER('工作表1'!P6),'工作表1'!P6,0) | P6: =IF('工作表1'!N6="",0,IF(COUNTIF('工作表1'!$M$50:$M$68,'工作表1'!N6)>0,0,1)) | Q6: =IF('工作表1'!S6="","",LEFT('工作表1'!S6,1)) | R6: =IF(ISNUMBER('工作表1'!U6),'工作表1'!U6,0) | S6: =IF('工作表1'!S6="",0,IF(COUNTIF('工作表1'!$R$50:$R$68,'工作表1'!S6)>0,0,1))
A7: 4 完工百分比認列（第20-22列） | B7: =ROUND(SUM('工作表1'!F20:F22),6) | C7: =ROUND(SUM('工作表1'!K20:K22),6) | D7: =ROUND(SUM('工作表1'!P20:P22),6) | E7: =ROUND(SUM('工作表1'!U20:U22),6) | H7: =IF('工作表1'!D7="","",LEFT('工作表1'!D7,1)) | I7: =IF(ISNUMBER('工作表1'!F7),'工作表1'!F7,0) | J7: =IF('工作表1'!D7="",0,IF(COUNTIF('工作表1'!$C$50:$C$68,'工作表1'!D7)>0,0,1)) | K7: =IF('工作表1'!I7="","",LEFT('工作表1'!I7,1)) | L7: =IF(ISNUMBER('工作表1'!K7),'工作表1'!K7,0) | M7: =IF('工作表1'!I7="",0,IF(COUNTIF('工作表1'!$H$50:$H$68,'工作表1'!I7)>0,0,1)) | N7: =IF('工作表1'!N7="","",LEFT('工作表1'!N7,1)) | O7: =IF(ISNUMBER('工作表1'!P7),'工作表1'!P7,0) | P7: =IF('工作表1'!N7="",0,IF(COUNTIF('工作表1'!$M$50:$M$68,'工作表1'!N7)>0,0,1)) | Q7: =IF('工作表1'!S7="","",LEFT('工作表1'!S7,1)) | R7: =IF(ISNUMBER('工作表1'!U7),'工作表1'!U7,0) | S7: =IF('工作表1'!S7="",0,IF(COUNTIF('工作表1'!$R$50:$R$68,'工作表1'!S7)>0,0,1))
A8: 4 ELIA（第24-26列） | B8: =ROUND(SUM('工作表1'!F24:F26),6) | C8: =ROUND(SUM('工作表1'!K24:K26),6) | D8: =ROUND(SUM('工作表1'!P24:P26),6) | E8: =ROUND(SUM('工作表1'!U24:U26),6) | H8: =IF('工作表1'!D8="","",LEFT('工作表1'!D8,1)) | I8: =IF(ISNUMBER('工作表1'!F8),'工作表1'!F8,0) | J8: =IF('工作表1'!D8="",0,IF(COUNTIF('工作表1'!$C$50:$C$68,'工作表1'!D8)>0,0,1)) | K8: =IF('工作表1'!I8="","",LEFT('工作表1'!I8,1)) | L8: =IF(ISNUMBER('工作表1'!K8),'工作表1'!K8,0) | M8: =IF('工作表1'!I8="",0,IF(COUNTIF('工作表1'!$H$50:$H$68,'工作表1'!I8)>0,0,1)) | N8: =IF('工作表1'!N8="","",LEFT('工作表1'!N8,1)) | O8: =IF(ISNUMBER('工作表1'!P8),'工作表1'!P8,0) | P8: =IF('工作表1'!N8="",0,IF(COUNTIF('工作表1'!$M$50:$M$68,'工作表1'!N8)>0,0,1)) | Q8: =IF('工作表1'!S8="","",LEFT('工作表1'!S8,1)) | R8: =IF(ISNUMBER('工作表1'!U8),'工作表1'!U8,0) | S8: =IF('工作表1'!S8="",0,IF(COUNTIF('工作表1'!$R$50:$R$68,'工作表1'!S8)>0,0,1))
A9: 5 開立發票（第31-33列） | B9: =ROUND(SUM('工作表1'!F31:F33),6) | C9: =ROUND(SUM('工作表1'!K31:K33),6) | D9: =ROUND(SUM('工作表1'!P31:P33),6) | E9: =ROUND(SUM('工作表1'!U31:U33),6) | H9: =IF('工作表1'!D9="","",LEFT('工作表1'!D9,1)) | I9: =IF(ISNUMBER('工作表1'!F9),'工作表1'!F9,0) | J9: =IF('工作表1'!D9="",0,IF(COUNTIF('工作表1'!$C$50:$C$68,'工作表1'!D9)>0,0,1)) | K9: =IF('工作表1'!I9="","",LEFT('工作表1'!I9,1)) | L9: =IF(ISNUMBER('工作表1'!K9),'工作表1'!K9,0) | M9: =IF('工作表1'!I9="",0,IF(COUNTIF('工作表1'!$H$50:$H$68,'工作表1'!I9)>0,0,1)) | N9: =IF('工作表1'!N9="","",LEFT('工作表1'!N9,1)) | O9: =IF(ISNUMBER('工作表1'!P9),'工作表1'!P9,0) | P9: =IF('工作表1'!N9="",0,IF(COUNTIF('工作表1'!$M$50:$M$68,'工作表1'!N9)>0,0,1)) | Q9: =IF('工作表1'!S9="","",LEFT('工作表1'!S9,1)) | R9: =IF(ISNUMBER('工作表1'!U9),'工作表1'!U9,0) | S9: =IF('工作表1'!S9="",0,IF(COUNTIF('工作表1'!$R$50:$R$68,'工作表1'!S9)>0,0,1))
A10: 5 TBU認列成本（第35-36列） | B10: =ROUND(SUM('工作表1'!F35:F36),6) | C10: =ROUND(SUM('工作表1'!K35:K36),6) | D10: =ROUND(SUM('工作表1'!P35:P36),6) | E10: =ROUND(SUM('工作表1'!U35:U36),6) | H10: =IF('工作表1'!D10="","",LEFT('工作表1'!D10,1)) | I10: =IF(ISNUMBER('工作表1'!F10),'工作表1'!F10,0) | J10: =IF('工作表1'!D10="",0,IF(COUNTIF('工作表1'!$C$50:$C$68,'工作表1'!D10)>0,0,1)) | K10: =IF('工作表1'!I10="","",LEFT('工作表1'!I10,1)) | L10: =IF(ISNUMBER('工作表1'!K10),'工作表1'!K10,0) | M10: =IF('工作表1'!I10="",0,IF(COUNTIF('工作表1'!$H$50:$H$68,'工作表1'!I10)>0,0,1)) | N10: =IF('工作表1'!N10="","",LEFT('工作表1'!N10,1)) | O10: =IF(ISNUMBER('工作表1'!P10),'工作表1'!P10,0) | P10: =IF('工作表1'!N10="",0,IF(COUNTIF('工作表1'!$M$50:$M$68,'工作表1'!N10)>0,0,1)) | Q10: =IF('工作表1'!S10="","",LEFT('工作表1'!S10,1)) | R10: =IF(ISNUMBER('工作表1'!U10),'工作表1'!U10,0) | S10: =IF('工作表1'!S10="",0,IF(COUNTIF('工作表1'!$R$50:$R$68,'工作表1'!S10)>0,0,1))
A11: 5 ELIA（第38-39列） | B11: =ROUND(SUM('工作表1'!F38:F39),6) | C11: =ROUND(SUM('工作表1'!K38:K39),6) | D11: =ROUND(SUM('工作表1'!P38:P39),6) | E11: =ROUND(SUM('工作表1'!U38:U39),6) | I11: 0 | J11: 0 | L11: 0 | M11: 0 | O11: 0 | P11: 0 | R11: 0 | S11: 0
A12: 6 支付AP（第42-43列） | B12: =ROUND(SUM('工作表1'!F42:F43),6) | C12: =ROUND(SUM('工作表1'!K42:K43),6) | D12: =ROUND(SUM('工作表1'!P42:P43),6) | E12: =ROUND(SUM('工作表1'!U42:U43),6) | I12: 0 | J12: 0 | L12: 0 | M12: 0 | O12: 0 | P12: 0 | R12: 0 | S12: 0
A13: 7 收取AR（第45-46列） | B13: =ROUND(SUM('工作表1'!F45:F46),6) | C13: =ROUND(SUM('工作表1'!K45:K46),6) | D13: =ROUND(SUM('工作表1'!P45:P46),6) | E13: =ROUND(SUM('工作表1'!U45:U46),6) | I13: 0 | J13: 0 | L13: 0 | M13: 0 | O13: 0 | P13: 0 | R13: 0 | S13: 0
A14: A 結果 | B14: =IF(SUMPRODUCT(ABS(B3:B13))<0.000001,"OK","不平") | C14: =IF(SUMPRODUCT(ABS(C3:C13))<0.000001,"OK","不平") | D14: =IF(SUMPRODUCT(ABS(D3:D13))<0.000001,"OK","不平") | E14: =IF(SUMPRODUCT(ABS(E3:E13))<0.000001,"OK","不平") | I14: 0 | J14: 0 | L14: 0 | M14: 0 | O14: 0 | P14: 0 | R14: 0 | S14: 0
I15: 0 | J15: 0 | L15: 0 | M15: 0 | O15: 0 | P15: 0 | R15: 0 | S15: 0
A16: B. 期末總結 vs BIM分錄直接加總（只計BIM列；代號首碼1/2=B/S，4/5/6=P/L） | H16: =IF('工作表1'!D16="","",LEFT('工作表1'!D16,1)) | I16: =IF(ISNUMBER('工作表1'!F16),'工作表1'!F16,0) | J16: =IF('工作表1'!D16="",0,IF(COUNTIF('工作表1'!$C$50:$C$68,'工作表1'!D16)>0,0,1)) | K16: =IF('工作表1'!I16="","",LEFT('工作表1'!I16,1)) | L16: =IF(ISNUMBER('工作表1'!K16),'工作表1'!K16,0) | M16: =IF('工作表1'!I16="",0,IF(COUNTIF('工作表1'!$H$50:$H$68,'工作表1'!I16)>0,0,1)) | N16: =IF('工作表1'!N16="","",LEFT('工作表1'!N16,1)) | O16: =IF(ISNUMBER('工作表1'!P16),'工作表1'!P16,0) | P16: =IF('工作表1'!N16="",0,IF(COUNTIF('工作表1'!$M$50:$M$68,'工作表1'!N16)>0,0,1)) | Q16: =IF('工作表1'!S16="","",LEFT('工作表1'!S16,1)) | R16: =IF(ISNUMBER('工作表1'!U16),'工作表1'!U16,0) | S16: =IF('工作表1'!S16="",0,IF(COUNTIF('工作表1'!$R$50:$R$68,'工作表1'!S16)>0,0,1))
A17: 項目 | B17: 內案POC | C17: 外案POC | D17: 雜項 | E17: 備標 | H17: =IF('工作表1'!D17="","",LEFT('工作表1'!D17,1)) | I17: =IF(ISNUMBER('工作表1'!F17),'工作表1'!F17,0) | J17: =IF('工作表1'!D17="",0,IF(COUNTIF('工作表1'!$C$50:$C$68,'工作表1'!D17)>0,0,1)) | K17: =IF('工作表1'!I17="","",LEFT('工作表1'!I17,1)) | L17: =IF(ISNUMBER('工作表1'!K17),'工作表1'!K17,0) | M17: =IF('工作表1'!I17="",0,IF(COUNTIF('工作表1'!$H$50:$H$68,'工作表1'!I17)>0,0,1)) | N17: =IF('工作表1'!N17="","",LEFT('工作表1'!N17,1)) | O17: =IF(ISNUMBER('工作表1'!P17),'工作表1'!P17,0) | P17: =IF('工作表1'!N17="",0,IF(COUNTIF('工作表1'!$M$50:$M$68,'工作表1'!N17)>0,0,1)) | Q17: =IF('工作表1'!S17="","",LEFT('工作表1'!S17,1)) | R17: =IF(ISNUMBER('工作表1'!U17),'工作表1'!U17,0) | S17: =IF('工作表1'!S17="",0,IF(COUNTIF('工作表1'!$R$50:$R$68,'工作表1'!S17)>0,0,1))
A18: B/S 分錄加總 | B18: =SUMIF($H$4:$H$47,"1",$I$4:$I$47)+SUMIF($H$4:$H$47,"2",$I$4:$I$47) | C18: =SUMIF($K$4:$K$47,"1",$L$4:$L$47)+SUMIF($K$4:$K$47,"2",$L$4:$L$47) | D18: =SUMIF($N$4:$N$47,"1",$O$4:$O$47)+SUMIF($N$4:$N$47,"2",$O$4:$O$47) | E18: =SUMIF($Q$4:$Q$47,"1",$R$4:$R$47)+SUMIF($Q$4:$Q$47,"2",$R$4:$R$47) | H18: =IF('工作表1'!D18="","",LEFT('工作表1'!D18,1)) | I18: =IF(ISNUMBER('工作表1'!F18),'工作表1'!F18,0) | J18: =IF('工作表1'!D18="",0,IF(COUNTIF('工作表1'!$C$50:$C$68,'工作表1'!D18)>0,0,1)) | K18: =IF('工作表1'!I18="","",LEFT('工作表1'!I18,1)) | L18: =IF(ISNUMBER('工作表1'!K18),'工作表1'!K18,0) | M18: =IF('工作表1'!I18="",0,IF(COUNTIF('工作表1'!$H$50:$H$68,'工作表1'!I18)>0,0,1)) | N18: =IF('工作表1'!N18="","",LEFT('工作表1'!N18,1)) | O18: =IF(ISNUMBER('工作表1'!P18),'工作表1'!P18,0) | P18: =IF('工作表1'!N18="",0,IF(COUNTIF('工作表1'!$M$50:$M$68,'工作表1'!N18)>0,0,1)) | Q18: =IF('工作表1'!S18="","",LEFT('工作表1'!S18,1)) | R18: =IF(ISNUMBER('工作表1'!U18),'工作表1'!U18,0) | S18: =IF('工作表1'!S18="",0,IF(COUNTIF('工作表1'!$R$50:$R$68,'工作表1'!S18)>0,0,1))
A19: B/S 期末總結(總計欄50+53:57) | B19: ='工作表1'!F50+SUM('工作表1'!F53:F57) | C19: ='工作表1'!K50+SUM('工作表1'!K53:K57) | D19: ='工作表1'!P50+SUM('工作表1'!P53:P57) | E19: ='工作表1'!U50+SUM('工作表1'!U53:U57) | H19: =IF('工作表1'!D19="","",LEFT('工作表1'!D19,1)) | I19: =IF(ISNUMBER('工作表1'!F19),'工作表1'!F19,0) | J19: =IF('工作表1'!D19="",0,IF(COUNTIF('工作表1'!$C$50:$C$68,'工作表1'!D19)>0,0,1)) | K19: =IF('工作表1'!I19="","",LEFT('工作表1'!I19,1)) | L19: =IF(ISNUMBER('工作表1'!K19),'工作表1'!K19,0) | M19: =IF('工作表1'!I19="",0,IF(COUNTIF('工作表1'!$H$50:$H$68,'工作表1'!I19)>0,0,1)) | N19: =IF('工作表1'!N19="","",LEFT('工作表1'!N19,1)) | O19: =IF(ISNUMBER('工作表1'!P19),'工作表1'!P19,0) | P19: =IF('工作表1'!N19="",0,IF(COUNTIF('工作表1'!$M$50:$M$68,'工作表1'!N19)>0,0,1)) | Q19: =IF('工作表1'!S19="","",LEFT('工作表1'!S19,1)) | R19: =IF(ISNUMBER('工作表1'!U19),'工作表1'!U19,0) | S19: =IF('工作表1'!S19="",0,IF(COUNTIF('工作表1'!$R$50:$R$68,'工作表1'!S19)>0,0,1))
A20: P/L 分錄加總 | B20: =SUMIF($H$4:$H$47,"4",$I$4:$I$47)+SUMIF($H$4:$H$47,"5",$I$4:$I$47)+SUMIF($H$4:$H$47,"6",$I$4:$I$47) | C20: =SUMIF($K$4:$K$47,"4",$L$4:$L$47)+SUMIF($K$4:$K$47,"5",$L$4:$L$47)+SUMIF($K$4:$K$47,"6",$L$4:$L$47) | D20: =SUMIF($N$4:$N$47,"4",$O$4:$O$47)+SUMIF($N$4:$N$47,"5",$O$4:$O$47)+SUMIF($N$4:$N$47,"6",$O$4:$O$47) | E20: =SUMIF($Q$4:$Q$47,"4",$R$4:$R$47)+SUMIF($Q$4:$Q$47,"5",$R$4:$R$47)+SUMIF($Q$4:$Q$47,"6",$R$4:$R$47) | H20: =IF('工作表1'!D20="","",LEFT('工作表1'!D20,1)) | I20: =IF(ISNUMBER('工作表1'!F20),'工作表1'!F20,0) | J20: =IF('工作表1'!D20="",0,IF(COUNTIF('工作表1'!$C$50:$C$68,'工作表1'!D20)>0,0,1)) | K20: =IF('工作表1'!I20="","",LEFT('工作表1'!I20,1)) | L20: =IF(ISNUMBER('工作表1'!K20),'工作表1'!K20,0) | M20: =IF('工作表1'!I20="",0,IF(COUNTIF('工作表1'!$H$50:$H$68,'工作表1'!I20)>0,0,1)) | N20: =IF('工作表1'!N20="","",LEFT('工作表1'!N20,1)) | O20: =IF(ISNUMBER('工作表1'!P20),'工作表1'!P20,0) | P20: =IF('工作表1'!N20="",0,IF(COUNTIF('工作表1'!$M$50:$M$68,'工作表1'!N20)>0,0,1)) | Q20: =IF('工作表1'!S20="","",LEFT('工作表1'!S20,1)) | R20: =IF(ISNUMBER('工作表1'!U20),'工作表1'!U20,0) | S20: =IF('工作表1'!S20="",0,IF(COUNTIF('工作表1'!$R$50:$R$68,'工作表1'!S20)>0,0,1))
A21: P/L 期末總結(總計欄58) | B21: ='工作表1'!F58 | C21: ='工作表1'!K58 | D21: ='工作表1'!P58 | E21: ='工作表1'!U58 | H21: =IF('工作表1'!D21="","",LEFT('工作表1'!D21,1)) | I21: =IF(ISNUMBER('工作表1'!F21),'工作表1'!F21,0) | J21: =IF('工作表1'!D21="",0,IF(COUNTIF('工作表1'!$C$50:$C$68,'工作表1'!D21)>0,0,1)) | K21: =IF('工作表1'!I21="","",LEFT('工作表1'!I21,1)) | L21: =IF(ISNUMBER('工作表1'!K21),'工作表1'!K21,0) | M21: =IF('工作表1'!I21="",0,IF(COUNTIF('工作表1'!$H$50:$H$68,'工作表1'!I21)>0,0,1)) | N21: =IF('工作表1'!N21="","",LEFT('工作表1'!N21,1)) | O21: =IF(ISNUMBER('工作表1'!P21),'工作表1'!P21,0) | P21: =IF('工作表1'!N21="",0,IF(COUNTIF('工作表1'!$M$50:$M$68,'工作表1'!N21)>0,0,1)) | Q21: =IF('工作表1'!S21="","",LEFT('工作表1'!S21,1)) | R21: =IF(ISNUMBER('工作表1'!U21),'工作表1'!U21,0) | S21: =IF('工作表1'!S21="",0,IF(COUNTIF('工作表1'!$R$50:$R$68,'工作表1'!S21)>0,0,1))
A22: B/S 差異 | B22: =B19-B18 | C22: =C19-C18 | D22: =D19-D18 | E22: =E19-E18 | H22: =IF('工作表1'!D22="","",LEFT('工作表1'!D22,1)) | I22: =IF(ISNUMBER('工作表1'!F22),'工作表1'!F22,0) | J22: =IF('工作表1'!D22="",0,IF(COUNTIF('工作表1'!$C$50:$C$68,'工作表1'!D22)>0,0,1)) | K22: =IF('工作表1'!I22="","",LEFT('工作表1'!I22,1)) | L22: =IF(ISNUMBER('工作表1'!K22),'工作表1'!K22,0) | M22: =IF('工作表1'!I22="",0,IF(COUNTIF('工作表1'!$H$50:$H$68,'工作表1'!I22)>0,0,1)) | N22: =IF('工作表1'!N22="","",LEFT('工作表1'!N22,1)) | O22: =IF(ISNUMBER('工作表1'!P22),'工作表1'!P22,0) | P22: =IF('工作表1'!N22="",0,IF(COUNTIF('工作表1'!$M$50:$M$68,'工作表1'!N22)>0,0,1)) | Q22: =IF('工作表1'!S22="","",LEFT('工作表1'!S22,1)) | R22: =IF(ISNUMBER('工作表1'!U22),'工作表1'!U22,0) | S22: =IF('工作表1'!S22="",0,IF(COUNTIF('工作表1'!$R$50:$R$68,'工作表1'!S22)>0,0,1))
A23: P/L 差異 | B23: =B21-B20 | C23: =C21-C20 | D23: =D21-D20 | E23: =E21-E20 | I23: 0 | J23: 0 | L23: 0 | M23: 0 | O23: 0 | P23: 0 | R23: 0 | S23: 0
A24: B/S+P/L(應為0) | B24: =B19+B21 | C24: =C19+C21 | D24: =D19+D21 | E24: =E19+E21 | I24: 0 | J24: 0 | L24: 0 | M24: 0 | O24: 0 | P24: 0 | R24: 0 | S24: 0
A25: B 結果 | B25: =IF(AND(ABS(B22)<0.000001,ABS(B23)<0.000001,ABS(B24)<0.000001),"OK","不符") | C25: =IF(AND(ABS(C22)<0.000001,ABS(C23)<0.000001,ABS(C24)<0.000001),"OK","不符") | D25: =IF(AND(ABS(D22)<0.000001,ABS(D23)<0.000001,ABS(D24)<0.000001),"OK","不符") | E25: =IF(AND(ABS(E22)<0.000001,ABS(E23)<0.000001,ABS(E24)<0.000001),"OK","不符") | I25: 0 | J25: 0 | L25: 0 | M25: 0 | O25: 0 | P25: 0 | R25: 0 | S25: 0
A26: C. BIM分錄科目未列入期末總結的行數 | B26: =SUM($J$4:$J$47) | C26: =SUM($M$4:$M$47) | D26: =SUM($P$4:$P$47) | E26: =SUM($S$4:$S$47) | I26: 0 | J26: 0 | L26: 0 | M26: 0 | O26: 0 | P26: 0 | R26: 0 | S26: 0
A27: C 結果 | B27: =IF(B26=0,"OK","有漏列") | C27: =IF(C26=0,"OK","有漏列") | D27: =IF(D26=0,"OK","有漏列") | E27: =IF(E26=0,"OK","有漏列") | I27: 0 | J27: 0 | L27: 0 | M27: 0 | O27: 0 | P27: 0 | R27: 0 | S27: 0
I28: 0 | J28: 0 | L28: 0 | M28: 0 | O28: 0 | P28: 0 | R28: 0 | S28: 0
I29: 0 | J29: 0 | L29: 0 | M29: 0 | O29: 0 | P29: 0 | R29: 0 | S29: 0
I30: 0 | J30: 0 | L30: 0 | M30: 0 | O30: 0 | P30: 0 | R30: 0 | S30: 0
H31: =IF('工作表1'!D31="","",LEFT('工作表1'!D31,1)) | I31: =IF(ISNUMBER('工作表1'!F31),'工作表1'!F31,0) | J31: =IF('工作表1'!D31="",0,IF(COUNTIF('工作表1'!$C$50:$C$68,'工作表1'!D31)>0,0,1)) | K31: =IF('工作表1'!I31="","",LEFT('工作表1'!I31,1)) | L31: =IF(ISNUMBER('工作表1'!K31),'工作表1'!K31,0) | M31: =IF('工作表1'!I31="",0,IF(COUNTIF('工作表1'!$H$50:$H$68,'工作表1'!I31)>0,0,1)) | N31: =IF('工作表1'!N31="","",LEFT('工作表1'!N31,1)) | O31: =IF(ISNUMBER('工作表1'!P31),'工作表1'!P31,0) | P31: =IF('工作表1'!N31="",0,IF(COUNTIF('工作表1'!$M$50:$M$68,'工作表1'!N31)>0,0,1)) | Q31: =IF('工作表1'!S31="","",LEFT('工作表1'!S31,1)) | R31: =IF(ISNUMBER('工作表1'!U31),'工作表1'!U31,0) | S31: =IF('工作表1'!S31="",0,IF(COUNTIF('工作表1'!$R$50:$R$68,'工作表1'!S31)>0,0,1))
H32: =IF('工作表1'!D32="","",LEFT('工作表1'!D32,1)) | I32: =IF(ISNUMBER('工作表1'!F32),'工作表1'!F32,0) | J32: =IF('工作表1'!D32="",0,IF(COUNTIF('工作表1'!$C$50:$C$68,'工作表1'!D32)>0,0,1)) | K32: =IF('工作表1'!I32="","",LEFT('工作表1'!I32,1)) | L32: =IF(ISNUMBER('工作表1'!K32),'工作表1'!K32,0) | M32: =IF('工作表1'!I32="",0,IF(COUNTIF('工作表1'!$H$50:$H$68,'工作表1'!I32)>0,0,1)) | N32: =IF('工作表1'!N32="","",LEFT('工作表1'!N32,1)) | O32: =IF(ISNUMBER('工作表1'!P32),'工作表1'!P32,0) | P32: =IF('工作表1'!N32="",0,IF(COUNTIF('工作表1'!$M$50:$M$68,'工作表1'!N32)>0,0,1)) | Q32: =IF('工作表1'!S32="","",LEFT('工作表1'!S32,1)) | R32: =IF(ISNUMBER('工作表1'!U32),'工作表1'!U32,0) | S32: =IF('工作表1'!S32="",0,IF(COUNTIF('工作表1'!$R$50:$R$68,'工作表1'!S32)>0,0,1))
H33: =IF('工作表1'!D33="","",LEFT('工作表1'!D33,1)) | I33: =IF(ISNUMBER('工作表1'!F33),'工作表1'!F33,0) | J33: =IF('工作表1'!D33="",0,IF(COUNTIF('工作表1'!$C$50:$C$68,'工作表1'!D33)>0,0,1)) | K33: =IF('工作表1'!I33="","",LEFT('工作表1'!I33,1)) | L33: =IF(ISNUMBER('工作表1'!K33),'工作表1'!K33,0) | M33: =IF('工作表1'!I33="",0,IF(COUNTIF('工作表1'!$H$50:$H$68,'工作表1'!I33)>0,0,1)) | N33: =IF('工作表1'!N33="","",LEFT('工作表1'!N33,1)) | O33: =IF(ISNUMBER('工作表1'!P33),'工作表1'!P33,0) | P33: =IF('工作表1'!N33="",0,IF(COUNTIF('工作表1'!$M$50:$M$68,'工作表1'!N33)>0,0,1)) | Q33: =IF('工作表1'!S33="","",LEFT('工作表1'!S33,1)) | R33: =IF(ISNUMBER('工作表1'!U33),'工作表1'!U33,0) | S33: =IF('工作表1'!S33="",0,IF(COUNTIF('工作表1'!$R$50:$R$68,'工作表1'!S33)>0,0,1))
I34: 0 | J34: 0 | L34: 0 | M34: 0 | O34: 0 | P34: 0 | R34: 0 | S34: 0
I35: 0 | J35: 0 | L35: 0 | M35: 0 | O35: 0 | P35: 0 | R35: 0 | S35: 0
I36: 0 | J36: 0 | L36: 0 | M36: 0 | O36: 0 | P36: 0 | R36: 0 | S36: 0
I37: 0 | J37: 0 | L37: 0 | M37: 0 | O37: 0 | P37: 0 | R37: 0 | S37: 0
I38: 0 | J38: 0 | L38: 0 | M38: 0 | O38: 0 | P38: 0 | R38: 0 | S38: 0
I39: 0 | J39: 0 | L39: 0 | M39: 0 | O39: 0 | P39: 0 | R39: 0 | S39: 0
I40: 0 | J40: 0 | L40: 0 | M40: 0 | O40: 0 | P40: 0 | R40: 0 | S40: 0
...
